Workbook

Sheet Master Sheet
A1: # of ambassadors
A2: =counta(B38:B1001) -> 14
B3: Mainfare Total Data | E3: Butterfield Total Data | H3: Total Data | K3: custom period times
A4: The total lbs collected (since hrs data been collected) | B4: Total lbs | C4: =sum('Bulk Data'!O4:O1001) -> 17917 | E4: Total lbs | F4: =sum('Bulk Data'!P4:P1001) -> 16092 | H4: Total lbs | I4: =sum('Bulk Data'!U4:U1001) -> 34009 | K4: Period | L4: start | M4: end
A5: The average of the total lbs collected each day (since hrs data been collected) | B5: avg lb p/wrkday | C5: =C6*(C9*24) -> 267.41791 | E5: avg lb p/wrkday | F5: =F6*(F9*24) -> 255.42857 | H5: avg lb p/wrkday | I5: =I6*(I9*24) -> 507.59701 | K5: Breakfast | L5: 0.25 | M5: 0.45833333
A6: The total lbs collected over the total hours worked | B6: Total lbs/hr | C6: =C4/C8 -> 60.990582 | E6: Total lbs/hr | F6: =F4/F8 -> 42.434844 | H6: Total lbs/hr | I6: =I4/I8 -> 50.534684 | K6: Lunch | L6: 0.45833333 | M6: 0.66666667
A7: The average of the hourly rate of each ambassador | B7: avg ambassador lb p/hr | C7: =averageif('Bulk Data'!M:M,"MF",'Bulk Data'!I:I) -> 58.966613 | E7: avg ambassador lb p/hr | F7: =averageif('Bulk Data'!M:M,"BF",'Bulk Data'!I:I) -> 42.696513 | H7: avg ambassador lb p/hr | I7: =AVERAGE('Bulk Data'!X:X) -> 51.297536 | K7: Dinner | L7: 0.66666667 | M7: 0.91666667
A8: The total hours worked | B8: Total hours | C8: =sum('Bulk Data'!Q:Q)*24 -> 293.76667 | E8: Total hours | F8: =sum('Bulk Data'!R:R)*24 -> 379.21667 | H8: Total hours | I8: =sum('Bulk Data'!V:V)*24 -> 672.98333
A9: The average of all of the hours worked each day | B9: avg hrs/day | C9: =average('Bulk Data'!Q:Q) -> 0.18269071 | E9: avg hrs/day | F9: =average('Bulk Data'!R:R) -> 0.25080467 | H9: avg hrs/day | I9: =AVERAGE('Bulk Data'!V:V) -> 0.41852197
A10: The number of lbs of CO2 not emitted due to diversion | B10: Impact [lbs of Co2e] | C10: =IFERROR(__xludf.DUMMYFUNCTION("(C4*IMPORTRANGE(""https://docs.google.com/spreadsheets/d/1yb3w4clrvBHRll4AUNyFaSjmuILrbD-EHJuFlOIIIuI/edit?gid=0#gid=0"",""'Impact Calculations'!G5""))*2000"),11386.791009999997) -> 11386.791 | E10: Impact [lbs of Co2e] | F10: =IFERROR(__xludf.DUMMYFUNCTION("(F4*IMPORTRANGE(""https://docs.google.com/spreadsheets/d/1yb3w4clrvBHRll4AUNyFaSjmuILrbD-EHJuFlOIIIuI/edit?gid=0#gid=0"",""'Impact Calculations'!G5""))*2000"),10226.94876) -> 10226.949 | H10: Impact [lbs of Co2e] | I10: =IFERROR(__xludf.DUMMYFUNCTION("(I4*IMPORTRANGE(""https://docs.google.com/spreadsheets/d/1yb3w4clrvBHRll4AUNyFaSjmuILrbD-EHJuFlOIIIuI/edit?gid=0#gid=0"",""'Impact Calculations'!G5""))*2000"),21613.73977) -> 21613.74
B13: Mainfare Weekday Data | E13: Butterfield Weekday Data | H13: Total Weekday Data | K13: Email Recipients [does not effect automations]
B14: avg MF wkdy | C14: Avg lb's/WD | D14: weekdays | E14: avg BF wkdy | F14: Avg lb's/WD | H14: avg wkdy | I14: Avg lb's/WD | K14: FALSE | L14: Matt | M14: matt8011@uri.edu
B15: Mon | C15: =AVERAGEif('Bulk Data'!L:L,"Monday",'Bulk Data'!O:O) -> 312.25 | D15: Monday | E15: Mon | F15: =AVERAGEif('Bulk Data'!L:L,"Monday",'Bulk Data'!P:P) -> 205.75 | H15: Mon | I15: =C15+F15 -> 518 | K15: FALSE | L15: Dylan | M15: dylan_murdock@uri.edu
B16: Tues | C16: =AVERAGEif('Bulk Data'!L:L,"Tuesday",'Bulk Data'!O:O) -> 316.71429 | D16: Tuesday | E16: Tues | F16: =AVERAGEif('Bulk Data'!L:L,"Tuesday",'Bulk Data'!P:P) -> 281.15385 | H16: Tues | I16: =C16+F16 -> 597.86813 | K16: FALSE | L16: Westin | M16: westin_palumbo@uri.edu
B17: Wed | C17: =AVERAGEif('Bulk Data'!L:L,"Wednesday",'Bulk Data'!O:O) -> 231.76923 | D17: Wednesday | E17: Wed | F17: =AVERAGEif('Bulk Data'!L:L,"Wednesday",'Bulk Data'!P:P) -> 299.16667 | H17: Wed | I17: =C17+F17 -> 530.9359 | K17: FALSE | L17: Cailey | M17: cailey.mingolla@uri.edu
B18: Thur | C18: =AVERAGEif('Bulk Data'!L:L,"Thursday",'Bulk Data'!O:O) -> 178 | D18: Thursday | E18: Thur | F18: =AVERAGEif('Bulk Data'!L:L,"Thursday",'Bulk Data'!P:P) -> 373.76923 | H18: Thur | I18: =C18+F18 -> 551.76923 | K18: TRUE | L18: aryan | M18: aryan.gautam@uri.edu
B19: Fri | C19: =AVERAGEif('Bulk Data'!L:L,"Friday",'Bulk Data'!O:O) -> 302.21429 | D19: Friday | E19: Fri | F19: =AVERAGEif('Bulk Data'!L:L,"Friday",'Bulk Data'!P:P) -> 116.84615 | H19: Fri | I19: =C19+F19 -> 419.06044 | K19: FALSE
B20: avg MF wkdy | C20: Avg lb's/hr/WD | D20: Saturday | E20: avg BF wkdy | F20: Avg lb's/hr/WD | H20: avg wkdy | I20: Avg lb's/hr/WD
B21: Mon | C21: =AVERAGEif('Bulk Data'!L:L,"Monday",'Bulk Data'!S:S) -> 61.124314 | E21: Mon | F21: =AVERAGEif('Bulk Data'!L:L,"Monday",'Bulk Data'!T:T) -> 40.780211 | H21: Mon | I21: =AVERAGEif('Bulk Data'!L:L,"Monday",'Bulk Data'!W:W) -> 48.940939
B22: Tues | C22: =AVERAGEif('Bulk Data'!L:L,"Tuesday",'Bulk Data'!S:S) -> 73.632304 | E22: Tues | F22: =AVERAGEif('Bulk Data'!L:L,"Tuesday",'Bulk Data'!T:T) -> 51.971437 | H22: Tues | I22: =AVERAGEif('Bulk Data'!L:L,"Tuesday",'Bulk Data'!W:W) -> 60.591204
B23: Wed | C23: =AVERAGEif('Bulk Data'!L:L,"Wednesday",'Bulk Data'!S:S) -> 46.195151 | E23: Wed | F23: =AVERAGEif('Bulk Data'!L:L,"Wednesday",'Bulk Data'!T:T) -> 43.897061 | H23: Wed | I23: =AVERAGEif('Bulk Data'!L:L,"Wednesday",'Bulk Data'!W:W) -> 37.623026
B24: Thur | C24: =AVERAGEif('Bulk Data'!L:L,"Thursday",'Bulk Data'!S:S) -> 56.62022 | E24: Thur | F24: =AVERAGEif('Bulk Data'!L:L,"Thursday",'Bulk Data'!T:T) -> 41.003144 | H24: Thur | I24: =AVERAGEif('Bulk Data'!L:L,"Thursday",'Bulk Data'!W:W) -> 47.037207
B25: Fri | C25: =AVERAGEif('Bulk Data'!L:L,"Friday",'Bulk Data'!S:S) -> 61.19406 | E25: Fri | F25: =AVERAGEif('Bulk Data'!L:L,"Friday",'Bulk Data'!T:T) -> 34.519823 | H25: Fri | I25: =AVERAGEif('Bulk Data'!L:L,"Friday",'Bulk Data'!W:W) -> 48.323278
B26: avg MF wkdy | C26: Avg hr/WD | E26: avg BF wkdy | F26: Avg hr/WD | H26: avg wkdy | I26: Avg hr/WD
B27: Mon | C27: =AVERAGEif('Bulk Data'!L:L,"Monday",'Bulk Data'!Q:Q) -> 0.22019676 | E27: Mon | F27: =AVERAGEif('Bulk Data'!L:L,"Monday",'Bulk Data'!R:R) -> 0.22673611 | H27: Mon | I27: =AVERAGEif('Bulk Data'!L:L,"Monday",'Bulk Data'!V:V) -> 0.44693287
B28: Tues | C28: =AVERAGEif('Bulk Data'!L:L,"Tuesday",'Bulk Data'!Q:Q) -> 0.18928571 | E28: Tues | F28: =AVERAGEif('Bulk Data'!L:L,"Tuesday",'Bulk Data'!R:R) -> 0.23974359 | H28: Tues | I28: =AVERAGEif('Bulk Data'!L:L,"Tuesday",'Bulk Data'!V:V) -> 0.41190476
B29: Wed | C29: =AVERAGEif('Bulk Data'!L:L,"Wednesday",'Bulk Data'!Q:Q) -> 0.16207265 | E29: Wed | F29: =AVERAGEif('Bulk Data'!L:L,"Wednesday",'Bulk Data'!R:R) -> 0.28674769 | H29: Wed | I29: =AVERAGEif('Bulk Data'!L:L,"Wednesday",'Bulk Data'!V:V) -> 0.42676282
B30: Thur | C30: =AVERAGEif('Bulk Data'!L:L,"Thursday",'Bulk Data'!Q:Q) -> 0.13229167 | E30: Thur | F30: =AVERAGEif('Bulk Data'!L:L,"Thursday",'Bulk Data'!R:R) -> 0.35475427 | H30: Thur | I30: =AVERAGEif('Bulk Data'!L:L,"Thursday",'Bulk Data'!V:V) -> 0.46170635
B31: Fri | C31: =AVERAGEif('Bulk Data'!L:L,"Friday",'Bulk Data'!Q:Q) -> 0.21349206 | E31: Fri | F31: =AVERAGEif('Bulk Data'!L:L,"Friday",'Bulk Data'!R:R) -> 0.14695513 | H31: Fri | I31: =AVERAGEif('Bulk Data'!L:L,"Friday",'Bulk Data'!V:V) -> 0.3499504
B32: Sat | C32: 1.1574074e-06 | E32: Sat | F32: 1.1574074e-06 | H32: Sat | I32: 1.1574074e-06 | O32: Ambassador List: | R32: Ambassadors missing
O33: Alexis Sylvestre | P33: asylvestre914@uri.edu | R33: =IFERROR(__xludf.DUMMYFUNCTION("COUNTUNIQUE('Bulk Data'!B4:B1001)-COUNTA(O33:O55)"),0.0) -> 0
O34: Arjya Aich | P34: arjyaaich@uri.edu
B35: [all time] shifts worked: | D35: =COUNTIF('Bulk Data'!C:C,False) -> 273 | E35: =average('Bulk Data'!N4:N1001) -> 1.2558438 | J35: [all time] shifts missed | L35: =sum(F38:F51)-D35 -> 102 | O35: Brynn Hornig | P35: brynn.hornig@uri.edu
B36: Ambassador Data | O36: Denise Romanszysn | P36: denise.romanszysn@uri.edu
B37: Ambassador | C37: total lbs | D37: score | E37: avg period | F37: expected shifts as of 4/29/2026 | G37: shifts worked | H37: Worked Shifts | I37: skipped shifts | J37: total hrs | K37: lb/hr | L37: lb/shift | O37: Emmett Khan | P37: emmettkhan@uri.edu
A38: FALSE | B38: Alexis Sylvestre | C38: {=SUMIF('Bulk Data'!B:B,INDIRECT("RC[-1]", FALSE),'Bulk Data'!H:H)} -> 193 | D38: {=AverageIF('Bulk Data'!B:B,INDIRECT("RC[-2]", FALSE),'Bulk Data'!N:N)} -> 0.81681823 | E38: =IFERROR(__xludf.DUMMYFUNCTION("LET( name, INDIRECT(""RC[-3]"", FALSE), periods, FILTER('Bulk Data'!J:J,'Bulk Data'!B:B = name, 'Bulk Data'!J:J <> """"), uniquePeriods, UNIQUE(periods), counts, COUNTIF(periods, uniquePeriods), INDEX(uniquePeriods, MATCH(MAX(counts), counts, 0)"&") )"),"Dinner") -> Dinner | F38: 24 | G38: {=COUNTIFS('Bulk Data'!B$4:B1001,INDIRECT("RC[-5]", FALSE),'Bulk Data'!C$4:C1001,False)} -> 3 | H38: =G38/F38 -> 0.125 | I38: =(F38-G38) -> 21 | J38: =sumif('Bulk Data'!B:B,B38,'Bulk Data'!E:E) -> 0.20138889 | K38: =C38/(J38*24) -> 39.931034 | L38: =C38/G38 -> 64.333333 | O38: Evan Morgan | P38: evan.morgan@uri.edu
A39: TRUE | B39: Arjya Aich | C39: {=SUMIF('Bulk Data'!B:B,INDIRECT("RC[-1]", FALSE),'Bulk Data'!H:H)} -> 837 | D39: {=AverageIF('Bulk Data'!B:B,INDIRECT("RC[-2]", FALSE),'Bulk Data'!N:N)} -> 0.72121733 | E39: =IFERROR(__xludf.DUMMYFUNCTION("LET( name, INDIRECT(""RC[-3]"", FALSE), periods, FILTER('Bulk Data'!J:J,'Bulk Data'!B:B = name, 'Bulk Data'!J:J <> """"), uniquePeriods, UNIQUE(periods), counts, COUNTIF(periods, uniquePeriods), INDEX(uniquePeriods, MATCH(MAX(counts), counts, 0)"&") )"),"Dinner") -> Dinner | F39: 43 | G39: {=COUNTIFS('Bulk Data'!B$4:B1001,INDIRECT("RC[-5]", FALSE),'Bulk Data'!C$4:C1001,False)} -> 11 | H39: =G39/F39 -> 0.25581395 | I39: =(F39-G39) -> 32 | J39: =sumif('Bulk Data'!B:B,B39,'Bulk Data'!E:E) -> 1.28125 | K39: =C39/(J39*24) -> 27.219512 | L39: =C39/G39 -> 76.090909 | O39: Kaylie Forgue | P39: kaylie.forgue@uri.edu
A40: FALSE | B40: Brynn Hornig | C40: {=SUMIF('Bulk Data'!B:B,INDIRECT("RC[-1]", FALSE),'Bulk Data'!H:H)} -> 3497 | D40: {=AverageIF('Bulk Data'!B:B,INDIRECT("RC[-2]", FALSE),'Bulk Data'!N:N)} -> 1.1325295 | E40: =IFERROR(__xludf.DUMMYFUNCTION("LET( name, INDIRECT(""RC[-3]"", FALSE), periods, FILTER('Bulk Data'!J:J,'Bulk Data'!B:B = name, 'Bulk Data'!J:J <> """"), uniquePeriods, UNIQUE(periods), counts, COUNTIF(periods, uniquePeriods), INDEX(uniquePeriods, MATCH(MAX(counts), counts, 0)"&") )"),"Lunch") -> Lunch | F40: 33 | G40: {=COUNTIFS('Bulk Data'!B$4:B1001,INDIRECT("RC[-5]", FALSE),'Bulk Data'!C$4:C1001,False)} -> 34 | H40: =G40/F40 -> 1.030303 | I40: =(F40-G40) -> -1 | J40: =sumif('Bulk Data'!B:B,B40,'Bulk Data'!E:E) -> 3.7652778 | K40: =C40/(J40*24) -> 38.697897 | L40: =C40/G40 -> 102.85294 | O40: Kyra Turner | P40: kyra.turner@uri.edu
A41: FALSE | B41: Denise Romanszysn | C41: {=SUMIF('Bulk Data'!B:B,INDIRECT("RC[-1]", FALSE),'Bulk Data'!H:H)} -> 1347 | D41: {=AverageIF('Bulk Data'!B:B,INDIRECT("RC[-2]", FALSE),'Bulk Data'!N:N)} -> 1.5802533 | E41: =IFERROR(__xludf.DUMMYFUNCTION("LET( name, INDIRECT(""RC[-3]"", FALSE), periods, FILTER('Bulk Data'!J:J,'Bulk Data'!B:B = name, 'Bulk Data'!J:J <> """"), uniquePeriods, UNIQUE(periods), counts, COUNTIF(periods, uniquePeriods), INDEX(uniquePeriods, MATCH(MAX(counts), counts, 0)"&") )"),"Breakfast") -> Breakfast | F41: 31 | G41: {=COUNTIFS('Bulk Data'!B$4:B1001,INDIRECT("RC[-5]", FALSE),'Bulk Data'!C$4:C1001,False)} -> 12 | H41: =G41/F41 -> 0.38709677 | I41: =(F41-G41) -> 19 | J41: =sumif('Bulk Data'!B:B,B41,'Bulk Data'!E:E) -> 0.98472222 | K41: =C41/(J41*24) -> 56.995769 | L41: =C41/G41 -> 112.25 | O41: Laila Maisuria | P41: laila.maisuria@uri.edu
A42: FALSE | B42: Emmett Khan | C42: {=SUMIF('Bulk Data'!B:B,INDIRECT("RC[-1]", FALSE),'Bulk Data'!H:H)} -> 2083 | D42: {=AverageIF('Bulk Data'!B:B,INDIRECT("RC[-2]", FALSE),'Bulk Data'!N:N)} -> 1.2475438 | E42: =IFERROR(__xludf.DUMMYFUNCTION("LET( name, INDIRECT(""RC[-3]"", FALSE), periods, FILTER('Bulk Data'!J:J,'Bulk Data'!B:B = name, 'Bulk Data'!J:J <> """"), uniquePeriods, UNIQUE(periods), counts, COUNTIF(periods, uniquePeriods), INDEX(uniquePeriods, MATCH(MAX(counts), counts, 0)"&") )"),"Dinner") -> Dinner | F42: 22 | G42: {=COUNTIFS('Bulk Data'!B$4:B1001,INDIRECT("RC[-5]", FALSE),'Bulk Data'!C$4:C1001,False)} -> 22 | H42: =G42/F42 -> 1 | I42: =(F42-G42) -> 0 | J42: =sumif('Bulk Data'!B:B,B42,'Bulk Data'!E:E) -> 1.36875 | K42: =C42/(J42*24) -> 63.409437 | L42: =C42/G42 -> 94.681818 | O42: Leah Bucci | P42: leah.bucci@uri.edu
...

Sheet Bulk Data
A1: auto | B1: auto | C1: <= | D1: auto | E1: auto | F1: auto | G1: array<= | H1: auto | I1: array<= | J1: array<= | K1: auto | L1: <= | M1: auto | N1: array<= | O1: array<= | P1: array<= | Q1: array<= | R1: array<= | S1: array<= | T1: array<= | U1: array<= | V1: array<= | W1: <= | X1: array<= | Y1: array<= | Z1: auto | AA1: auto | AB1: <=
A2: Timestamp | B2: Name | C2: Double Name | D2: Start hour | E2: hours worked | F2: End hour | G2: hours pp | H2: Derived Weight | I2: lb/hr per shift | J2: Period | K2: Date | L2: Weekday | M2: Dining Hall | N2: Effeciency Score | O2: MF lbs td | P2: BF lbs td | Q2: MF hrs td | R2: BF hrs td | S2: MF lbs/hr td | T2: BF lbs/hr td | U2: lbs td | V2: hours td | W2: lbs/hr td | X2: Avg Ambassador lbs/hr | Y2: Effeciency score td | Z2: MF Diners td | AA2: BF Diners td | AB2: Diners Today
A3: 46041 | B3: N/A | C3: FALSE | H3: 0 | K3: 46041 | L3: =IFS( K3="","", WEEKDAY(K3)=1, "Sunday", WEEKDAY(K3)=2, "Monday", WEEKDAY(K3)=3, "Tuesday", WEEKDAY(K3)=4, "Wednesday", WEEKDAY(K3)=5, "Thursday", WEEKDAY(K3)=6, "Friday", WEEKDAY(K3)=7, "Saturday" ) -> Monday
A4: =IFERROR(__xludf.DUMMYFUNCTION("IMPORTRANGE(""https://docs.google.com/spreadsheets/d/1jmXuuYb2rWIX1PbFVp-yzH3IqJm3OKXaoMXcca97_l4/edit?gid=1259547262#gid=1259547262"",""S2026 Bin Weight!A2:A500"")"),46043.62020392361) -> 46043.62 | B4: =IFERROR(__xludf.DUMMYFUNCTION("IMPORTRANGE(""https://docs.google.com/spreadsheets/d/1jmXuuYb2rWIX1PbFVp-yzH3IqJm3OKXaoMXcca97_l4/edit?gid=1259547262#gid=1259547262"",""S2026 Bin Weight!B2:B500"")"),"Brynn Hornig") -> Brynn Hornig | C4: =false -> FALSE | D4: =IFERROR(__xludf.DUMMYFUNCTION("IMPORTRANGE(""https://docs.google.com/spreadsheets/d/1jmXuuYb2rWIX1PbFVp-yzH3IqJm3OKXaoMXcca97_l4/edit?gid=1259547262#gid=1259547262"",""S2026 Bin Weight!E2:E500"")"),0.5208333333357587) -> 0.52083333 | E4: =IFERROR(__xludf.DUMMYFUNCTION("arrayformula(IMPORTRANGE(""https://docs.google.com/spreadsheets/d/1jmXuuYb2rWIX1PbFVp-yzH3IqJm3OKXaoMXcca97_l4/edit?gid=1259547262#gid=1259547262"",""S2026 Bin Weight!F2:F500"") - IMPORTRANGE(""https://docs.google.com/spreadsheets/d/1jmXuuYb2rWIX1PbFVp-yz"&"H3IqJm3OKXaoMXcca97_l4/edit?gid=1259547262#gid=1259547262"",""S2026 Bin Weight!E2:E500""))"),0.10416666666424135) -> 0.10416667 | F4: =IFERROR(__xludf.DUMMYFUNCTION("IMPORTRANGE(""https://docs.google.com/spreadsheets/d/1jmXuuYb2rWIX1PbFVp-yzH3IqJm3OKXaoMXcca97_l4/edit?gid=1259547262#gid=1259547262"",""S2026 Bin Weight!F2:F500"")"),0.625) -> 0.625 | G4: {=IF(C4:C1001="","", IF(C4:C1001=TRUE,"", SUMIF( SCAN(0,C4:C1001,LAMBDA(a,c,a+(c=FALSE))), SCAN(0,C4:C1001,LAMBDA(a,c,a+(c=FALSE))), E4:E1001 ) ) )} -> 0.10416667 | H4: =IFERROR(__xludf.DUMMYFUNCTION("arrayformula(IMPORTRANGE(""https://docs.google.com/spreadsheets/d/1jmXuuYb2rWIX1PbFVp-yzH3IqJm3OKXaoMXcca97_l4/edit?gid=1259547262#gid=1259547262"",""S2026 Bin Weight!H2:H500"") - IMPORTRANGE(""https://docs.google.com/spreadsheets/d/1jmXuuYb2rWIX1PbFVp-yz"&"H3IqJm3OKXaoMXcca97_l4/edit?gid=1259547262#gid=1259547262"",""S2026 Bin Weight!G2:G500""))"),129.0) -> 129 | I4: {=IF(C4:C1001="","", IF(C4:C1001=TRUE,"", IFERROR( SUMIF( SCAN(0,C4:C1001,LAMBDA(a,c,a+(c=FALSE))), SCAN(0,C4:C1001,LAMBDA(a,c,a+(c=FALSE))), H4:H1001 ) / (24 * G4:G1001), "" ) ) )} -> 51.6 | J4: {=IF(D4:D1001="","", IF( (D4:D1001 < 'Master Sheet'!M5) * (F4:F1001 > 'Master Sheet'!L6), "Breakfast/Lunch", IF( (D4:D1001 < ('Master Sheet'!M6-0.01)) * (F4:F1001 > 'Master Sheet'!L7), "Lunch/Dinner", IF( (D4:D1001 >= 'Master Sheet'!L5) * (F4:F1001 <= 'Master Sheet'!M5), "Breakfast", IF( (D4:D1001 >= 'Master Sheet'!L6) * (F4:F1001 <= 'Master Sheet'!M6), "Lunch", IF( (D4:D1001 >= ('Master Sheet'!L7-0.01)) * (F4:F1001 <= 'Master Sheet'!M7), "Dinner", "" ) ) ) ) ) )} -> Lunch | K4: =IFERROR(__xludf.DUMMYFUNCTION("IMPORTRANGE(""https://docs.google.com/spreadsheets/d/1jmXuuYb2rWIX1PbFVp-yzH3IqJm3OKXaoMXcca97_l4/edit?gid=1259547262#gid=1259547262"",""S2026 Bin Weight!C2:C500"")"),46043.0) -> 46043 | L4: =IFS( K4="","", WEEKDAY(K4)=1, "Sunday", WEEKDAY(K4)=2, "Monday", WEEKDAY(K4)=3, "Tuesday", WEEKDAY(K4)=4, "Wednesday", WEEKDAY(K4)=5, "Thursday", WEEKDAY(K4)=6, "Friday", WEEKDAY(K4)=7, "Saturday" ) -> Wednesday | M4: =IFERROR(__xludf.DUMMYFUNCTION("ARRAYFORMULA( iferror(IFs( IMPORTRANGE( ""https://docs.google.com/spreadsheets/d/1jmXuuYb2rWIX1PbFVp-yzH3IqJm3OKXaoMXcca97_l4"", ""S2026 Bin Weight!D2:D500"" ) = ""Mainfare"", ""MF"", IMPORTRANGE( ""https://docs.google."&"com/spreadsheets/d/1jmXuuYb2rWIX1PbFVp-yzH3IqJm3OKXaoMXcca97_l4"", ""S2026 Bin Weight!D2:D500"" ) = ""Butterfield"", ""BF"" ),"""") )"),"MF") -> MF | N4: {=IF(I4:I1001="","", IF(J4:J1001="", "", IF(J4:J1001="Breakfast", IF(M4:M1001="MF", I4:I1001 / INDEX('Std Deviations'!AG22:AG26, MATCH(L4:L1001, {"Monday","Tuesday","Wednesday","Thursday","Friday"},0)), IF(M4:M1001="BF", I4:I1001 / INDEX('Std Deviations'!AG32:AG36, MATCH(L4:L1001, {"Monday","Tuesday","Wednesday","Thursday","Friday"},0)), "")), IF(J4:J1001="Breakfast/Lunch", I4:I1001 / ( (INDEX('Std Deviations'!AG22:AG26, MATCH(L4:L1001, {"Monday","Tuesday","Wednesday","Thursday","Friday"},0)) * ( 'Master Sheet'!L6 - D4:D1001 ) / E4:E1001 ) + (INDEX('Std Deviations'!AG32:AG36, MATCH(L4:L1001, {"Monday","Tuesday","Wednesday","Thursday","Friday"},0)) * ( F4:F1001 - 'Master Sheet'!L6 ) / E4:E1001 ) ), IF(J4:J1001="Lunch", IF(M4:M1001="MF", I4:I1001 / INDEX('Std Deviations'!AC32:AC36, MATCH(L4:L1001, {"Monday","Tuesday","Wednesday","Thursday","Friday"},0)), IF(M4:M1001="BF", I4:I1001 / INDEX('Std Deviations'!AG32:AG36, MATCH(L4:L1001, {"Monday","Tuesday","Wednesday","Thursday","Friday"},0)), "")), IF(J4:J1001="Lunch/Dinner", I4:I1001 / ( (INDEX('Std Deviations'!AC32:AC36, MATCH(L4:L1001, {"Monday","Tuesday","Wednesday","Thursday","Friday"},0)) * ( 'Master Sheet'!L7 - D4:D1001 ) / E4:E1001 ) + (INDEX('Std Deviations'!AC42:AC46, MATCH(L4:L1001, {"Monday","Tuesday","Wednesday","Thursday","Friday"},0)) * ( F4:F1001 - 'Master Sheet'!L7 ) / E4:E1001 ) ), IF(J4:J1001="Dinner", IF(M4:M1001="MF", I4:I1001 / INDEX('Std Deviations'!AC42:AC46, MATCH(L4:L1001, {"Monday","Tuesday","Wednesday","Thursday","Friday"},0)), IF(M4:M1001="BF", I4:I1001 / INDEX('Std Deviations'!AG42:AG45, MATCH(L4:L1001, {"Monday","Tuesday","Wednesday","Thursday"},0)), "")), "")))))))} -> 1.0263041 | O4: =IFERROR(__xludf.DUMMYFUNCTION("BYROW('Bulk Data'!K4:K1001, LAMBDA(r, IF(r="""","""", LET( nextVal, IFERROR(INDEX('Bulk Data'!K4:K1001, ROW(r)-ROW('Bulk Data'!K4)+2), """"), IF(r <> nextVal, IFERROR( SUM(FILTER('Bulk Data'!H4:H1001, 'Bulk Data'!K4:K"&"1001 = r, 'Bulk Data'!M4:M1001 = ""MF"")), """" ), """" ) ) ) ))"),129.0) -> 129 | P4: =IFERROR(__xludf.DUMMYFUNCTION("BYROW('Bulk Data'!K4:K1001, LAMBDA(r, IF(r="""","""", LET( nextVal, IFERROR(INDEX('Bulk Data'!K4:K1001, ROW(r)-ROW('Bulk Data'!K4)+2), """"), IF(r <> nextVal, IFERROR( IF(SUM(FILTER('Bulk Data'!H4:H1001, 'Bulk Data'!K"&"4:K1001 = r, 'Bulk Data'!M4:M1001 = ""BF""))=0,"""", SUM(FILTER('Bulk Data'!H4:H1001, 'Bulk Data'!K4:K1001 = r, 'Bulk Data'!M4:M1001 = ""BF"")) ), """" ), """" ) ) ) )) "),"") | Q4: =IFERROR(__xludf.DUMMYFUNCTION("BYROW('Bulk Data'!K4:K1001, LAMBDA(r, IF(r="""","""", LET( nextVal, IFERROR(INDEX('Bulk Data'!K4:K1001, ROW(r)-ROW('Bulk Data'!K4)+2), """"), IF(r <> nextVal, IFERROR( IF(SUM(FILTER('Bulk Data'!E4:E1001, 'Bulk Data'!K"&"4:K1001=r, 'Bulk Data'!M4:M1001=""MF""))=0,"""", SUM(FILTER('Bulk Data'!E4:E1001, 'Bulk Data'!K4:K1001=r, 'Bulk Data'!M4:M1001=""MF"")) ), """" ), """" ) ) ) )) "),0.10416666666424135) -> 0.10416667 | R4: =IFERROR(__xludf.DUMMYFUNCTION("BYROW('Bulk Data'!K4:K1001, LAMBDA(r, IF(r="""","""", LET( nextVal, IFERROR(INDEX('Bulk Data'!K4:K1001, ROW(r)-ROW('Bulk Data'!K4)+2), """"), IF(r <> nextVal, IFERROR( IF(SUM(FILTER('Bulk Data'!E4:E1001, 'Bulk Data'!K"&"4:K1001=r, 'Bulk Data'!M4:M1001=""BF""))=0,"""", SUM(FILTER('Bulk Data'!E4:E1001, 'Bulk Data'!K4:K1001=r, 'Bulk Data'!M4:M1001=""BF"")) ), """" ), """" ) ) ) ))"),"") | S4: =IFERROR(__xludf.DUMMYFUNCTION("BYROW('Bulk Data'!K4:K1001, LAMBDA(r, IF(r="""","""", LET( nextVal, IFERROR(INDEX('Bulk Data'!K4:K1001, ROW(r)-ROW('Bulk Data'!K4)+2), """"), IF(r <> nextVal, IFERROR( IF(AVERAGE(FILTER('Bulk Data'!I4:I1001, 'Bulk Dat"&"a'!K4:K1001=r, 'Bulk Data'!M4:M1001=""MF""))=0,"""", AVERAGE(FILTER('Bulk Data'!I4:I1001, 'Bulk Data'!K4:K1001=r, 'Bulk Data'!M4:M1001=""MF"")) ), """" ), """" ) ) ) )) "),51.60000000120141) -> 51.6 | T4: =IFERROR(__xludf.DUMMYFUNCTION("BYROW('Bulk Data'!K4:K1001, LAMBDA(r, IF(r="""","""", LET( nextVal, IFERROR(INDEX('Bulk Data'!K4:K1001, ROW(r)-ROW('Bulk Data'!K4)+2), """"), IF(r <> nextVal, IFERROR( IF(AVERAGE(FILTER('Bulk Data'!I4:I1001, 'Bulk Dat"&"a'!K4:K1001=r, 'Bulk Data'!M4:M1001=""BF""))=0,"""", AVERAGE(FILTER('Bulk Data'!I4:I1001, 'Bulk Data'!K4:K1001=r, 'Bulk Data'!M4:M1001=""BF"")) ), """" ), """" ) ) ) )) "),"") | U4: =IFERROR(__xludf.DUMMYFUNCTION("BYROW('Bulk Data'!K4:K1001, LAMBDA(r, IF(r="""","""", LET( nextVal, IFERROR(INDEX('Bulk Data'!K4:K1001, ROW(r)-ROW('Bulk Data'!K4)+2), """"), IF(r <> nextVal, IFERROR( SUM(FILTER('Bulk Data'!H4:H1001, 'Bulk Data'!K4:K"&"1001 = r)), """" ), """" ) ) ) )) "),129.0) -> 129 | V4: =IFERROR(__xludf.DUMMYFUNCTION("BYROW('Bulk Data'!K4:K1001, LAMBDA(r, IF(r="""","""", LET( nextVal, IFERROR(INDEX('Bulk Data'!K4:K1001, ROW(r)-ROW('Bulk Data'!K4)+2), """"), IF(r <> nextVal, IFERROR( SUM(FILTER('Bulk Data'!E4:E1001, 'Bulk Data'!K4:K"&"1001 = r)), """" ), """" ) ) ) )) "),0.10416666666424135) -> 0.10416667 | W4: =iferror(if(U4/(V4*24)=0,"",U4/(V4*24)),"") -> 51.6 | X4: =IFERROR(__xludf.DUMMYFUNCTION("BYROW('Bulk Data'!K4:K1001, LAMBDA(r, IF(r="""","""", LET( nextVal, IFERROR(INDEX('Bulk Data'!K4:K1001, ROW(r)-ROW('Bulk Data'!K4)+2), """"), IF(r <> nextVal, IFERROR( AVERAGE(FILTER('Bulk Data'!I4:I1001, 'Bulk Data'!"&"K4:K1001 = r)), """" ), """" ) ) ) )) "),51.60000000120141) -> 51.6 | Y4: =IFERROR(__xludf.DUMMYFUNCTION("BYROW('Bulk Data'!K4:K1001, LAMBDA(r, IF(r="""","""", LET( nextVal, IFERROR(INDEX('Bulk Data'!K4:K1001, ROW(r)-ROW('Bulk Data'!K4)+2), """"), IF(r <> nextVal, LET( filteredVals, FILTER( IF("&" 'Bulk Data'!J4:J1001="""","""", IF('Bulk Data'!J4:J1001=""Breakfast"", 'Bulk Data'!I4:I1001/'Period Data'!A30, IF('Bulk Data'!J4:J1001=""Breakfast/Lunch"", 'Bulk D"&"ata'!I4:I1001/'Period Data'!G30, IF('Bulk Data'!J4:J1001=""Lunch"", 'Bulk Data'!I4:I1001/'Period Data'!M30, IF('Bulk Data'!J4:J1001=""Lunch/Dinner"", 'Bulk Data'!I4:I1001/'Period Da"&"ta'!S30, IF('Bulk Data'!J4:J1001=""Dinner"", 'Bulk Data'!I4:I1001/'Period Data'!Y30, """" ))))) ), 'Bulk Data'!K4:K1001 = r ), "&"IFERROR(AVERAGE(filteredVals),"""") ), """" ) ) ) )) "),1.0184732700553483) -> 1.0184733
A5: =IFERROR(__xludf.DUMMYFUNCTION("""COMPUTED_VALUE"""),46044.77925564814) -> 46044.779 | B5: =IFERROR(__xludf.DUMMYFUNCTION("""COMPUTED_VALUE"""),"Emmett Khan") -> Emmett Khan | C5: =IF( B5="", "", AND( B5=B4, K5=K4, M5=M4, ABS(D5 - F4) <= TIME(0,25,0) ) ) -> FALSE | D5: =IFERROR(__xludf.DUMMYFUNCTION("""COMPUTED_VALUE"""),0.7083333333357587) -> 0.70833333 | E5: =IFERROR(__xludf.DUMMYFUNCTION("""COMPUTED_VALUE"""),0.07291666666424135) -> 0.072916667 | F5: =IFERROR(__xludf.DUMMYFUNCTION("""COMPUTED_VALUE"""),0.78125) -> 0.78125 | G5: 0.072916667 | H5: =IFERROR(__xludf.DUMMYFUNCTION("""COMPUTED_VALUE"""),114.0) -> 114 | I5: 65.142857 | J5: Dinner | K5: =IFERROR(__xludf.DUMMYFUNCTION("""COMPUTED_VALUE"""),46044.0) -> 46044 | L5: =IFS( K5="","", WEEKDAY(K5)=1, "Sunday", WEEKDAY(K5)=2, "Monday", WEEKDAY(K5)=3, "Tuesday", WEEKDAY(K5)=4, "Wednesday", WEEKDAY(K5)=5, "Thursday", WEEKDAY(K5)=6, "Friday", WEEKDAY(K5)=7, "Saturday" ) -> Thursday | M5: =IFERROR(__xludf.DUMMYFUNCTION("""COMPUTED_VALUE"""),"BF") -> BF | N5: 1.4661308 | O5: =IFERROR(__xludf.DUMMYFUNCTION("""COMPUTED_VALUE"""),"") | P5: =IFERROR(__xludf.DUMMYFUNCTION("""COMPUTED_VALUE"""),"") | Q5: =IFERROR(__xludf.DUMMYFUNCTION("""COMPUTED_VALUE"""),"") | R5: =IFERROR(__xludf.DUMMYFUNCTION("""COMPUTED_VALUE"""),"") | S5: =IFERROR(__xludf.DUMMYFUNCTION("""COMPUTED_VALUE"""),"") | T5: =IFERROR(__xludf.DUMMYFUNCTION("""COMPUTED_VALUE"""),"") | U5: =IFERROR(__xludf.DUMMYFUNCTION("""COMPUTED_VALUE"""),"") | V5: =IFERROR(__xludf.DUMMYFUNCTION("""COMPUTED_VALUE"""),"") | W5: =iferror(if(U5/(V5*24)=0,"",U5/(V5*24)),"") | X5: =IFERROR(__xludf.DUMMYFUNCTION("""COMPUTED_VALUE"""),"") | Y5: =IFERROR(__xludf.DUMMYFUNCTION("""COMPUTED_VALUE"""),"")
A6: =IFERROR(__xludf.DUMMYFUNCTION("""COMPUTED_VALUE"""),46044.79840002315) -> 46044.798 | B6: =IFERROR(__xludf.DUMMYFUNCTION("""COMPUTED_VALUE"""),"Orpheus Wilson") -> Orpheus Wilson | C6: =IF( B6="", "", AND( B6=B5, K6=K5, M6=M5, ABS(D6 - F5) <= TIME(0,25,0) ) ) -> FALSE | D6: =IFERROR(__xludf.DUMMYFUNCTION("""COMPUTED_VALUE"""),0.7118055555547471) -> 0.71180556 | E6: =IFERROR(__xludf.DUMMYFUNCTION("""COMPUTED_VALUE"""),0.07708333332993789) -> 0.077083333 | F6: =IFERROR(__xludf.DUMMYFUNCTION("""COMPUTED_VALUE"""),0.788888888884685) -> 0.78888889 | G6: 0.077083333 | H6: =IFERROR(__xludf.DUMMYFUNCTION("""COMPUTED_VALUE"""),104.0) -> 104 | I6: 56.216216 | J6: Dinner | K6: =IFERROR(__xludf.DUMMYFUNCTION("""COMPUTED_VALUE"""),46044.0) -> 46044 | L6: =IFS( K6="","", WEEKDAY(K6)=1, "Sunday", WEEKDAY(K6)=2, "Monday", WEEKDAY(K6)=3, "Tuesday", WEEKDAY(K6)=4, "Wednesday", WEEKDAY(K6)=5, "Thursday", WEEKDAY(K6)=6, "Friday", WEEKDAY(K6)=7, "Saturday" ) -> Thursday | M6: =IFERROR(__xludf.DUMMYFUNCTION("""COMPUTED_VALUE"""),"MF") -> MF | N6: 1.1758389 | O6: =IFERROR(__xludf.DUMMYFUNCTION("""COMPUTED_VALUE"""),104.0) -> 104 | P6: =IFERROR(__xludf.DUMMYFUNCTION("""COMPUTED_VALUE"""),114.0) -> 114 | Q6: =IFERROR(__xludf.DUMMYFUNCTION("""COMPUTED_VALUE"""),0.07708333332993789) -> 0.077083333 | R6: =IFERROR(__xludf.DUMMYFUNCTION("""COMPUTED_VALUE"""),0.07291666666424135) -> 0.072916667 | S6: =IFERROR(__xludf.DUMMYFUNCTION("""COMPUTED_VALUE"""),56.21621621869249) -> 56.216216 | T6: =IFERROR(__xludf.DUMMYFUNCTION("""COMPUTED_VALUE"""),65.1428571450239) -> 65.142857 | U6: =IFERROR(__xludf.DUMMYFUNCTION("""COMPUTED_VALUE"""),218.0) -> 218 | V6: =IFERROR(__xludf.DUMMYFUNCTION("""COMPUTED_VALUE"""),0.14999999999417923) -> 0.15 | W6: =iferror(if(U6/(V6*24)=0,"",U6/(V6*24)),"") -> 60.555556 | X6: =IFERROR(__xludf.DUMMYFUNCTION("""COMPUTED_VALUE"""),60.679536681858195) -> 60.679537 | Y6: =IFERROR(__xludf.DUMMYFUNCTION("""COMPUTED_VALUE"""),1.0807181040721305) -> 1.0807181
A7: =IFERROR(__xludf.DUMMYFUNCTION("""COMPUTED_VALUE"""),46045.61947065972) -> 46045.619 | B7: =IFERROR(__xludf.DUMMYFUNCTION("""COMPUTED_VALUE"""),"Oluwatimilehin Shodipe") -> Oluwatimilehin Shodipe | C7: =IF( B7="", "", AND( B7=B6, K7=K6, M7=M6, ABS(D7 - F6) <= TIME(0,25,0) ) ) -> FALSE | D7: =IFERROR(__xludf.DUMMYFUNCTION("""COMPUTED_VALUE"""),0.5048611111124046) -> 0.50486111 | E7: =IFERROR(__xludf.DUMMYFUNCTION("""COMPUTED_VALUE"""),0.12013888888759539) -> 0.12013889 | F7: =IFERROR(__xludf.DUMMYFUNCTION("""COMPUTED_VALUE"""),0.625) -> 0.625 | G7: 0.12013889 | H7: =IFERROR(__xludf.DUMMYFUNCTION("""COMPUTED_VALUE"""),143.0) -> 143 | I7: 49.595376 | J7: Lunch | K7: =IFERROR(__xludf.DUMMYFUNCTION("""COMPUTED_VALUE"""),46045.0) -> 46045 | L7: =IFS( K7="","", WEEKDAY(K7)=1, "Sunday", WEEKDAY(K7)=2, "Monday", WEEKDAY(K7)=3, "Tuesday", WEEKDAY(K7)=4, "Wednesday", WEEKDAY(K7)=5, "Thursday", WEEKDAY(K7)=6, "Friday", WEEKDAY(K7)=7, "Saturday" ) -> Friday | M7: =IFERROR(__xludf.DUMMYFUNCTION("""COMPUTED_VALUE"""),"MF") -> MF | N7: 0.98643292 | O7: =IFERROR(__xludf.DUMMYFUNCTION("""COMPUTED_VALUE"""),143.0) -> 143 | P7: =IFERROR(__xludf.DUMMYFUNCTION("""COMPUTED_VALUE"""),"") | Q7: =IFERROR(__xludf.DUMMYFUNCTION("""COMPUTED_VALUE"""),0.12013888888759539) -> 0.12013889 | R7: =IFERROR(__xludf.DUMMYFUNCTION("""COMPUTED_VALUE"""),"") | S7: =IFERROR(__xludf.DUMMYFUNCTION("""COMPUTED_VALUE"""),49.59537572307733) -> 49.595376 | T7: =IFERROR(__xludf.DUMMYFUNCTION("""COMPUTED_VALUE"""),"") | U7: =IFERROR(__xludf.DUMMYFUNCTION("""COMPUTED_VALUE"""),143.0) -> 143 | V7: =IFERROR(__xludf.DUMMYFUNCTION("""COMPUTED_VALUE"""),0.12013888888759539) -> 0.12013889 | W7: =iferror(if(U7/(V7*24)=0,"",U7/(V7*24)),"") -> 49.595376 | X7: =IFERROR(__xludf.DUMMYFUNCTION("""COMPUTED_VALUE"""),49.59537572307733) -> 49.595376 | Y7: =IFERROR(__xludf.DUMMYFUNCTION("""COMPUTED_VALUE"""),0.9789062885877934) -> 0.97890629
A8: =IFERROR(__xludf.DUMMYFUNCTION("""COMPUTED_VALUE"""),46049.86973208333) -> 46049.87 | B8: =IFERROR(__xludf.DUMMYFUNCTION("""COMPUTED_VALUE"""),"Laila Maisuria") -> Laila Maisuria | C8: =IF( B8="", "", AND( B8=B7, K8=K7, M8=M7, ABS(D8 - F7) <= TIME(0,25,0) ) ) -> FALSE | D8: =IFERROR(__xludf.DUMMYFUNCTION("""COMPUTED_VALUE"""),0.7527777777795563) -> 0.75277778 | E8: =IFERROR(__xludf.DUMMYFUNCTION("""COMPUTED_VALUE"""),0.11458333333575865) -> 0.11458333 | F8: =IFERROR(__xludf.DUMMYFUNCTION("""COMPUTED_VALUE"""),0.867361111115315) -> 0.86736111 | G8: 0.11458333 | H8: =IFERROR(__xludf.DUMMYFUNCTION("""COMPUTED_VALUE"""),134.0) -> 134 | I8: 48.727273 | J8: Dinner | K8: =IFERROR(__xludf.DUMMYFUNCTION("""COMPUTED_VALUE"""),46049.0) -> 46049 | L8: =IFS( K8="","", WEEKDAY(K8)=1, "Sunday", WEEKDAY(K8)=2, "Monday", WEEKDAY(K8)=3, "Tuesday", WEEKDAY(K8)=4, "Wednesday", WEEKDAY(K8)=5, "Thursday", WEEKDAY(K8)=6, "Friday", WEEKDAY(K8)=7, "Saturday" ) -> Tuesday | M8: =IFERROR(__xludf.DUMMYFUNCTION("""COMPUTED_VALUE"""),"MF") -> MF | N8: 1.0191974 | O8: =IFERROR(__xludf.DUMMYFUNCTION("""COMPUTED_VALUE"""),134.0) -> 134 | P8: =IFERROR(__xludf.DUMMYFUNCTION("""COMPUTED_VALUE"""),"") | Q8: =IFERROR(__xludf.DUMMYFUNCTION("""COMPUTED_VALUE"""),0.11458333333575865) -> 0.11458333 | R8: =IFERROR(__xludf.DUMMYFUNCTION("""COMPUTED_VALUE"""),"") | S8: =IFERROR(__xludf.DUMMYFUNCTION("""COMPUTED_VALUE"""),48.727272726241345) -> 48.727273 | T8: =IFERROR(__xludf.DUMMYFUNCTION("""COMPUTED_VALUE"""),"") | U8: =IFERROR(__xludf.DUMMYFUNCTION("""COMPUTED_VALUE"""),134.0) -> 134 | V8: =IFERROR(__xludf.DUMMYFUNCTION("""COMPUTED_VALUE"""),0.11458333333575865) -> 0.11458333 | W8: =iferror(if(U8/(V8*24)=0,"",U8/(V8*24)),"") -> 48.727273 | X8: =IFERROR(__xludf.DUMMYFUNCTION("""COMPUTED_VALUE"""),48.727272726241345) -> 48.727273 | Y8: =IFERROR(__xludf.DUMMYFUNCTION("""COMPUTED_VALUE"""),0.8678452189476501) -> 0.86784522
A9: =IFERROR(__xludf.DUMMYFUNCTION("""COMPUTED_VALUE"""),46050.47128442129) -> 46050.471 | B9: =IFERROR(__xludf.DUMMYFUNCTION("""COMPUTED_VALUE"""),"Kaylie Forgue") -> Kaylie Forgue | C9: =IF( B9="", "", AND( B9=B8, K9=K8, M9=M8, ABS(D9 - F8) <= TIME(0,25,0) ) ) -> FALSE | D9: =IFERROR(__xludf.DUMMYFUNCTION("""COMPUTED_VALUE"""),0.30902777778101154) -> 0.30902778 | E9: =IFERROR(__xludf.DUMMYFUNCTION("""COMPUTED_VALUE"""),0.11597222222189885) -> 0.11597222 | F9: =IFERROR(__xludf.DUMMYFUNCTION("""COMPUTED_VALUE"""),0.4250000000029104) -> 0.425 | G9: 0.11597222 | H9: =IFERROR(__xludf.DUMMYFUNCTION("""COMPUTED_VALUE"""),115.0) -> 115 | I9: 41.317365 | J9: Breakfast | K9: =IFERROR(__xludf.DUMMYFUNCTION("""COMPUTED_VALUE"""),46050.0) -> 46050 | L9: =IFS( K9="","", WEEKDAY(K9)=1, "Sunday", WEEKDAY(K9)=2, "Monday", WEEKDAY(K9)=3, "Tuesday", WEEKDAY(K9)=4, "Wednesday", WEEKDAY(K9)=5, "Thursday", WEEKDAY(K9)=6, "Friday", WEEKDAY(K9)=7, "Saturday" ) -> Wednesday | M9: =IFERROR(__xludf.DUMMYFUNCTION("""COMPUTED_VALUE"""),"BF") -> BF | N9: 1.4573693 | O9: =IFERROR(__xludf.DUMMYFUNCTION("""COMPUTED_VALUE"""),"") | P9: =IFERROR(__xludf.DUMMYFUNCTION("""COMPUTED_VALUE"""),"") | Q9: =IFERROR(__xludf.DUMMYFUNCTION("""COMPUTED_VALUE"""),"") | R9: =IFERROR(__xludf.DUMMYFUNCTION("""COMPUTED_VALUE"""),"") | S9: =IFERROR(__xludf.DUMMYFUNCTION("""COMPUTED_VALUE"""),"") | T9: =IFERROR(__xludf.DUMMYFUNCTION("""COMPUTED_VALUE"""),"") | U9: =IFERROR(__xludf.DUMMYFUNCTION("""COMPUTED_VALUE"""),"") | V9: =IFERROR(__xludf.DUMMYFUNCTION("""COMPUTED_VALUE"""),"") | W9: =iferror(if(U9/(V9*24)=0,"",U9/(V9*24)),"") | X9: =IFERROR(__xludf.DUMMYFUNCTION("""COMPUTED_VALUE"""),"") | Y9: =IFERROR(__xludf.DUMMYFUNCTION("""COMPUTED_VALUE"""),"")
A10: =IFERROR(__xludf.DUMMYFUNCTION("""COMPUTED_VALUE"""),46050.50898162037) -> 46050.509 | B10: =IFERROR(__xludf.DUMMYFUNCTION("""COMPUTED_VALUE"""),"Oluwatimilehin Shodipe") -> Oluwatimilehin Shodipe | C10: =IF( B10="", "", AND( B10=B9, K10=K9, M10=M9, ABS(D10 - F9) <= TIME(0,25,0) ) ) -> FALSE | D10: =IFERROR(__xludf.DUMMYFUNCTION("""COMPUTED_VALUE"""),0.4437499999985448) -> 0.44375 | E10: =IFERROR(__xludf.DUMMYFUNCTION("""COMPUTED_VALUE"""),0.06666666666569654) -> 0.066666667 | F10: =IFERROR(__xludf.DUMMYFUNCTION("""COMPUTED_VALUE"""),0.5104166666642413) -> 0.51041667 | G10: 0.066666667 | H10: =IFERROR(__xludf.DUMMYFUNCTION("""COMPUTED_VALUE"""),72.0) -> 72 | I10: 45 | J10: Breakfast/Lunch | K10: =IFERROR(__xludf.DUMMYFUNCTION("""COMPUTED_VALUE"""),46050.0) -> 46050 | L10: =IFS( K10="","", WEEKDAY(K10)=1, "Sunday", WEEKDAY(K10)=2, "Monday", WEEKDAY(K10)=3, "Tuesday", WEEKDAY(K10)=4, "Wednesday", WEEKDAY(K10)=5, "Thursday", WEEKDAY(K10)=6, "Friday", WEEKDAY(K10)=7, "Saturday" ) -> Wednesday | M10: =IFERROR(__xludf.DUMMYFUNCTION("""COMPUTED_VALUE"""),"BF") -> BF | N10: 1.4085837 | O10: =IFERROR(__xludf.DUMMYFUNCTION("""COMPUTED_VALUE"""),"") | P10: =IFERROR(__xludf.DUMMYFUNCTION("""COMPUTED_VALUE"""),"") | Q10: =IFERROR(__xludf.DUMMYFUNCTION("""COMPUTED_VALUE"""),"") | R10: =IFERROR(__xludf.DUMMYFUNCTION("""COMPUTED_VALUE"""),"") | S10: =IFERROR(__xludf.DUMMYFUNCTION("""COMPUTED_VALUE"""),"") | T10: =IFERROR(__xludf.DUMMYFUNCTION("""COMPUTED_VALUE"""),"") | U10: =IFERROR(__xludf.DUMMYFUNCTION("""COMPUTED_VALUE"""),"") | V10: =IFERROR(__xludf.DUMMYFUNCTION("""COMPUTED_VALUE"""),"") | W10: =iferror(if(U10/(V10*24)=0,"",U10/(V10*24)),"") | X10: =IFERROR(__xludf.DUMMYFUNCTION("""COMPUTED_VALUE"""),"") | Y10: =IFERROR(__xludf.DUMMYFUNCTION("""COMPUTED_VALUE"""),"")
A11: =IFERROR(__xludf.DUMMYFUNCTION("""COMPUTED_VALUE"""),46050.84860915509) -> 46050.849 | B11: =IFERROR(__xludf.DUMMYFUNCTION("""COMPUTED_VALUE"""),"Maureen Surgot") -> Maureen Surgot | C11: =IF( B11="", "", AND( B11=B10, K11=K10, M11=M10, ABS(D11 - F10) <= TIME(0,25,0) ) ) -> FALSE | D11: =IFERROR(__xludf.DUMMYFUNCTION("""COMPUTED_VALUE"""),0.6875) -> 0.6875 | E11: =IFERROR(__xludf.DUMMYFUNCTION("""COMPUTED_VALUE"""),0.16666666666424135) -> 0.16666667 | F11: =IFERROR(__xludf.DUMMYFUNCTION("""COMPUTED_VALUE"""),0.8541666666642413) -> 0.85416667 | G11: 0.16666667 | H11: =IFERROR(__xludf.DUMMYFUNCTION("""COMPUTED_VALUE"""),258.0) -> 258 | I11: 64.5 | J11: Dinner | K11: =IFERROR(__xludf.DUMMYFUNCTION("""COMPUTED_VALUE"""),46050.0) -> 46050 | L11: =IFS( K11="","", WEEKDAY(K11)=1, "Sunday", WEEKDAY(K11)=2, "Monday", WEEKDAY(K11)=3, "Tuesday", WEEKDAY(K11)=4, "Wednesday", WEEKDAY(K11)=5, "Thursday", WEEKDAY(K11)=6, "Friday", WEEKDAY(K11)=7, "Saturday" ) -> Wednesday | M11: =IFERROR(__xludf.DUMMYFUNCTION("""COMPUTED_VALUE"""),"BF") -> BF | N11: 1.4516624 | O11: =IFERROR(__xludf.DUMMYFUNCTION("""COMPUTED_VALUE"""),"") | P11: =IFERROR(__xludf.DUMMYFUNCTION("""COMPUTED_VALUE"""),"") | Q11: =IFERROR(__xludf.DUMMYFUNCTION("""COMPUTED_VALUE"""),"") | R11: =IFERROR(__xludf.DUMMYFUNCTION("""COMPUTED_VALUE"""),"") | S11: =IFERROR(__xludf.DUMMYFUNCTION("""COMPUTED_VALUE"""),"") | T11: =IFERROR(__xludf.DUMMYFUNCTION("""COMPUTED_VALUE"""),"") | U11: =IFERROR(__xludf.DUMMYFUNCTION("""COMPUTED_VALUE"""),"") | V11: =IFERROR(__xludf.DUMMYFUNCTION("""COMPUTED_VALUE"""),"") | W11: =iferror(if(U11/(V11*24)=0,"",U11/(V11*24)),"") | X11: =IFERROR(__xludf.DUMMYFUNCTION("""COMPUTED_VALUE"""),"") | Y11: =IFERROR(__xludf.DUMMYFUNCTION("""COMPUTED_VALUE"""),"")
A12: =IFERROR(__xludf.DUMMYFUNCTION("""COMPUTED_VALUE"""),46050.87090170139) -> 46050.871 | B12: =IFERROR(__xludf.DUMMYFUNCTION("""COMPUTED_VALUE"""),"Brynn Hornig") -> Brynn Hornig | C12: =IF( B12="", "", AND( B12=B11, K12=K11, M12=M11, ABS(D12 - F11) <= TIME(0,25,0) ) ) -> FALSE | D12: =IFERROR(__xludf.DUMMYFUNCTION("""COMPUTED_VALUE"""),0.75) -> 0.75 | E12: =IFERROR(__xludf.DUMMYFUNCTION("""COMPUTED_VALUE"""),0.125) -> 0.125 | F12: =IFERROR(__xludf.DUMMYFUNCTION("""COMPUTED_VALUE"""),0.875) -> 0.875 | G12: 0.125 | H12: =IFERROR(__xludf.DUMMYFUNCTION("""COMPUTED_VALUE"""),130.0) -> 130 | I12: 43.333333 | J12: Dinner | K12: =IFERROR(__xludf.DUMMYFUNCTION("""COMPUTED_VALUE"""),46050.0) -> 46050 | L12: =IFS( K12="","", WEEKDAY(K12)=1, "Sunday", WEEKDAY(K12)=2, "Monday", WEEKDAY(K12)=3, "Tuesday", WEEKDAY(K12)=4, "Wednesday", WEEKDAY(K12)=5, "Thursday", WEEKDAY(K12)=6, "Friday", WEEKDAY(K12)=7, "Saturday" ) -> Wednesday | M12: =IFERROR(__xludf.DUMMYFUNCTION("""COMPUTED_VALUE"""),"MF") -> MF | N12: 0.90637584 | O12: =IFERROR(__xludf.DUMMYFUNCTION("""COMPUTED_VALUE"""),130.0) -> 130 | P12: =IFERROR(__xludf.DUMMYFUNCTION("""COMPUTED_VALUE"""),445.0) -> 445 | Q12: =IFERROR(__xludf.DUMMYFUNCTION("""COMPUTED_VALUE"""),0.125) -> 0.125 | R12: =IFERROR(__xludf.DUMMYFUNCTION("""COMPUTED_VALUE"""),0.34930555555183673) -> 0.34930556 | S12: =IFERROR(__xludf.DUMMYFUNCTION("""COMPUTED_VALUE"""),43.333333333333336) -> 43.333333 | T12: =IFERROR(__xludf.DUMMYFUNCTION("""COMPUTED_VALUE"""),50.272455090389904) -> 50.272455 | U12: =IFERROR(__xludf.DUMMYFUNCTION("""COMPUTED_VALUE"""),575.0) -> 575 | V12: =IFERROR(__xludf.DUMMYFUNCTION("""COMPUTED_VALUE"""),0.47430555555183673) -> 0.47430556 | W12: =iferror(if(U12/(V12*24)=0,"",U12/(V12*24)),"") -> 50.512445 | X12: =IFERROR(__xludf.DUMMYFUNCTION("""COMPUTED_VALUE"""),48.53767465112576) -> 48.537675 | Y12: =IFERROR(__xludf.DUMMYFUNCTION("""COMPUTED_VALUE"""),0.9878734855096749) -> 0.98787349
A13: =IFERROR(__xludf.DUMMYFUNCTION("""COMPUTED_VALUE"""),46051.53061296296) -> 46051.531 | B13: =IFERROR(__xludf.DUMMYFUNCTION("""COMPUTED_VALUE"""),"Emmett Khan") -> Emmett Khan | C13: =IF( B13="", "", AND( B13=B12, K13=K12, M13=M12, ABS(D13 - F12) <= TIME(0,25,0) ) ) -> FALSE | D13: =IFERROR(__xludf.DUMMYFUNCTION("""COMPUTED_VALUE"""),0.47916666666424135) -> 0.47916667 | E13: =IFERROR(__xludf.DUMMYFUNCTION("""COMPUTED_VALUE"""),0.04930555555620231) -> 0.049305556 | F13: =IFERROR(__xludf.DUMMYFUNCTION("""COMPUTED_VALUE"""),0.5284722222204437) -> 0.52847222 | G13: 0.049305556 | H13: =IFERROR(__xludf.DUMMYFUNCTION("""COMPUTED_VALUE"""),33.0) -> 33 | I13: 27.887324 | J13: Lunch | K13: =IFERROR(__xludf.DUMMYFUNCTION("""COMPUTED_VALUE"""),46051.0) -> 46051 | L13: =IFS( K13="","", WEEKDAY(K13)=1, "Sunday", WEEKDAY(K13)=2, "Monday", WEEKDAY(K13)=3, "Tuesday", WEEKDAY(K13)=4, "Wednesday", WEEKDAY(K13)=5, "Thursday", WEEKDAY(K13)=6, "Friday", WEEKDAY(K13)=7, "Saturday" ) -> Thursday | M13: =IFERROR(__xludf.DUMMYFUNCTION("""COMPUTED_VALUE"""),"BF") -> BF | N13: 0.98365733 | O13: =IFERROR(__xludf.DUMMYFUNCTION("""COMPUTED_VALUE"""),"") | P13: =IFERROR(__xludf.DUMMYFUNCTION("""COMPUTED_VALUE"""),"") | Q13: =IFERROR(__xludf.DUMMYFUNCTION("""COMPUTED_VALUE"""),"") | R13: =IFERROR(__xludf.DUMMYFUNCTION("""COMPUTED_VALUE"""),"") | S13: =IFERROR(__xludf.DUMMYFUNCTION("""COMPUTED_VALUE"""),"") | T13: =IFERROR(__xludf.DUMMYFUNCTION("""COMPUTED_VALUE"""),"") | U13: =IFERROR(__xludf.DUMMYFUNCTION("""COMPUTED_VALUE"""),"") | V13: =IFERROR(__xludf.DUMMYFUNCTION("""COMPUTED_VALUE"""),"") | W13: =iferror(if(U13/(V13*24)=0,"",U13/(V13*24)),"") | X13: =IFERROR(__xludf.DUMMYFUNCTION("""COMPUTED_VALUE"""),"") | Y13: =IFERROR(__xludf.DUMMYFUNCTION("""COMPUTED_VALUE"""),"")
A14: =IFERROR(__xludf.DUMMYFUNCTION("""COMPUTED_VALUE"""),46051.54014075232) -> 46051.54 | B14: =IFERROR(__xludf.DUMMYFUNCTION("""COMPUTED_VALUE"""),"Kyra Turner") -> Kyra Turner | C14: =IF( B14="", "", AND( B14=B13, K14=K13, M14=M13, ABS(D14 - F13) <= TIME(0,25,0) ) ) -> FALSE | D14: =IFERROR(__xludf.DUMMYFUNCTION("""COMPUTED_VALUE"""),0.5) -> 0.5 | E14: =IFERROR(__xludf.DUMMYFUNCTION("""COMPUTED_VALUE"""),0.03749999999854481) -> 0.0375 | F14: =IFERROR(__xludf.DUMMYFUNCTION("""COMPUTED_VALUE"""),0.5374999999985448) -> 0.5375 | G14: 0.14166667 | H14: =IFERROR(__xludf.DUMMYFUNCTION("""COMPUTED_VALUE"""),28.0) -> 28 | I14: 31.764706 | J14: Lunch | K14: =IFERROR(__xludf.DUMMYFUNCTION("""COMPUTED_VALUE"""),46051.0) -> 46051 | L14: =IFS( K14="","", WEEKDAY(K14)=1, "Sunday", WEEKDAY(K14)=2, "Monday", WEEKDAY(K14)=3, "Tuesday", WEEKDAY(K14)=4, "Wednesday", WEEKDAY(K14)=5, "Thursday", WEEKDAY(K14)=6, "Friday", WEEKDAY(K14)=7, "Saturday" ) -> Thursday | M14: =IFERROR(__xludf.DUMMYFUNCTION("""COMPUTED_VALUE"""),"BF") -> BF | N14: 1.1204225 | O14: =IFERROR(__xludf.DUMMYFUNCTION("""COMPUTED_VALUE"""),"") | P14: =IFERROR(__xludf.DUMMYFUNCTION("""COMPUTED_VALUE"""),"") | Q14: =IFERROR(__xludf.DUMMYFUNCTION("""COMPUTED_VALUE"""),"") | R14: =IFERROR(__xludf.DUMMYFUNCTION("""COMPUTED_VALUE"""),"") | S14: =IFERROR(__xludf.DUMMYFUNCTION("""COMPUTED_VALUE"""),"") | T14: =IFERROR(__xludf.DUMMYFUNCTION("""COMPUTED_VALUE"""),"") | U14: =IFERROR(__xludf.DUMMYFUNCTION("""COMPUTED_VALUE"""),"") | V14: =IFERROR(__xludf.DUMMYFUNCTION("""COMPUTED_VALUE"""),"") | W14: =iferror(if(U14/(V14*24)=0,"",U14/(V14*24)),"") | X14: =IFERROR(__xludf.DUMMYFUNCTION("""COMPUTED_VALUE"""),"") | Y14: =IFERROR(__xludf.DUMMYFUNCTION("""COMPUTED_VALUE"""),"")
A15: =IFERROR(__xludf.DUMMYFUNCTION("""COMPUTED_VALUE"""),46051.644792499996) -> 46051.645 | B15: =IFERROR(__xludf.DUMMYFUNCTION("""COMPUTED_VALUE"""),"Kyra Turner") -> Kyra Turner | C15: =IF( B15="", "", AND( B15=B14, K15=K14, M15=M14, ABS(D15 - F14) <= TIME(0,25,0) ) ) -> TRUE | D15: =IFERROR(__xludf.DUMMYFUNCTION("""COMPUTED_VALUE"""),0.5395833333313931) -> 0.53958333 | E15: =IFERROR(__xludf.DUMMYFUNCTION("""COMPUTED_VALUE"""),0.1041666666715173) -> 0.10416667 | F15: =IFERROR(__xludf.DUMMYFUNCTION("""COMPUTED_VALUE"""),0.6437500000029104) -> 0.64375 | H15: =IFERROR(__xludf.DUMMYFUNCTION("""COMPUTED_VALUE"""),80.0) -> 80 | J15: Lunch | K15: =IFERROR(__xludf.DUMMYFUNCTION("""COMPUTED_VALUE"""),46051.0) -> 46051 | L15: =IFS( K15="","", WEEKDAY(K15)=1, "Sunday", WEEKDAY(K15)=2, "Monday", WEEKDAY(K15)=3, "Tuesday", WEEKDAY(K15)=4, "Wednesday", WEEKDAY(K15)=5, "Thursday", WEEKDAY(K15)=6, "Friday", WEEKDAY(K15)=7, "Saturday" ) -> Thursday | M15: =IFERROR(__xludf.DUMMYFUNCTION("""COMPUTED_VALUE"""),"BF") -> BF | O15: =IFERROR(__xludf.DUMMYFUNCTION("""COMPUTED_VALUE"""),"") | P15: =IFERROR(__xludf.DUMMYFUNCTION("""COMPUTED_VALUE"""),"") | Q15: =IFERROR(__xludf.DUMMYFUNCTION("""COMPUTED_VALUE"""),"") | R15: =IFERROR(__xludf.DUMMYFUNCTION("""COMPUTED_VALUE"""),"") | S15: =IFERROR(__xludf.DUMMYFUNCTION("""COMPUTED_VALUE"""),"") | T15: =IFERROR(__xludf.DUMMYFUNCTION("""COMPUTED_VALUE"""),"") | U15: =IFERROR(__xludf.DUMMYFUNCTION("""COMPUTED_VALUE"""),"") | V15: =IFERROR(__xludf.DUMMYFUNCTION("""COMPUTED_VALUE"""),"") | W15: =iferror(if(U15/(V15*24)=0,"",U15/(V15*24)),"") | X15: =IFERROR(__xludf.DUMMYFUNCTION("""COMPUTED_VALUE"""),"") | Y15: =IFERROR(__xludf.DUMMYFUNCTION("""COMPUTED_VALUE"""),"")
A16: =IFERROR(__xludf.DUMMYFUNCTION("""COMPUTED_VALUE"""),46051.779202060185) -> 46051.779 | B16: =IFERROR(__xludf.DUMMYFUNCTION("""COMPUTED_VALUE"""),"Emmett Khan") -> Emmett Khan | C16: =IF( B16="", "", AND( B16=B15, K16=K15, M16=M15, ABS(D16 - F15) <= TIME(0,25,0) ) ) -> FALSE | D16: =IFERROR(__xludf.DUMMYFUNCTION("""COMPUTED_VALUE"""),0.7083333333357587) -> 0.70833333 | E16: =IFERROR(__xludf.DUMMYFUNCTION("""COMPUTED_VALUE"""),0.07291666666424135) -> 0.072916667 | F16: =IFERROR(__xludf.DUMMYFUNCTION("""COMPUTED_VALUE"""),0.78125) -> 0.78125 | G16: 0.072916667 | H16: =IFERROR(__xludf.DUMMYFUNCTION("""COMPUTED_VALUE"""),93.0) -> 93 | I16: 53.142857 | J16: Dinner | K16: =IFERROR(__xludf.DUMMYFUNCTION("""COMPUTED_VALUE"""),46051.0) -> 46051 | L16: =IFS( K16="","", WEEKDAY(K16)=1, "Sunday", WEEKDAY(K16)=2, "Monday", WEEKDAY(K16)=3, "Tuesday", WEEKDAY(K16)=4, "Wednesday", WEEKDAY(K16)=5, "Thursday", WEEKDAY(K16)=6, "Friday", WEEKDAY(K16)=7, "Saturday" ) -> Thursday | M16: =IFERROR(__xludf.DUMMYFUNCTION("""COMPUTED_VALUE"""),"MF") -> MF | N16: 1.1115554 | O16: =IFERROR(__xludf.DUMMYFUNCTION("""COMPUTED_VALUE"""),93.0) -> 93 | P16: =IFERROR(__xludf.DUMMYFUNCTION("""COMPUTED_VALUE"""),141.0) -> 141 | Q16: =IFERROR(__xludf.DUMMYFUNCTION("""COMPUTED_VALUE"""),0.07291666666424135) -> 0.072916667 | R16: =IFERROR(__xludf.DUMMYFUNCTION("""COMPUTED_VALUE"""),0.19097222222626442) -> 0.19097222 | S16: =IFERROR(__xludf.DUMMYFUNCTION("""COMPUTED_VALUE"""),53.142857144624756) -> 53.142857 | T16: =IFERROR(__xludf.DUMMYFUNCTION("""COMPUTED_VALUE"""),29.82601491244389) -> 29.826015 | U16: =IFERROR(__xludf.DUMMYFUNCTION("""COMPUTED_VALUE"""),234.0) -> 234 | V16: =IFERROR(__xludf.DUMMYFUNCTION("""COMPUTED_VALUE"""),0.26388888889050577) -> 0.26388889 | W16: =iferror(if(U16/(V16*24)=0,"",U16/(V16*24)),"") -> 36.947368 | X16: =IFERROR(__xludf.DUMMYFUNCTION("""COMPUTED_VALUE"""),37.59829565650418) -> 37.598296 | Y16: =IFERROR(__xludf.DUMMYFUNCTION("""COMPUTED_VALUE"""),0.530972742275288) -> 0.53097274
A17: =IFERROR(__xludf.DUMMYFUNCTION("""COMPUTED_VALUE"""),46052.58172553241) -> 46052.582 | B17: =IFERROR(__xludf.DUMMYFUNCTION("""COMPUTED_VALUE"""),"Brynn Hornig") -> Brynn Hornig | C17: =IF( B17="", "", AND( B17=B16, K17=K16, M17=M16, ABS(D17 - F16) <= TIME(0,25,0) ) ) -> FALSE | D17: =IFERROR(__xludf.DUMMYFUNCTION("""COMPUTED_VALUE"""),0.5208333333357587) -> 0.52083333 | E17: =IFERROR(__xludf.DUMMYFUNCTION("""COMPUTED_VALUE"""),0.0625) -> 0.0625 | F17: =IFERROR(__xludf.DUMMYFUNCTION("""COMPUTED_VALUE"""),0.5833333333357587) -> 0.58333333 | G17: 0.0625 | H17: =IFERROR(__xludf.DUMMYFUNCTION("""COMPUTED_VALUE"""),76.0) -> 76 | I17: 50.666667 | J17: Lunch | K17: =IFERROR(__xludf.DUMMYFUNCTION("""COMPUTED_VALUE"""),46052.0) -> 46052 | L17: =IFS( K17="","", WEEKDAY(K17)=1, "Sunday", WEEKDAY(K17)=2, "Monday", WEEKDAY(K17)=3, "Tuesday", WEEKDAY(K17)=4, "Wednesday", WEEKDAY(K17)=5, "Thursday", WEEKDAY(K17)=6, "Friday", WEEKDAY(K17)=7, "Saturday" ) -> Friday | M17: =IFERROR(__xludf.DUMMYFUNCTION("""COMPUTED_VALUE"""),"BF") -> BF | N17: 1.7871431 | O17: =IFERROR(__xludf.DUMMYFUNCTION("""COMPUTED_VALUE"""),"") | P17: =IFERROR(__xludf.DUMMYFUNCTION("""COMPUTED_VALUE"""),"") | Q17: =IFERROR(__xludf.DUMMYFUNCTION("""COMPUTED_VALUE"""),"") | R17: =IFERROR(__xludf.DUMMYFUNCTION("""COMPUTED_VALUE"""),"") | S17: =IFERROR(__xludf.DUMMYFUNCTION("""COMPUTED_VALUE"""),"") | T17: =IFERROR(__xludf.DUMMYFUNCTION("""COMPUTED_VALUE"""),"") | U17: =IFERROR(__xludf.DUMMYFUNCTION("""COMPUTED_VALUE"""),"") | V17: =IFERROR(__xludf.DUMMYFUNCTION("""COMPUTED_VALUE"""),"") | W17: =iferror(if(U17/(V17*24)=0,"",U17/(V17*24)),"") | X17: =IFERROR(__xludf.DUMMYFUNCTION("""COMPUTED_VALUE"""),"") | Y17: =IFERROR(__xludf.DUMMYFUNCTION("""COMPUTED_VALUE"""),"")
A18: =IFERROR(__xludf.DUMMYFUNCTION("""COMPUTED_VALUE"""),46052.6284697338) -> 46052.628 | B18: =IFERROR(__xludf.DUMMYFUNCTION("""COMPUTED_VALUE"""),"Oluwatimilehin Shodipe") -> Oluwatimilehin Shodipe | C18: =IF( B18="", "", AND( B18=B17, K18=K17, M18=M17, ABS(D18 - F17) <= TIME(0,25,0) ) ) -> FALSE | D18: =IFERROR(__xludf.DUMMYFUNCTION("""COMPUTED_VALUE"""),0.48263888889050577) -> 0.48263889 | E18: =IFERROR(__xludf.DUMMYFUNCTION("""COMPUTED_VALUE"""),0.14236111110949423) -> 0.14236111 | F18: =IFERROR(__xludf.DUMMYFUNCTION("""COMPUTED_VALUE"""),0.625) -> 0.625 | G18: 0.14236111 | H18: =IFERROR(__xludf.DUMMYFUNCTION("""COMPUTED_VALUE"""),144.0) -> 144 | I18: 42.146341 | J18: Lunch | K18: =IFERROR(__xludf.DUMMYFUNCTION("""COMPUTED_VALUE"""),46052.0) -> 46052 | L18: =IFS( K18="","", WEEKDAY(K18)=1, "Sunday", WEEKDAY(K18)=2, "Monday", WEEKDAY(K18)=3, "Tuesday", WEEKDAY(K18)=4, "Wednesday", WEEKDAY(K18)=5, "Thursday", WEEKDAY(K18)=6, "Friday", WEEKDAY(K18)=7, "Saturday" ) -> Friday | M18: =IFERROR(__xludf.DUMMYFUNCTION("""COMPUTED_VALUE"""),"MF") -> MF | N18: 0.8382745 | O18: =IFERROR(__xludf.DUMMYFUNCTION("""COMPUTED_VALUE"""),"") | P18: =IFERROR(__xludf.DUMMYFUNCTION("""COMPUTED_VALUE"""),"") | Q18: =IFERROR(__xludf.DUMMYFUNCTION("""COMPUTED_VALUE"""),"") | R18: =IFERROR(__xludf.DUMMYFUNCTION("""COMPUTED_VALUE"""),"") | S18: =IFERROR(__xludf.DUMMYFUNCTION("""COMPUTED_VALUE"""),"") | T18: =IFERROR(__xludf.DUMMYFUNCTION("""COMPUTED_VALUE"""),"") | U18: =IFERROR(__xludf.DUMMYFUNCTION("""COMPUTED_VALUE"""),"") | V18: =IFERROR(__xludf.DUMMYFUNCTION("""COMPUTED_VALUE"""),"") | W18: =iferror(if(U18/(V18*24)=0,"",U18/(V18*24)),"") | X18: =IFERROR(__xludf.DUMMYFUNCTION("""COMPUTED_VALUE"""),"") | Y18: =IFERROR(__xludf.DUMMYFUNCTION("""COMPUTED_VALUE"""),"")
A19: =IFERROR(__xludf.DUMMYFUNCTION("""COMPUTED_VALUE"""),46052.80948892361) -> 46052.809 | B19: =IFERROR(__xludf.DUMMYFUNCTION("""COMPUTED_VALUE"""),"Orpheus Wilson") -> Orpheus Wilson | C19: =IF( B19="", "", AND( B19=B18, K19=K18, M19=M18, ABS(D19 - F18) <= TIME(0,25,0) ) ) -> FALSE | D19: =IFERROR(__xludf.DUMMYFUNCTION("""COMPUTED_VALUE"""),0.7472222222204437) -> 0.74722222 | E19: =IFERROR(__xludf.DUMMYFUNCTION("""COMPUTED_VALUE"""),0.061111111113859806) -> 0.061111111 | F19: =IFERROR(__xludf.DUMMYFUNCTION("""COMPUTED_VALUE"""),0.8083333333343035) -> 0.80833333 | G19: 0.074305556 | H19: =IFERROR(__xludf.DUMMYFUNCTION("""COMPUTED_VALUE"""),158.0) -> 158 | I19: 107.1028 | J19: Dinner | K19: =IFERROR(__xludf.DUMMYFUNCTION("""COMPUTED_VALUE"""),46052.0) -> 46052 | L19: =IFS( K19="","", WEEKDAY(K19)=1, "Sunday", WEEKDAY(K19)=2, "Monday", WEEKDAY(K19)=3, "Tuesday", WEEKDAY(K19)=4, "Wednesday", WEEKDAY(K19)=5, "Thursday", WEEKDAY(K19)=6, "Friday", WEEKDAY(K19)=7, "Saturday" ) -> Friday | M19: =IFERROR(__xludf.DUMMYFUNCTION("""COMPUTED_VALUE"""),"MF") -> MF | N19: 2.2402014 | O19: =IFERROR(__xludf.DUMMYFUNCTION("""COMPUTED_VALUE"""),"") | P19: =IFERROR(__xludf.DUMMYFUNCTION("""COMPUTED_VALUE"""),"") | Q19: =IFERROR(__xludf.DUMMYFUNCTION("""COMPUTED_VALUE"""),"") | R19: =IFERROR(__xludf.DUMMYFUNCTION("""COMPUTED_VALUE"""),"") | S19: =IFERROR(__xludf.DUMMYFUNCTION("""COMPUTED_VALUE"""),"") | T19: =IFERROR(__xludf.DUMMYFUNCTION("""COMPUTED_VALUE"""),"") | U19: =IFERROR(__xludf.DUMMYFUNCTION("""COMPUTED_VALUE"""),"") | V19: =IFERROR(__xludf.DUMMYFUNCTION("""COMPUTED_VALUE"""),"") | W19: =iferror(if(U19/(V19*24)=0,"",U19/(V19*24)),"") | X19: =IFERROR(__xludf.DUMMYFUNCTION("""COMPUTED_VALUE"""),"") | Y19: =IFERROR(__xludf.DUMMYFUNCTION("""COMPUTED_VALUE"""),"")
A20: =IFERROR(__xludf.DUMMYFUNCTION("""COMPUTED_VALUE"""),46052.83015725695) -> 46052.83 | B20: =IFERROR(__xludf.DUMMYFUNCTION("""COMPUTED_VALUE"""),"Orpheus Wilson") -> Orpheus Wilson | C20: =IF( B20="", "", AND( B20=B19, K20=K19, M20=M19, ABS(D20 - F19) <= TIME(0,25,0) ) ) -> TRUE | D20: =IFERROR(__xludf.DUMMYFUNCTION("""COMPUTED_VALUE"""),0.8145833333328483) -> 0.81458333 | E20: =IFERROR(__xludf.DUMMYFUNCTION("""COMPUTED_VALUE"""),0.013194444443797693) -> 0.013194444 | F20: =IFERROR(__xludf.DUMMYFUNCTION("""COMPUTED_VALUE"""),0.827777777776646) -> 0.82777778 | H20: =IFERROR(__xludf.DUMMYFUNCTION("""COMPUTED_VALUE"""),33.0) -> 33 | J20: Dinner | K20: =IFERROR(__xludf.DUMMYFUNCTION("""COMPUTED_VALUE"""),46052.0) -> 46052 | L20: =IFS( K20="","", WEEKDAY(K20)=1, "Sunday", WEEKDAY(K20)=2, "Monday", WEEKDAY(K20)=3, "Tuesday", WEEKDAY(K20)=4, "Wednesday", WEEKDAY(K20)=5, "Thursday", WEEKDAY(K20)=6, "Friday", WEEKDAY(K20)=7, "Saturday" ) -> Friday | M20: =IFERROR(__xludf.DUMMYFUNCTION("""COMPUTED_VALUE"""),"MF") -> MF | O20: =IFERROR(__xludf.DUMMYFUNCTION("""COMPUTED_VALUE"""),335.0) -> 335 | P20: =IFERROR(__xludf.DUMMYFUNCTION("""COMPUTED_VALUE"""),76.0) -> 76 | Q20: =IFERROR(__xludf.DUMMYFUNCTION("""COMPUTED_VALUE"""),0.21666666666715173) -> 0.21666667 | R20: =IFERROR(__xludf.DUMMYFUNCTION("""COMPUTED_VALUE"""),0.0625) -> 0.0625 | S20: =IFERROR(__xludf.DUMMYFUNCTION("""COMPUTED_VALUE"""),74.62457259959068) -> 74.624573 | T20: =IFERROR(__xludf.DUMMYFUNCTION("""COMPUTED_VALUE"""),50.666666666666664) -> 50.666667 | U20: =IFERROR(__xludf.DUMMYFUNCTION("""COMPUTED_VALUE"""),411.0) -> 411 | V20: =IFERROR(__xludf.DUMMYFUNCTION("""COMPUTED_VALUE"""),0.27916666666715173) -> 0.27916667 | W20: =iferror(if(U20/(V20*24)=0,"",U20/(V20*24)),"") -> 61.343284 | X20: =IFERROR(__xludf.DUMMYFUNCTION("""COMPUTED_VALUE"""),66.63860395528268) -> 66.638604 | Y20: =IFERROR(__xludf.DUMMYFUNCTION("""COMPUTED_VALUE"""),0.9348645004118957) -> 0.9348645
A21: =IFERROR(__xludf.DUMMYFUNCTION("""COMPUTED_VALUE"""),46055.643042905096) -> 46055.643 | B21: =IFERROR(__xludf.DUMMYFUNCTION("""COMPUTED_VALUE"""),"Brynn Hornig") -> Brynn Hornig | C21: =IF( B21="", "", AND( B21=B20, K21=K20, M21=M20, ABS(D21 - F20) <= TIME(0,25,0) ) ) -> FALSE | D21: =IFERROR(__xludf.DUMMYFUNCTION("""COMPUTED_VALUE"""),0.5208333333357587) -> 0.52083333 | E21: =IFERROR(__xludf.DUMMYFUNCTION("""COMPUTED_VALUE"""),0.125) -> 0.125 | F21: =IFERROR(__xludf.DUMMYFUNCTION("""COMPUTED_VALUE"""),0.6458333333357587) -> 0.64583333 | G21: 0.125 | H21: =IFERROR(__xludf.DUMMYFUNCTION("""COMPUTED_VALUE"""),106.0) -> 106 | I21: 35.333333 | J21: Lunch | K21: =IFERROR(__xludf.DUMMYFUNCTION("""COMPUTED_VALUE"""),46055.0) -> 46055 | L21: =IFS( K21="","", WEEKDAY(K21)=1, "Sunday", WEEKDAY(K21)=2, "Monday", WEEKDAY(K21)=3, "Tuesday", WEEKDAY(K21)=4, "Wednesday", WEEKDAY(K21)=5, "Thursday", WEEKDAY(K21)=6, "Friday", WEEKDAY(K21)=7, "Saturday" ) -> Monday | M21: =IFERROR(__xludf.DUMMYFUNCTION("""COMPUTED_VALUE"""),"BF") -> BF | N21: 1.2462971 | O21: =IFERROR(__xludf.DUMMYFUNCTION("""COMPUTED_VALUE"""),"") | P21: =IFERROR(__xludf.DUMMYFUNCTION("""COMPUTED_VALUE"""),"") | Q21: =IFERROR(__xludf.DUMMYFUNCTION("""COMPUTED_VALUE"""),"") | R21: =IFERROR(__xludf.DUMMYFUNCTION("""COMPUTED_VALUE"""),"") | S21: =IFERROR(__xludf.DUMMYFUNCTION("""COMPUTED_VALUE"""),"") | T21: =IFERROR(__xludf.DUMMYFUNCTION("""COMPUTED_VALUE"""),"") | U21: =IFERROR(__xludf.DUMMYFUNCTION("""COMPUTED_VALUE"""),"") | V21: =IFERROR(__xludf.DUMMYFUNCTION("""COMPUTED_VALUE"""),"") | W21: =iferror(if(U21/(V21*24)=0,"",U21/(V21*24)),"") | X21: =IFERROR(__xludf.DUMMYFUNCTION("""COMPUTED_VALUE"""),"") | Y21: =IFERROR(__xludf.DUMMYFUNCTION("""COMPUTED_VALUE"""),"")
A22: =IFERROR(__xludf.DUMMYFUNCTION("""COMPUTED_VALUE"""),46055.7456662037) -> 46055.746 | B22: =IFERROR(__xludf.DUMMYFUNCTION("""COMPUTED_VALUE"""),"Orpheus Wilson") -> Orpheus Wilson | C22: =IF( B22="", "", AND( B22=B21, K22=K21, M22=M21, ABS(D22 - F21) <= TIME(0,25,0) ) ) -> FALSE | D22: =IFERROR(__xludf.DUMMYFUNCTION("""COMPUTED_VALUE"""),0.6666666666642413) -> 0.66666667 | E22: =IFERROR(__xludf.DUMMYFUNCTION("""COMPUTED_VALUE"""),0.07638888889050577) -> 0.076388889 | F22: =IFERROR(__xludf.DUMMYFUNCTION("""COMPUTED_VALUE"""),0.7430555555547471) -> 0.74305556 | G22: 0.076388889 | H22: =IFERROR(__xludf.DUMMYFUNCTION("""COMPUTED_VALUE"""),99.0) -> 99 | I22: 54 | J22: Dinner | K22: =IFERROR(__xludf.DUMMYFUNCTION("""COMPUTED_VALUE"""),46055.0) -> 46055 | L22: =IFS( K22="","", WEEKDAY(K22)=1, "Sunday", WEEKDAY(K22)=2, "Monday", WEEKDAY(K22)=3, "Tuesday", WEEKDAY(K22)=4, "Wednesday", WEEKDAY(K22)=5, "Thursday", WEEKDAY(K22)=6, "Friday", WEEKDAY(K22)=7, "Saturday" ) -> Monday | M22: =IFERROR(__xludf.DUMMYFUNCTION("""COMPUTED_VALUE"""),"MF") -> MF | N22: 1.1294837 | O22: =IFERROR(__xludf.DUMMYFUNCTION("""COMPUTED_VALUE"""),"") | P22: =IFERROR(__xludf.DUMMYFUNCTION("""COMPUTED_VALUE"""),"") | Q22: =IFERROR(__xludf.DUMMYFUNCTION("""COMPUTED_VALUE"""),"") | R22: =IFERROR(__xludf.DUMMYFUNCTION("""COMPUTED_VALUE"""),"") | S22: =IFERROR(__xludf.DUMMYFUNCTION("""COMPUTED_VALUE"""),"") | T22: =IFERROR(__xludf.DUMMYFUNCTION("""COMPUTED_VALUE"""),"") | U22: =IFERROR(__xludf.DUMMYFUNCTION("""COMPUTED_VALUE"""),"") | V22: =IFERROR(__xludf.DUMMYFUNCTION("""COMPUTED_VALUE"""),"") | W22: =iferror(if(U22/(V22*24)=0,"",U22/(V22*24)),"") | X22: =IFERROR(__xludf.DUMMYFUNCTION("""COMPUTED_VALUE"""),"") | Y22: =IFERROR(__xludf.DUMMYFUNCTION("""COMPUTED_VALUE"""),"")
A23: =IFERROR(__xludf.DUMMYFUNCTION("""COMPUTED_VALUE"""),46055.86231668982) -> 46055.862 | B23: =IFERROR(__xludf.DUMMYFUNCTION("""COMPUTED_VALUE"""),"Arjya Aich") -> Arjya Aich | C23: =IF( B23="", "", AND( B23=B22, K23=K22, M23=M22, ABS(D23 - F22) <= TIME(0,25,0) ) ) -> FALSE | D23: =IFERROR(__xludf.DUMMYFUNCTION("""COMPUTED_VALUE"""),0.6875) -> 0.6875 | E23: =IFERROR(__xludf.DUMMYFUNCTION("""COMPUTED_VALUE"""),0.17013888889050577) -> 0.17013889 | F23: =IFERROR(__xludf.DUMMYFUNCTION("""COMPUTED_VALUE"""),0.8576388888905058) -> 0.85763889 | G23: 0.17013889 | H23: =IFERROR(__xludf.DUMMYFUNCTION("""COMPUTED_VALUE"""),171.0) -> 171 | I23: 41.877551 | J23: Dinner | K23: =IFERROR(__xludf.DUMMYFUNCTION("""COMPUTED_VALUE"""),46055.0) -> 46055 | L23: =IFS( K23="","", WEEKDAY(K23)=1, "Sunday", WEEKDAY(K23)=2, "Monday", WEEKDAY(K23)=3, "Tuesday", WEEKDAY(K23)=4, "Wednesday", WEEKDAY(K23)=5, "Thursday", WEEKDAY(K23)=6, "Friday", WEEKDAY(K23)=7, "Saturday" ) -> Monday | M23: =IFERROR(__xludf.DUMMYFUNCTION("""COMPUTED_VALUE"""),"BF") -> BF | N23: 0.94251266 | O23: =IFERROR(__xludf.DUMMYFUNCTION("""COMPUTED_VALUE"""),"") | P23: =IFERROR(__xludf.DUMMYFUNCTION("""COMPUTED_VALUE"""),"") | Q23: =IFERROR(__xludf.DUMMYFUNCTION("""COMPUTED_VALUE"""),"") | R23: =IFERROR(__xludf.DUMMYFUNCTION("""COMPUTED_VALUE"""),"") | S23: =IFERROR(__xludf.DUMMYFUNCTION("""COMPUTED_VALUE"""),"") | T23: =IFERROR(__xludf.DUMMYFUNCTION("""COMPUTED_VALUE"""),"") | U23: =IFERROR(__xludf.DUMMYFUNCTION("""COMPUTED_VALUE"""),"") | V23: =IFERROR(__xludf.DUMMYFUNCTION("""COMPUTED_VALUE"""),"") | W23: =iferror(if(U23/(V23*24)=0,"",U23/(V23*24)),"") | X23: =IFERROR(__xludf.DUMMYFUNCTION("""COMPUTED_VALUE"""),"") | Y23: =IFERROR(__xludf.DUMMYFUNCTION("""COMPUTED_VALUE"""),"")
A24: =IFERROR(__xludf.DUMMYFUNCTION("""COMPUTED_VALUE"""),46055.86573452546) -> 46055.866 | B24: =IFERROR(__xludf.DUMMYFUNCTION("""COMPUTED_VALUE"""),"Maureen Surgot") -> Maureen Surgot | C24: =IF( B24="", "", AND( B24=B23, K24=K23, M24=M23, ABS(D24 - F23) <= TIME(0,25,0) ) ) -> FALSE | D24: =IFERROR(__xludf.DUMMYFUNCTION("""COMPUTED_VALUE"""),0.75) -> 0.75 | E24: =IFERROR(__xludf.DUMMYFUNCTION("""COMPUTED_VALUE"""),0.125) -> 0.125 | F24: =IFERROR(__xludf.DUMMYFUNCTION("""COMPUTED_VALUE"""),0.875) -> 0.875 | G24: 0.125 | H24: =IFERROR(__xludf.DUMMYFUNCTION("""COMPUTED_VALUE"""),144.0) -> 144 | I24: 48 | J24: Dinner | K24: =IFERROR(__xludf.DUMMYFUNCTION("""COMPUTED_VALUE"""),46055.0) -> 46055 | L24: =IFS( K24="","", WEEKDAY(K24)=1, "Sunday", WEEKDAY(K24)=2, "Monday", WEEKDAY(K24)=3, "Tuesday", WEEKDAY(K24)=4, "Wednesday", WEEKDAY(K24)=5, "Thursday", WEEKDAY(K24)=6, "Friday", WEEKDAY(K24)=7, "Saturday" ) -> Monday | M24: =IFERROR(__xludf.DUMMYFUNCTION("""COMPUTED_VALUE"""),"MF") -> MF | N24: 1.0039855 | O24: =IFERROR(__xludf.DUMMYFUNCTION("""COMPUTED_VALUE"""),243.0) -> 243 | P24: =IFERROR(__xludf.DUMMYFUNCTION("""COMPUTED_VALUE"""),277.0) -> 277 | Q24: =IFERROR(__xludf.DUMMYFUNCTION("""COMPUTED_VALUE"""),0.20138888889050577) -> 0.20138889 | R24: =IFERROR(__xludf.DUMMYFUNCTION("""COMPUTED_VALUE"""),0.29513888889050577) -> 0.29513889 | S24: =IFERROR(__xludf.DUMMYFUNCTION("""COMPUTED_VALUE"""),50.99999999942851) -> 51 | T24: =IFERROR(__xludf.DUMMYFUNCTION("""COMPUTED_VALUE"""),38.60544217667176) -> 38.605442 | U24: =IFERROR(__xludf.DUMMYFUNCTION("""COMPUTED_VALUE"""),520.0) -> 520 | V24: =IFERROR(__xludf.DUMMYFUNCTION("""COMPUTED_VALUE"""),0.49652777778101154) -> 0.49652778 | W24: =iferror(if(U24/(V24*24)=0,"",U24/(V24*24)),"") -> 43.636364 | X24: =IFERROR(__xludf.DUMMYFUNCTION("""COMPUTED_VALUE"""),44.802721088050134) -> 44.802721 | Y24: =IFERROR(__xludf.DUMMYFUNCTION("""COMPUTED_VALUE"""),0.8149750612897129) -> 0.81497506
