Workbook

Sheet YoY Viz Data
A1: Bulk Tab → | B1: S24 | C1: F24 | D1: S25 | E1: F25 | F1: S26
A2: Sem Start Date → | B2: =MIN('S24'!$K:$K) -> 45313 | C2: =MIN('F24'!$K:$K) -> 45544 | D2: =MIN('S25'!$K:$K) -> 45677 | E2: =MIN('F25'!$K:$K) -> 45908 | F2: =MIN('S26'!$K:$K) -> 46041
A4: T8 · lbs by Period per Semester → stacked bar chart
A5: Period | B5: S24 | C5: F24 | D5: S25 | E5: F25 | F5: S26*
A6: Breakfast | B6: =IFERROR(SUMIF('S24'!$J:$J,"Breakfast",'S24'!$H:$H),0) -> 727.18 | C6: =IFERROR(SUMIF('F24'!$J:$J,"Breakfast",'F24'!$H:$H),0) -> 2685 | D6: =IFERROR(SUMIF('S25'!$J:$J,"Breakfast",'S25'!$H:$H),0) -> 4199 | E6: =IFERROR(SUMIF('F25'!$J:$J,"Breakfast",'F25'!$H:$H),0) -> 1851 | F6: =IFERROR(SUMIF('S26'!$J:$J,"Breakfast",'S26'!$H:$H),0) -> 2634
A7: Lunch | B7: =IFERROR(SUMIF('S24'!$J:$J,"Lunch",'S24'!$H:$H),0) -> 3747.78 | C7: =IFERROR(SUMIF('F24'!$J:$J,"Lunch",'F24'!$H:$H),0) -> 12163 | D7: =IFERROR(SUMIF('S25'!$J:$J,"Lunch",'S25'!$H:$H),0) -> 13311 | E7: =IFERROR(SUMIF('F25'!$J:$J,"Lunch",'F25'!$H:$H),0) -> 14184.5 | F7: =IFERROR(SUMIF('S26'!$J:$J,"Lunch",'S26'!$H:$H),0) -> 9821
A8: Dinner | B8: =IFERROR(SUMIF('S24'!$J:$J,"Dinner",'S24'!$H:$H),0) -> 2431.9 | C8: =IFERROR(SUMIF('F24'!$J:$J,"Dinner",'F24'!$H:$H),0) -> 10619 | D8: =IFERROR(SUMIF('S25'!$J:$J,"Dinner",'S25'!$H:$H),0) -> 13563 | E8: =IFERROR(SUMIF('F25'!$J:$J,"Dinner",'F25'!$H:$H),0) -> 15726.5 | F8: =IFERROR(SUMIF('S26'!$J:$J,"Dinner",'S26'!$H:$H),0) -> 13964
A9: Breakfast/Lunch | B9: =IFERROR(SUMIF('S24'!$J:$J,"Breakfast/Lunch",'S24'!$H:$H),0) -> 0 | C9: =IFERROR(SUMIF('F24'!$J:$J,"Breakfast/Lunch",'F24'!$H:$H),0) -> 919 | D9: =IFERROR(SUMIF('S25'!$J:$J,"Breakfast/Lunch",'S25'!$H:$H),0) -> 0 | E9: =IFERROR(SUMIF('F25'!$J:$J,"Breakfast/Lunch",'F25'!$H:$H),0) -> 1675 | F9: =IFERROR(SUMIF('S26'!$J:$J,"Breakfast/Lunch",'S26'!$H:$H),0) -> 2141
A10: Total | B10: =SUM('YoY Viz Data'!$B$6:$B$9) -> 6906.86 | C10: =SUM('YoY Viz Data'!$C$6:$C$9) -> 26386 | D10: =SUM('YoY Viz Data'!$D$6:$D$9) -> 31073 | E10: =SUM('YoY Viz Data'!$E$6:$E$9) -> 33437 | F10: =SUM('YoY Viz Data'!$F$6:$F$9) -> 28560
A11: † S24: period approximated from timestamp hour (B: 6–11am, L: 11am–4pm, D: 4–10pm). Dining Hall unavailable for S24.
A13: T9 · lbs by Period × Hall per Semester → grouped bar / heatmap
A14: Period | B14: Hall | C14: S24 | D14: F24 | E14: S25 | F14: F25 | G14: S26*
A15: Dinner | B15: MF | C15: =IFERROR(SUMIFS('S24'!$H:$H,'S24'!$J:$J,"Dinner",'S24'!$M:$M,"MF"),0) -> 0 | D15: =IFERROR(SUMIFS('F24'!$H:$H,'F24'!$J:$J,"Dinner",'F24'!$M:$M,"MF"),0) -> 5145 | E15: =IFERROR(SUMIFS('S25'!$H:$H,'S25'!$J:$J,"Dinner",'S25'!$M:$M,"MF"),0) -> 7476 | F15: =IFERROR(SUMIFS('F25'!$H:$H,'F25'!$J:$J,"Dinner",'F25'!$M:$M,"MF"),0) -> 8260 | G15: =IFERROR(SUMIFS('S26'!$H:$H,'S26'!$J:$J,"Dinner",'S26'!$M:$M,"MF"),0) -> 8696
A16: Dinner | B16: BF | C16: =IFERROR(SUMIFS('S24'!$H:$H,'S24'!$J:$J,"Dinner",'S24'!$M:$M,"BF"),0) -> 0 | D16: =IFERROR(SUMIFS('F24'!$H:$H,'F24'!$J:$J,"Dinner",'F24'!$M:$M,"BF"),0) -> 5474 | E16: =IFERROR(SUMIFS('S25'!$H:$H,'S25'!$J:$J,"Dinner",'S25'!$M:$M,"BF"),0) -> 6087 | F16: =IFERROR(SUMIFS('F25'!$H:$H,'F25'!$J:$J,"Dinner",'F25'!$M:$M,"BF"),0) -> 7466.5 | G16: =IFERROR(SUMIFS('S26'!$H:$H,'S26'!$J:$J,"Dinner",'S26'!$M:$M,"BF"),0) -> 5268
A17: Lunch | B17: MF | C17: =IFERROR(SUMIFS('S24'!$H:$H,'S24'!$J:$J,"Lunch",'S24'!$M:$M,"MF"),0) -> 0 | D17: =IFERROR(SUMIFS('F24'!$H:$H,'F24'!$J:$J,"Lunch",'F24'!$M:$M,"MF"),0) -> 6636 | E17: =IFERROR(SUMIFS('S25'!$H:$H,'S25'!$J:$J,"Lunch",'S25'!$M:$M,"MF"),0) -> 6793 | F17: =IFERROR(SUMIFS('F25'!$H:$H,'F25'!$J:$J,"Lunch",'F25'!$M:$M,"MF"),0) -> 9189 | G17: =IFERROR(SUMIFS('S26'!$H:$H,'S26'!$J:$J,"Lunch",'S26'!$M:$M,"MF"),0) -> 6214
A18: Lunch | B18: BF | C18: =IFERROR(SUMIFS('S24'!$H:$H,'S24'!$J:$J,"Lunch",'S24'!$M:$M,"BF"),0) -> 0 | D18: =IFERROR(SUMIFS('F24'!$H:$H,'F24'!$J:$J,"Lunch",'F24'!$M:$M,"BF"),0) -> 5527 | E18: =IFERROR(SUMIFS('S25'!$H:$H,'S25'!$J:$J,"Lunch",'S25'!$M:$M,"BF"),0) -> 6518 | F18: =IFERROR(SUMIFS('F25'!$H:$H,'F25'!$J:$J,"Lunch",'F25'!$M:$M,"BF"),0) -> 4995.5 | G18: =IFERROR(SUMIFS('S26'!$H:$H,'S26'!$J:$J,"Lunch",'S26'!$M:$M,"BF"),0) -> 3607
A19: Breakfast | B19: BF | C19: =IFERROR(SUMIFS('S24'!$H:$H,'S24'!$J:$J,"Breakfast",'S24'!$M:$M,"BF"),0) -> 0 | D19: =IFERROR(SUMIFS('F24'!$H:$H,'F24'!$J:$J,"Breakfast",'F24'!$M:$M,"BF"),0) -> 2685 | E19: =IFERROR(SUMIFS('S25'!$H:$H,'S25'!$J:$J,"Breakfast",'S25'!$M:$M,"BF"),0) -> 4199 | F19: =IFERROR(SUMIFS('F25'!$H:$H,'F25'!$J:$J,"Breakfast",'F25'!$M:$M,"BF"),0) -> 1851 | G19: =IFERROR(SUMIFS('S26'!$H:$H,'S26'!$J:$J,"Breakfast",'S26'!$M:$M,"BF"),0) -> 2616
A20: Breakfast/Lunch | B20: BF | C20: =IFERROR(SUMIFS('S24'!$H:$H,'S24'!$J:$J,"Breakfast/Lunch",'S24'!$M:$M,"BF"),0) -> 0 | D20: =IFERROR(SUMIFS('F24'!$H:$H,'F24'!$J:$J,"Breakfast/Lunch",'F24'!$M:$M,"BF"),0) -> 919 | E20: =IFERROR(SUMIFS('S25'!$H:$H,'S25'!$J:$J,"Breakfast/Lunch",'S25'!$M:$M,"BF"),0) -> 0 | F20: =IFERROR(SUMIFS('F25'!$H:$H,'F25'!$J:$J,"Breakfast/Lunch",'F25'!$M:$M,"BF"),0) -> 1675 | G20: =IFERROR(SUMIFS('S26'!$H:$H,'S26'!$J:$J,"Breakfast/Lunch",'S26'!$M:$M,"BF"),0) -> 2141
A21: † S24: Dining Hall not collected — all S24 values are 0. Rows with < 50 lbs total pruned.
A23: T10 · Weekly lbs within Semester → multi-line overlay chart
A24: Week | B24: Average | C24: S24 | D24: S24 date | E24: S24 notes | F24: F24 | G24: F24 date | H24: F24 notes | I24: S25 | J24: S25 date | K24: S25 notes | L24: F25 | M24: F25 date | N24: F25 notes | O24: S26* | P24: S26* date | Q24: S26* notes
A25: 1 | B25: =IFERROR((IF(ISNUMBER(C25),C25,0)+IF(ISNUMBER(F25),F25,0)+IF(ISNUMBER(I25),I25,0)+IF(ISNUMBER(L25),L25,0)+IF(ISNUMBER(O25),O25,0))/(ISNUMBER(C25)*1+ISNUMBER(F25)*1+ISNUMBER(I25)*1+ISNUMBER(L25)*1+ISNUMBER(O25)*1),"") -> 1201.6667 | C25: =IFERROR(IF(SUMPRODUCT(('S24'!$K$3:$K$600>=$B$2+0)*('S24'!$K$3:$K$600<$B$2+7)*('S24'!$H$3:$H$600))=0,"",SUMPRODUCT(('S24'!$K$3:$K$600>=$B$2+0)*('S24'!$K$3:$K$600<$B$2+7)*('S24'!$H$3:$H$600))),"") | D25: S24 · Jan 22, 2024 | F25: =IFERROR(IF(SUMPRODUCT(('F24'!$K$3:$K$600>=$C$2+0)*('F24'!$K$3:$K$600<$C$2+7)*('F24'!$H$3:$H$600))=0,"",SUMPRODUCT(('F24'!$K$3:$K$600>=$C$2+0)*('F24'!$K$3:$K$600<$C$2+7)*('F24'!$H$3:$H$600))),"") -> 1079 | G25: F24 · Sep 9, 2024 | I25: =IFERROR(IF(SUMPRODUCT(('S25'!$K$3:$K$600>=$D$2+0)*('S25'!$K$3:$K$600<$D$2+7)*('S25'!$H$3:$H$600))=0,"",SUMPRODUCT(('S25'!$K$3:$K$600>=$D$2+0)*('S25'!$K$3:$K$600<$D$2+7)*('S25'!$H$3:$H$600))),"") | J25: S25 · Jan 20, 2025 | L25: =IFERROR(IF(SUMPRODUCT(('F25'!$K$3:$K$600>=$E$2+0)*('F25'!$K$3:$K$600<$E$2+7)*('F25'!$H$3:$H$600))=0,"",SUMPRODUCT(('F25'!$K$3:$K$600>=$E$2+0)*('F25'!$K$3:$K$600<$E$2+7)*('F25'!$H$3:$H$600))),"") -> 2036 | M25: F25 · Sep 8, 2025 | O25: =IFERROR(IF(SUMPRODUCT(('S26'!$K$3:$K$600>=$F$2+0)*('S26'!$K$3:$K$600<$F$2+7)*('S26'!$H$3:$H$600))=0,"",SUMPRODUCT(('S26'!$K$3:$K$600>=$F$2+0)*('S26'!$K$3:$K$600<$F$2+7)*('S26'!$H$3:$H$600))),"") -> 490 | P25: S26* · Jan 19, 2026
A26: 2 | B26: =IFERROR((IF(ISNUMBER(C26),C26,0)+IF(ISNUMBER(F26),F26,0)+IF(ISNUMBER(I26),I26,0)+IF(ISNUMBER(L26),L26,0)+IF(ISNUMBER(O26),O26,0))/(ISNUMBER(C26)*1+ISNUMBER(F26)*1+ISNUMBER(I26)*1+ISNUMBER(L26)*1+ISNUMBER(O26)*1),"") -> 1950.25 | C26: =IFERROR(IF(SUMPRODUCT(('S24'!$K$3:$K$600>=$B$2+7)*('S24'!$K$3:$K$600<$B$2+14)*('S24'!$H$3:$H$600))=0,"",SUMPRODUCT(('S24'!$K$3:$K$600>=$B$2+7)*('S24'!$K$3:$K$600<$B$2+14)*('S24'!$H$3:$H$600))),"") | D26: S24 · Jan 29, 2024 | F26: =IFERROR(IF(SUMPRODUCT(('F24'!$K$3:$K$600>=$C$2+7)*('F24'!$K$3:$K$600<$C$2+14)*('F24'!$H$3:$H$600))=0,"",SUMPRODUCT(('F24'!$K$3:$K$600>=$C$2+7)*('F24'!$K$3:$K$600<$C$2+14)*('F24'!$H$3:$H$600))),"") -> 1634 | G26: F24 · Sep 16, 2024 | I26: =IFERROR(IF(SUMPRODUCT(('S25'!$K$3:$K$600>=$D$2+7)*('S25'!$K$3:$K$600<$D$2+14)*('S25'!$H$3:$H$600))=0,"",SUMPRODUCT(('S25'!$K$3:$K$600>=$D$2+7)*('S25'!$K$3:$K$600<$D$2+14)*('S25'!$H$3:$H$600))),"") -> 2292 | J26: S25 · Jan 27, 2025 | L26: =IFERROR(IF(SUMPRODUCT(('F25'!$K$3:$K$600>=$E$2+7)*('F25'!$K$3:$K$600<$E$2+14)*('F25'!$H$3:$H$600))=0,"",SUMPRODUCT(('F25'!$K$3:$K$600>=$E$2+7)*('F25'!$K$3:$K$600<$E$2+14)*('F25'!$H$3:$H$600))),"") -> 2521 | M26: F25 · Sep 15, 2025 | O26: =IFERROR(IF(SUMPRODUCT(('S26'!$K$3:$K$600>=$F$2+7)*('S26'!$K$3:$K$600<$F$2+14)*('S26'!$H$3:$H$600))=0,"",SUMPRODUCT(('S26'!$K$3:$K$600>=$F$2+7)*('S26'!$K$3:$K$600<$F$2+14)*('S26'!$H$3:$H$600))),"") -> 1354 | P26: S26* · Jan 26, 2026
A27: 3 | B27: =IFERROR((IF(ISNUMBER(C27),C27,0)+IF(ISNUMBER(F27),F27,0)+IF(ISNUMBER(I27),I27,0)+IF(ISNUMBER(L27),L27,0)+IF(ISNUMBER(O27),O27,0))/(ISNUMBER(C27)*1+ISNUMBER(F27)*1+ISNUMBER(I27)*1+ISNUMBER(L27)*1+ISNUMBER(O27)*1),"") -> 2583.5 | C27: =IFERROR(IF(SUMPRODUCT(('S24'!$K$3:$K$600>=$B$2+14)*('S24'!$K$3:$K$600<$B$2+21)*('S24'!$H$3:$H$600))=0,"",SUMPRODUCT(('S24'!$K$3:$K$600>=$B$2+14)*('S24'!$K$3:$K$600<$B$2+21)*('S24'!$H$3:$H$600))),"") | D27: S24 · Feb 5, 2024 | F27: =IFERROR(IF(SUMPRODUCT(('F24'!$K$3:$K$600>=$C$2+14)*('F24'!$K$3:$K$600<$C$2+21)*('F24'!$H$3:$H$600))=0,"",SUMPRODUCT(('F24'!$K$3:$K$600>=$C$2+14)*('F24'!$K$3:$K$600<$C$2+21)*('F24'!$H$3:$H$600))),"") -> 1502 | G27: F24 · Sep 23, 2024 | I27: =IFERROR(IF(SUMPRODUCT(('S25'!$K$3:$K$600>=$D$2+14)*('S25'!$K$3:$K$600<$D$2+21)*('S25'!$H$3:$H$600))=0,"",SUMPRODUCT(('S25'!$K$3:$K$600>=$D$2+14)*('S25'!$K$3:$K$600<$D$2+21)*('S25'!$H$3:$H$600))),"") -> 2581 | J27: S25 · Feb 3, 2025 | L27: =IFERROR(IF(SUMPRODUCT(('F25'!$K$3:$K$600>=$E$2+14)*('F25'!$K$3:$K$600<$E$2+21)*('F25'!$H$3:$H$600))=0,"",SUMPRODUCT(('F25'!$K$3:$K$600>=$E$2+14)*('F25'!$K$3:$K$600<$E$2+21)*('F25'!$H$3:$H$600))),"") -> 2807 | M27: F25 · Sep 22, 2025 | O27: =IFERROR(IF(SUMPRODUCT(('S26'!$K$3:$K$600>=$F$2+14)*('S26'!$K$3:$K$600<$F$2+21)*('S26'!$H$3:$H$600))=0,"",SUMPRODUCT(('S26'!$K$3:$K$600>=$F$2+14)*('S26'!$K$3:$K$600<$F$2+21)*('S26'!$H$3:$H$600))),"") -> 3444 | P27: S26* · Feb 2, 2026
A28: 4 | B28: =IFERROR((IF(ISNUMBER(C28),C28,0)+IF(ISNUMBER(F28),F28,0)+IF(ISNUMBER(I28),I28,0)+IF(ISNUMBER(L28),L28,0)+IF(ISNUMBER(O28),O28,0))/(ISNUMBER(C28)*1+ISNUMBER(F28)*1+ISNUMBER(I28)*1+ISNUMBER(L28)*1+ISNUMBER(O28)*1),"") -> 2654 | C28: =IFERROR(IF(SUMPRODUCT(('S24'!$K$3:$K$600>=$B$2+21)*('S24'!$K$3:$K$600<$B$2+28)*('S24'!$H$3:$H$600))=0,"",SUMPRODUCT(('S24'!$K$3:$K$600>=$B$2+21)*('S24'!$K$3:$K$600<$B$2+28)*('S24'!$H$3:$H$600))),"") | D28: S24 · Feb 12, 2024 | F28: =IFERROR(IF(SUMPRODUCT(('F24'!$K$3:$K$600>=$C$2+21)*('F24'!$K$3:$K$600<$C$2+28)*('F24'!$H$3:$H$600))=0,"",SUMPRODUCT(('F24'!$K$3:$K$600>=$C$2+21)*('F24'!$K$3:$K$600<$C$2+28)*('F24'!$H$3:$H$600))),"") -> 2521 | G28: F24 · Sep 30, 2024 | I28: =IFERROR(IF(SUMPRODUCT(('S25'!$K$3:$K$600>=$D$2+21)*('S25'!$K$3:$K$600<$D$2+28)*('S25'!$H$3:$H$600))=0,"",SUMPRODUCT(('S25'!$K$3:$K$600>=$D$2+21)*('S25'!$K$3:$K$600<$D$2+28)*('S25'!$H$3:$H$600))),"") -> 2857 | J28: S25 · Feb 10, 2025 | L28: =IFERROR(IF(SUMPRODUCT(('F25'!$K$3:$K$600>=$E$2+21)*('F25'!$K$3:$K$600<$E$2+28)*('F25'!$H$3:$H$600))=0,"",SUMPRODUCT(('F25'!$K$3:$K$600>=$E$2+21)*('F25'!$K$3:$K$600<$E$2+28)*('F25'!$H$3:$H$600))),"") -> 2637 | M28: F25 · Sep 29, 2025 | O28: =IFERROR(IF(SUMPRODUCT(('S26'!$K$3:$K$600>=$F$2+21)*('S26'!$K$3:$K$600<$F$2+28)*('S26'!$H$3:$H$600))=0,"",SUMPRODUCT(('S26'!$K$3:$K$600>=$F$2+21)*('S26'!$K$3:$K$600<$F$2+28)*('S26'!$H$3:$H$600))),"") -> 2601 | P28: S26* · Feb 9, 2026
A29: 5 | B29: =IFERROR((IF(ISNUMBER(C29),C29,0)+IF(ISNUMBER(F29),F29,0)+IF(ISNUMBER(I29),I29,0)+IF(ISNUMBER(L29),L29,0)+IF(ISNUMBER(O29),O29,0))/(ISNUMBER(C29)*1+ISNUMBER(F29)*1+ISNUMBER(I29)*1+ISNUMBER(L29)*1+ISNUMBER(O29)*1),"") -> 2372 | C29: =IFERROR(IF(SUMPRODUCT(('S24'!$K$3:$K$600>=$B$2+28)*('S24'!$K$3:$K$600<$B$2+35)*('S24'!$H$3:$H$600))=0,"",SUMPRODUCT(('S24'!$K$3:$K$600>=$B$2+28)*('S24'!$K$3:$K$600<$B$2+35)*('S24'!$H$3:$H$600))),"") | D29: S24 · Feb 19, 2024 | F29: =IFERROR(IF(SUMPRODUCT(('F24'!$K$3:$K$600>=$C$2+28)*('F24'!$K$3:$K$600<$C$2+35)*('F24'!$H$3:$H$600))=0,"",SUMPRODUCT(('F24'!$K$3:$K$600>=$C$2+28)*('F24'!$K$3:$K$600<$C$2+35)*('F24'!$H$3:$H$600))),"") -> 2246 | G29: F24 · Oct 7, 2024 | I29: =IFERROR(IF(SUMPRODUCT(('S25'!$K$3:$K$600>=$D$2+28)*('S25'!$K$3:$K$600<$D$2+35)*('S25'!$H$3:$H$600))=0,"",SUMPRODUCT(('S25'!$K$3:$K$600>=$D$2+28)*('S25'!$K$3:$K$600<$D$2+35)*('S25'!$H$3:$H$600))),"") -> 2372 | J29: S25 · Feb 17, 2025 | L29: =IFERROR(IF(SUMPRODUCT(('F25'!$K$3:$K$600>=$E$2+28)*('F25'!$K$3:$K$600<$E$2+35)*('F25'!$H$3:$H$600))=0,"",SUMPRODUCT(('F25'!$K$3:$K$600>=$E$2+28)*('F25'!$K$3:$K$600<$E$2+35)*('F25'!$H$3:$H$600))),"") -> 2198 | M29: F25 · Oct 6, 2025 | O29: =IFERROR(IF(SUMPRODUCT(('S26'!$K$3:$K$600>=$F$2+28)*('S26'!$K$3:$K$600<$F$2+35)*('S26'!$H$3:$H$600))=0,"",SUMPRODUCT(('S26'!$K$3:$K$600>=$F$2+28)*('S26'!$K$3:$K$600<$F$2+35)*('S26'!$H$3:$H$600))),"") -> 2672 | P29: S26* · Feb 16, 2026
A30: 6 | B30: =IFERROR((IF(ISNUMBER(C30),C30,0)+IF(ISNUMBER(F30),F30,0)+IF(ISNUMBER(I30),I30,0)+IF(ISNUMBER(L30),L30,0)+IF(ISNUMBER(O30),O30,0))/(ISNUMBER(C30)*1+ISNUMBER(F30)*1+ISNUMBER(I30)*1+ISNUMBER(L30)*1+ISNUMBER(O30)*1),"") -> 1751 | C30: =IFERROR(IF(SUMPRODUCT(('S24'!$K$3:$K$600>=$B$2+35)*('S24'!$K$3:$K$600<$B$2+42)*('S24'!$H$3:$H$600))=0,"",SUMPRODUCT(('S24'!$K$3:$K$600>=$B$2+35)*('S24'!$K$3:$K$600<$B$2+42)*('S24'!$H$3:$H$600))),"") | D30: S24 · Feb 26, 2024 | F30: =IFERROR(IF(SUMPRODUCT(('F24'!$K$3:$K$600>=$C$2+35)*('F24'!$K$3:$K$600<$C$2+42)*('F24'!$H$3:$H$600))=0,"",SUMPRODUCT(('F24'!$K$3:$K$600>=$C$2+35)*('F24'!$K$3:$K$600<$C$2+42)*('F24'!$H$3:$H$600))),"") -> 1921 | G30: F24 · Oct 14, 2024 | H30: Columbus Day | I30: =IFERROR(IF(SUMPRODUCT(('S25'!$K$3:$K$600>=$D$2+35)*('S25'!$K$3:$K$600<$D$2+42)*('S25'!$H$3:$H$600))=0,"",SUMPRODUCT(('S25'!$K$3:$K$600>=$D$2+35)*('S25'!$K$3:$K$600<$D$2+42)*('S25'!$H$3:$H$600))),"") -> 2607 | J30: S25 · Feb 24, 2025 | L30: =IFERROR(IF(SUMPRODUCT(('F25'!$K$3:$K$600>=$E$2+35)*('F25'!$K$3:$K$600<$E$2+42)*('F25'!$H$3:$H$600))=0,"",SUMPRODUCT(('F25'!$K$3:$K$600>=$E$2+35)*('F25'!$K$3:$K$600<$E$2+42)*('F25'!$H$3:$H$600))),"") -> 1860 | M30: F25 · Oct 13, 2025 | N30: Columbus Day | O30: =IFERROR(IF(SUMPRODUCT(('S26'!$K$3:$K$600>=$F$2+35)*('S26'!$K$3:$K$600<$F$2+42)*('S26'!$H$3:$H$600))=0,"",SUMPRODUCT(('S26'!$K$3:$K$600>=$F$2+35)*('S26'!$K$3:$K$600<$F$2+42)*('S26'!$H$3:$H$600))),"") -> 616 | P30: S26* · Feb 23, 2026 | Q30: 3 snow days
A31: 7 | B31: =IFERROR((IF(ISNUMBER(C31),C31,0)+IF(ISNUMBER(F31),F31,0)+IF(ISNUMBER(I31),I31,0)+IF(ISNUMBER(L31),L31,0)+IF(ISNUMBER(O31),O31,0))/(ISNUMBER(C31)*1+ISNUMBER(F31)*1+ISNUMBER(I31)*1+ISNUMBER(L31)*1+ISNUMBER(O31)*1),"") -> 2558.75 | C31: =IFERROR(IF(SUMPRODUCT(('S24'!$K$3:$K$600>=$B$2+42)*('S24'!$K$3:$K$600<$B$2+49)*('S24'!$H$3:$H$600))=0,"",SUMPRODUCT(('S24'!$K$3:$K$600>=$B$2+42)*('S24'!$K$3:$K$600<$B$2+49)*('S24'!$H$3:$H$600))),"") | D31: S24 · Mar 4, 2024 | F31: =IFERROR(IF(SUMPRODUCT(('F24'!$K$3:$K$600>=$C$2+42)*('F24'!$K$3:$K$600<$C$2+49)*('F24'!$H$3:$H$600))=0,"",SUMPRODUCT(('F24'!$K$3:$K$600>=$C$2+42)*('F24'!$K$3:$K$600<$C$2+49)*('F24'!$H$3:$H$600))),"") -> 2697 | G31: F24 · Oct 21, 2024 | I31: =IFERROR(IF(SUMPRODUCT(('S25'!$K$3:$K$600>=$D$2+42)*('S25'!$K$3:$K$600<$D$2+49)*('S25'!$H$3:$H$600))=0,"",SUMPRODUCT(('S25'!$K$3:$K$600>=$D$2+42)*('S25'!$K$3:$K$600<$D$2+49)*('S25'!$H$3:$H$600))),"") -> 2059 | J31: S25 · Mar 3, 2025 | L31: =IFERROR(IF(SUMPRODUCT(('F25'!$K$3:$K$600>=$E$2+42)*('F25'!$K$3:$K$600<$E$2+49)*('F25'!$H$3:$H$600))=0,"",SUMPRODUCT(('F25'!$K$3:$K$600>=$E$2+42)*('F25'!$K$3:$K$600<$E$2+49)*('F25'!$H$3:$H$600))),"") -> 2852 | M31: F25 · Oct 20, 2025 | O31: =IFERROR(IF(SUMPRODUCT(('S26'!$K$3:$K$600>=$F$2+42)*('S26'!$K$3:$K$600<$F$2+49)*('S26'!$H$3:$H$600))=0,"",SUMPRODUCT(('S26'!$K$3:$K$600>=$F$2+42)*('S26'!$K$3:$K$600<$F$2+49)*('S26'!$H$3:$H$600))),"") -> 2627 | P31: S26* · Mar 2, 2026
A32: 8 | B32: =IFERROR((IF(ISNUMBER(C32),C32,0)+IF(ISNUMBER(F32),F32,0)+IF(ISNUMBER(I32),I32,0)+IF(ISNUMBER(L32),L32,0)+IF(ISNUMBER(O32),O32,0))/(ISNUMBER(C32)*1+ISNUMBER(F32)*1+ISNUMBER(I32)*1+ISNUMBER(L32)*1+ISNUMBER(O32)*1),"") -> 2717 | C32: =IFERROR(IF(SUMPRODUCT(('S24'!$K$3:$K$600>=$B$2+49)*('S24'!$K$3:$K$600<$B$2+56)*('S24'!$H$3:$H$600))=0,"",SUMPRODUCT(('S24'!$K$3:$K$600>=$B$2+49)*('S24'!$K$3:$K$600<$B$2+56)*('S24'!$H$3:$H$600))),"") | D32: S24 · Mar 11, 2024 | F32: =IFERROR(IF(SUMPRODUCT(('F24'!$K$3:$K$600>=$C$2+49)*('F24'!$K$3:$K$600<$C$2+56)*('F24'!$H$3:$H$600))=0,"",SUMPRODUCT(('F24'!$K$3:$K$600>=$C$2+49)*('F24'!$K$3:$K$600<$C$2+56)*('F24'!$H$3:$H$600))),"") -> 2343 | G32: F24 · Oct 28, 2024 | I32: =IFERROR(IF(SUMPRODUCT(('S25'!$K$3:$K$600>=$D$2+49)*('S25'!$K$3:$K$600<$D$2+56)*('S25'!$H$3:$H$600))=0,"",SUMPRODUCT(('S25'!$K$3:$K$600>=$D$2+49)*('S25'!$K$3:$K$600<$D$2+56)*('S25'!$H$3:$H$600))),"") | J32: S25 · Mar 10, 2025 | K32: spring break | L32: =IFERROR(IF(SUMPRODUCT(('F25'!$K$3:$K$600>=$E$2+49)*('F25'!$K$3:$K$600<$E$2+56)*('F25'!$H$3:$H$600))=0,"",SUMPRODUCT(('F25'!$K$3:$K$600>=$E$2+49)*('F25'!$K$3:$K$600<$E$2+56)*('F25'!$H$3:$H$600))),"") -> 3078 | M32: F25 · Oct 27, 2025 | O32: =IFERROR(IF(SUMPRODUCT(('S26'!$K$3:$K$600>=$F$2+49)*('S26'!$K$3:$K$600<$F$2+56)*('S26'!$H$3:$H$600))=0,"",SUMPRODUCT(('S26'!$K$3:$K$600>=$F$2+49)*('S26'!$K$3:$K$600<$F$2+56)*('S26'!$H$3:$H$600))),"") -> 2730 | P32: S26* · Mar 9, 2026
A33: 9 | B33: =IFERROR((IF(ISNUMBER(C33),C33,0)+IF(ISNUMBER(F33),F33,0)+IF(ISNUMBER(I33),I33,0)+IF(ISNUMBER(L33),L33,0)+IF(ISNUMBER(O33),O33,0))/(ISNUMBER(C33)*1+ISNUMBER(F33)*1+ISNUMBER(I33)*1+ISNUMBER(L33)*1+ISNUMBER(O33)*1),"") -> 2023.115 | C33: =IFERROR(IF(SUMPRODUCT(('S24'!$K$3:$K$600>=$B$2+56)*('S24'!$K$3:$K$600<$B$2+63)*('S24'!$H$3:$H$600))=0,"",SUMPRODUCT(('S24'!$K$3:$K$600>=$B$2+56)*('S24'!$K$3:$K$600<$B$2+63)*('S24'!$H$3:$H$600))),"") -> 744.46 | D33: S24 · Mar 18, 2024 | F33: =IFERROR(IF(SUMPRODUCT(('F24'!$K$3:$K$600>=$C$2+56)*('F24'!$K$3:$K$600<$C$2+63)*('F24'!$H$3:$H$600))=0,"",SUMPRODUCT(('F24'!$K$3:$K$600>=$C$2+56)*('F24'!$K$3:$K$600<$C$2+63)*('F24'!$H$3:$H$600))),"") -> 2007 | G33: F24 · Oct 29, 2024 | I33: =IFERROR(IF(SUMPRODUCT(('S25'!$K$3:$K$600>=$D$2+56)*('S25'!$K$3:$K$600<$D$2+63)*('S25'!$H$3:$H$600))=0,"",SUMPRODUCT(('S25'!$K$3:$K$600>=$D$2+56)*('S25'!$K$3:$K$600<$D$2+63)*('S25'!$H$3:$H$600))),"") -> 2401 | J33: S25 · Mar 17, 2025 | L33: =IFERROR(IF(SUMPRODUCT(('F25'!$K$3:$K$600>=$E$2+56)*('F25'!$K$3:$K$600<$E$2+63)*('F25'!$H$3:$H$600))=0,"",SUMPRODUCT(('F25'!$K$3:$K$600>=$E$2+56)*('F25'!$K$3:$K$600<$E$2+63)*('F25'!$H$3:$H$600))),"") -> 2940 | M33: F25 · Oct 28, 2025 | O33: =IFERROR(IF(SUMPRODUCT(('S26'!$K$3:$K$600>=$F$2+56)*('S26'!$K$3:$K$600<$F$2+63)*('S26'!$H$3:$H$600))=0,"",SUMPRODUCT(('S26'!$K$3:$K$600>=$F$2+56)*('S26'!$K$3:$K$600<$F$2+63)*('S26'!$H$3:$H$600))),"") | P33: S26* · Mar 16, 2026 | Q33: spring break
A34: 10 | B34: =IFERROR((IF(ISNUMBER(C34),C34,0)+IF(ISNUMBER(F34),F34,0)+IF(ISNUMBER(I34),I34,0)+IF(ISNUMBER(L34),L34,0)+IF(ISNUMBER(O34),O34,0))/(ISNUMBER(C34)*1+ISNUMBER(F34)*1+ISNUMBER(I34)*1+ISNUMBER(L34)*1+ISNUMBER(O34)*1),"") -> 2111.02 | C34: =IFERROR(IF(SUMPRODUCT(('S24'!$K$3:$K$600>=$B$2+63)*('S24'!$K$3:$K$600<$B$2+70)*('S24'!$H$3:$H$600))=0,"",SUMPRODUCT(('S24'!$K$3:$K$600>=$B$2+63)*('S24'!$K$3:$K$600<$B$2+70)*('S24'!$H$3:$H$600))),"") -> 1473.1 | D34: S24 · Mar 25, 2024 | F34: =IFERROR(IF(SUMPRODUCT(('F24'!$K$3:$K$600>=$C$2+63)*('F24'!$K$3:$K$600<$C$2+70)*('F24'!$H$3:$H$600))=0,"",SUMPRODUCT(('F24'!$K$3:$K$600>=$C$2+63)*('F24'!$K$3:$K$600<$C$2+70)*('F24'!$H$3:$H$600))),"") -> 1977 | G34: F24 · Nov 4, 2024 | I34: =IFERROR(IF(SUMPRODUCT(('S25'!$K$3:$K$600>=$D$2+63)*('S25'!$K$3:$K$600<$D$2+70)*('S25'!$H$3:$H$600))=0,"",SUMPRODUCT(('S25'!$K$3:$K$600>=$D$2+63)*('S25'!$K$3:$K$600<$D$2+70)*('S25'!$H$3:$H$600))),"") -> 2181 | J34: S25 · Mar 24, 2025 | L34: =IFERROR(IF(SUMPRODUCT(('F25'!$K$3:$K$600>=$E$2+63)*('F25'!$K$3:$K$600<$E$2+70)*('F25'!$H$3:$H$600))=0,"",SUMPRODUCT(('F25'!$K$3:$K$600>=$E$2+63)*('F25'!$K$3:$K$600<$E$2+70)*('F25'!$H$3:$H$600))),"") -> 2468 | M34: F25 · Nov 3, 2025 | O34: =IFERROR(IF(SUMPRODUCT(('S26'!$K$3:$K$600>=$F$2+63)*('S26'!$K$3:$K$600<$F$2+70)*('S26'!$H$3:$H$600))=0,"",SUMPRODUCT(('S26'!$K$3:$K$600>=$F$2+63)*('S26'!$K$3:$K$600<$F$2+70)*('S26'!$H$3:$H$600))),"") -> 2456 | P34: S26* · Mar 23, 2026
A35: 11 | B35: =IFERROR((IF(ISNUMBER(C35),C35,0)+IF(ISNUMBER(F35),F35,0)+IF(ISNUMBER(I35),I35,0)+IF(ISNUMBER(L35),L35,0)+IF(ISNUMBER(O35),O35,0))/(ISNUMBER(C35)*1+ISNUMBER(F35)*1+ISNUMBER(I35)*1+ISNUMBER(L35)*1+ISNUMBER(O35)*1),"") -> 2227.6 | C35: =IFERROR(IF(SUMPRODUCT(('S24'!$K$3:$K$600>=$B$2+70)*('S24'!$K$3:$K$600<$B$2+77)*('S24'!$H$3:$H$600))=0,"",SUMPRODUCT(('S24'!$K$3:$K$600>=$B$2+70)*('S24'!$K$3:$K$600<$B$2+77)*('S24'!$H$3:$H$600))),"") -> 877 | D35: S24 · Apr 1, 2024 | F35: =IFERROR(IF(SUMPRODUCT(('F24'!$K$3:$K$600>=$C$2+70)*('F24'!$K$3:$K$600<$C$2+77)*('F24'!$H$3:$H$600))=0,"",SUMPRODUCT(('F24'!$K$3:$K$600>=$C$2+70)*('F24'!$K$3:$K$600<$C$2+77)*('F24'!$H$3:$H$600))),"") -> 2065 | G35: F24 · Nov 11, 2024 | I35: =IFERROR(IF(SUMPRODUCT(('S25'!$K$3:$K$600>=$D$2+70)*('S25'!$K$3:$K$600<$D$2+77)*('S25'!$H$3:$H$600))=0,"",SUMPRODUCT(('S25'!$K$3:$K$600>=$D$2+70)*('S25'!$K$3:$K$600<$D$2+77)*('S25'!$H$3:$H$600))),"") -> 2134 | J35: S25 · Mar 31, 2025 | L35: =IFERROR(IF(SUMPRODUCT(('F25'!$K$3:$K$600>=$E$2+70)*('F25'!$K$3:$K$600<$E$2+77)*('F25'!$H$3:$H$600))=0,"",SUMPRODUCT(('F25'!$K$3:$K$600>=$E$2+70)*('F25'!$K$3:$K$600<$E$2+77)*('F25'!$H$3:$H$600))),"") -> 3196 | M35: F25 · Nov 10, 2025 | O35: =IFERROR(IF(SUMPRODUCT(('S26'!$K$3:$K$600>=$F$2+70)*('S26'!$K$3:$K$600<$F$2+77)*('S26'!$H$3:$H$600))=0,"",SUMPRODUCT(('S26'!$K$3:$K$600>=$F$2+70)*('S26'!$K$3:$K$600<$F$2+77)*('S26'!$H$3:$H$600))),"") -> 2866 | P35: S26* · Mar 30, 2026
A36: 12 | B36: =IFERROR((IF(ISNUMBER(C36),C36,0)+IF(ISNUMBER(F36),F36,0)+IF(ISNUMBER(I36),I36,0)+IF(ISNUMBER(L36),L36,0)+IF(ISNUMBER(O36),O36,0))/(ISNUMBER(C36)*1+ISNUMBER(F36)*1+ISNUMBER(I36)*1+ISNUMBER(L36)*1+ISNUMBER(O36)*1),"") -> 1567.88 | C36: =IFERROR(IF(SUMPRODUCT(('S24'!$K$3:$K$600>=$B$2+77)*('S24'!$K$3:$K$600<$B$2+84)*('S24'!$H$3:$H$600))=0,"",SUMPRODUCT(('S24'!$K$3:$K$600>=$B$2+77)*('S24'!$K$3:$K$600<$B$2+84)*('S24'!$H$3:$H$600))),"") -> 1328.4 | D36: S24 · Apr 8, 2024 | F36: =IFERROR(IF(SUMPRODUCT(('F24'!$K$3:$K$600>=$C$2+77)*('F24'!$K$3:$K$600<$C$2+84)*('F24'!$H$3:$H$600))=0,"",SUMPRODUCT(('F24'!$K$3:$K$600>=$C$2+77)*('F24'!$K$3:$K$600<$C$2+84)*('F24'!$H$3:$H$600))),"") -> 322 | G36: F24 · Nov 18, 2024 | H36: Thanksgiving | I36: =IFERROR(IF(SUMPRODUCT(('S25'!$K$3:$K$600>=$D$2+77)*('S25'!$K$3:$K$600<$D$2+84)*('S25'!$H$3:$H$600))=0,"",SUMPRODUCT(('S25'!$K$3:$K$600>=$D$2+77)*('S25'!$K$3:$K$600<$D$2+84)*('S25'!$H$3:$H$600))),"") -> 2389 | J36: S25 · Apr 7, 2025 | L36: =IFERROR(IF(SUMPRODUCT(('F25'!$K$3:$K$600>=$E$2+77)*('F25'!$K$3:$K$600<$E$2+84)*('F25'!$H$3:$H$600))=0,"",SUMPRODUCT(('F25'!$K$3:$K$600>=$E$2+77)*('F25'!$K$3:$K$600<$E$2+84)*('F25'!$H$3:$H$600))),"") -> 674 | M36: F25 · Nov 17, 2025 | N36: Thanksgiving | O36: =IFERROR(IF(SUMPRODUCT(('S26'!$K$3:$K$600>=$F$2+77)*('S26'!$K$3:$K$600<$F$2+84)*('S26'!$H$3:$H$600))=0,"",SUMPRODUCT(('S26'!$K$3:$K$600>=$F$2+77)*('S26'!$K$3:$K$600<$F$2+84)*('S26'!$H$3:$H$600))),"") -> 3126 | P36: S26* · Apr 6, 2026
A37: 13 | B37: =IFERROR((IF(ISNUMBER(C37),C37,0)+IF(ISNUMBER(F37),F37,0)+IF(ISNUMBER(I37),I37,0)+IF(ISNUMBER(L37),L37,0)+IF(ISNUMBER(O37),O37,0))/(ISNUMBER(C37)*1+ISNUMBER(F37)*1+ISNUMBER(I37)*1+ISNUMBER(L37)*1+ISNUMBER(O37)*1),"") -> 2323.58 | C37: =IFERROR(IF(SUMPRODUCT(('S24'!$K$3:$K$600>=$B$2+84)*('S24'!$K$3:$K$600<$B$2+91)*('S24'!$H$3:$H$600))=0,"",SUMPRODUCT(('S24'!$K$3:$K$600>=$B$2+84)*('S24'!$K$3:$K$600<$B$2+91)*('S24'!$H$3:$H$600))),"") -> 1418.9 | D37: S24 · Apr 15, 2024 | F37: =IFERROR(IF(SUMPRODUCT(('F24'!$K$3:$K$600>=$C$2+84)*('F24'!$K$3:$K$600<$C$2+91)*('F24'!$H$3:$H$600))=0,"",SUMPRODUCT(('F24'!$K$3:$K$600>=$C$2+84)*('F24'!$K$3:$K$600<$C$2+91)*('F24'!$H$3:$H$600))),"") -> 2408 | G37: F24 · Nov 25, 2024 | I37: =IFERROR(IF(SUMPRODUCT(('S25'!$K$3:$K$600>=$D$2+84)*('S25'!$K$3:$K$600<$D$2+91)*('S25'!$H$3:$H$600))=0,"",SUMPRODUCT(('S25'!$K$3:$K$600>=$D$2+84)*('S25'!$K$3:$K$600<$D$2+91)*('S25'!$H$3:$H$600))),"") -> 2647 | J37: S25 · Apr 14, 2025 | L37: =IFERROR(IF(SUMPRODUCT(('F25'!$K$3:$K$600>=$E$2+84)*('F25'!$K$3:$K$600<$E$2+91)*('F25'!$H$3:$H$600))=0,"",SUMPRODUCT(('F25'!$K$3:$K$600>=$E$2+84)*('F25'!$K$3:$K$600<$E$2+91)*('F25'!$H$3:$H$600))),"") -> 2701 | M37: F25 · Nov 24, 2025 | O37: =IFERROR(IF(SUMPRODUCT(('S26'!$K$3:$K$600>=$F$2+84)*('S26'!$K$3:$K$600<$F$2+91)*('S26'!$H$3:$H$600))=0,"",SUMPRODUCT(('S26'!$K$3:$K$600>=$F$2+84)*('S26'!$K$3:$K$600<$F$2+91)*('S26'!$H$3:$H$600))),"") -> 2443 | P37: S26* · Apr 13, 2026
A38: 14 | B38: =IFERROR((IF(ISNUMBER(C38),C38,0)+IF(ISNUMBER(F38),F38,0)+IF(ISNUMBER(I38),I38,0)+IF(ISNUMBER(L38),L38,0)+IF(ISNUMBER(O38),O38,0))/(ISNUMBER(C38)*1+ISNUMBER(F38)*1+ISNUMBER(I38)*1+ISNUMBER(L38)*1+ISNUMBER(O38)*1),"") -> 1599.4 | C38: =IFERROR(IF(SUMPRODUCT(('S24'!$K$3:$K$600>=$B$2+91)*('S24'!$K$3:$K$600<$B$2+98)*('S24'!$H$3:$H$600))=0,"",SUMPRODUCT(('S24'!$K$3:$K$600>=$B$2+91)*('S24'!$K$3:$K$600<$B$2+98)*('S24'!$H$3:$H$600))),"") -> 1116 | D38: S24 · Apr 22, 2024 | F38: =IFERROR(IF(SUMPRODUCT(('F24'!$K$3:$K$600>=$C$2+91)*('F24'!$K$3:$K$600<$C$2+98)*('F24'!$H$3:$H$600))=0,"",SUMPRODUCT(('F24'!$K$3:$K$600>=$C$2+91)*('F24'!$K$3:$K$600<$C$2+98)*('F24'!$H$3:$H$600))),"") -> 1577 | G38: F24 · Dec 2, 2024 | I38: =IFERROR(IF(SUMPRODUCT(('S25'!$K$3:$K$600>=$D$2+91)*('S25'!$K$3:$K$600<$D$2+98)*('S25'!$H$3:$H$600))=0,"",SUMPRODUCT(('S25'!$K$3:$K$600>=$D$2+91)*('S25'!$K$3:$K$600<$D$2+98)*('S25'!$H$3:$H$600))),"") -> 2700 | J38: S25 · Apr 21, 2025 | L38: =IFERROR(IF(SUMPRODUCT(('F25'!$K$3:$K$600>=$E$2+91)*('F25'!$K$3:$K$600<$E$2+98)*('F25'!$H$3:$H$600))=0,"",SUMPRODUCT(('F25'!$K$3:$K$600>=$E$2+91)*('F25'!$K$3:$K$600<$E$2+98)*('F25'!$H$3:$H$600))),"") -> 1469 | M38: F25 · Dec 1, 2025 | O38: =IFERROR(IF(SUMPRODUCT(('S26'!$K$3:$K$600>=$F$2+91)*('S26'!$K$3:$K$600<$F$2+98)*('S26'!$H$3:$H$600))=0,"",SUMPRODUCT(('S26'!$K$3:$K$600>=$F$2+91)*('S26'!$K$3:$K$600<$F$2+98)*('S26'!$H$3:$H$600))),"") -> 1135 | P38: S26* · Apr 20, 2026
A39: † Tooltip date cols (italic headers) show the actual calendar date per semester per week. In chart editor: select each "[sem] date" column → Column role → Tooltip.
A41: T11 · Program Progress → color-coded scatter by semester
B42: lifetime lbs ──▶ | G42: lbs this week ──▶
A43: Week | B43: S24 | C43: F24 | D43: S25 | E43: F25 | F43: S26* | G43: S24 | H43: F24 | I43: S25 | J43: F25 | K43: S26*
A44: 45313 | B44: =IFERROR(IF(SUMPRODUCT(('S24'!$K$3:$K$600>=$B$2+0)*('S24'!$K$3:$K$600<$B$2+7)*('S24'!$H$3:$H$600))=0,"",SUMPRODUCT(('S24'!$K$3:$K$600>=$B$2+0)*('S24'!$K$3:$K$600<$B$2+7)*('S24'!$H$3:$H$600))),"") | G44: =IFERROR(IF(SUMPRODUCT(('S24'!$K$3:$K$600>=$B$2+0)*('S24'!$K$3:$K$600<$B$2+7)*('S24'!$H$3:$H$600))=0,"",SUMPRODUCT(('S24'!$K$3:$K$600>=$B$2+0)*('S24'!$K$3:$K$600<$B$2+7)*('S24'!$H$3:$H$600))),"")
...

Sheet S24
A1: Timestamp | B1: Name | C1: double name | D1: start hour | E1: hours worked | F1: end hour | G1: hours pp | H1: Derived Weight | I1: lb/hr per shift | J1: period | K1: Date | L1: Weekday | M1: lbs td
A2: 45313 | B2: N/A | C2: FALSE | H2: 0 | K2: 45313 | L2: Monday | M2: =IFERROR(__xludf.DUMMYFUNCTION("BYROW('S24'!K2:K782, LAMBDA(r, IF(r="""","""", LET( nextVal, IFERROR(INDEX('S24'!K2:K782, ROW(r)-ROW('S24'!K2)+2), """"), IF(r <> nextVal, IFERROR( SUM(FILTER('S24'!H2:H782, 'S24'!K2:K782 = r)), """" "&" ), """" ) ) ) )) "),0.0) -> 0
A3: 45369.491 | B3: Westin Palumbo | C3: FALSE | H3: 32.3 | J3: Lunch | K3: 45369 | L3: Monday | M3: =IFERROR(__xludf.DUMMYFUNCTION("""COMPUTED_VALUE"""),32.3) -> 32.3
A4: 45370.604 | B4: Kayleigh O’Mealia | C4: FALSE | H4: 32.47 | J4: Lunch | K4: 45370 | L4: Tuesday | M4: =IFERROR(__xludf.DUMMYFUNCTION("""COMPUTED_VALUE"""),"")
A5: 45370.875 | B5: Bitanya | C5: FALSE | H5: 101 | J5: Dinner | K5: 45370 | L5: Tuesday | M5: =IFERROR(__xludf.DUMMYFUNCTION("""COMPUTED_VALUE"""),"")
A6: 45370.876 | B6: Bitanya Hailu | C6: FALSE | H6: 163 | J6: Dinner | K6: 45370 | L6: Tuesday | M6: =IFERROR(__xludf.DUMMYFUNCTION("""COMPUTED_VALUE"""),296.47) -> 296.47
A7: 45371.395 | B7: Kayleigh O’Mealia | C7: FALSE | H7: 21.8 | J7: Breakfast | K7: 45371 | L7: Wednesday | M7: =IFERROR(__xludf.DUMMYFUNCTION("""COMPUTED_VALUE"""),"")
A8: 45371.47 | B8: Westin Palumbo | C8: FALSE | H8: 45.8 | J8: Lunch | K8: 45371 | L8: Wednesday | M8: =IFERROR(__xludf.DUMMYFUNCTION("""COMPUTED_VALUE"""),"")
A9: 45371.487 | B9: Westin Palumbo | C9: FALSE | H9: 7.61 | J9: Lunch | K9: 45371 | L9: Wednesday | M9: =IFERROR(__xludf.DUMMYFUNCTION("""COMPUTED_VALUE"""),"")
A10: 45371.656 | B10: Bitanya Hailu | C10: FALSE | H10: 113 | J10: Lunch | K10: 45371 | L10: Wednesday | M10: =IFERROR(__xludf.DUMMYFUNCTION("""COMPUTED_VALUE"""),"")
A11: 45371.656 | B11: Bitanya Hailu | C11: FALSE | H11: 88 | J11: Lunch | K11: 45371 | L11: Wednesday | M11: =IFERROR(__xludf.DUMMYFUNCTION("""COMPUTED_VALUE"""),276.21) -> 276.21
A12: 45372.669 | B12: Skyler Bobinski | C12: FALSE | H12: 93.1 | J12: Dinner | K12: 45372 | L12: Thursday | M12: =IFERROR(__xludf.DUMMYFUNCTION("""COMPUTED_VALUE"""),93.1) -> 93.1
A13: 45373.396 | B13: Kayleigh O’Mealia | C13: FALSE | H13: 46.38 | J13: Breakfast | K13: 45373 | L13: Friday | M13: =IFERROR(__xludf.DUMMYFUNCTION("""COMPUTED_VALUE"""),46.38) -> 46.38
A14: 45376.396 | B14: Kayleigh Omealia | C14: FALSE | H14: 50 | J14: Breakfast | K14: 45376 | L14: Monday | M14: =IFERROR(__xludf.DUMMYFUNCTION("""COMPUTED_VALUE"""),"")
A15: 45376.492 | B15: Westin Palumbo | C15: FALSE | H15: 40 | J15: Lunch | K15: 45376 | L15: Monday | M15: =IFERROR(__xludf.DUMMYFUNCTION("""COMPUTED_VALUE"""),"")
A16: 45376.586 | B16: Skyler Bobinski | C16: FALSE | H16: 134.3 | J16: Lunch | K16: 45376 | L16: Monday | M16: =IFERROR(__xludf.DUMMYFUNCTION("""COMPUTED_VALUE"""),"")
A17: 45376.651 | B17: Bitanya Hailu | C17: FALSE | H17: 131 | J17: Lunch | K17: 45376 | L17: Monday | M17: =IFERROR(__xludf.DUMMYFUNCTION("""COMPUTED_VALUE"""),"")
A18: 45376.651 | B18: Bitanya Hailu | C18: FALSE | H18: 75 | J18: Lunch | K18: 45376 | L18: Monday | M18: =IFERROR(__xludf.DUMMYFUNCTION("""COMPUTED_VALUE"""),"")
A19: 45376.747 | B19: Rushil Nepal | C19: FALSE | H19: 65 | J19: Dinner | K19: 45376 | L19: Monday | M19: =IFERROR(__xludf.DUMMYFUNCTION("""COMPUTED_VALUE"""),"")
A20: 45376.876 | B20: Rushil Nepal | C20: FALSE | H20: 167 | J20: Dinner | K20: 45376 | L20: Monday | M20: =IFERROR(__xludf.DUMMYFUNCTION("""COMPUTED_VALUE"""),662.3) -> 662.3
A21: 45377.491 | B21: Katie Field | C21: FALSE | H21: 104 | J21: Lunch | K21: 45377 | L21: Tuesday | M21: =IFERROR(__xludf.DUMMYFUNCTION("""COMPUTED_VALUE"""),"")
A22: 45377.604 | B22: Kayleigh O’Mealia | C22: FALSE | H22: 56 | J22: Lunch | K22: 45377 | L22: Tuesday | M22: =IFERROR(__xludf.DUMMYFUNCTION("""COMPUTED_VALUE"""),"")
A23: 45377.839 | B23: Bitanya Hailu | C23: FALSE | H23: 115 | J23: Dinner | K23: 45377 | L23: Tuesday | M23: =IFERROR(__xludf.DUMMYFUNCTION("""COMPUTED_VALUE"""),275.0) -> 275
A24: 45378.396 | B24: Kayleigh O’Mealia | C24: FALSE | H24: 24 | J24: Breakfast | K24: 45378 | L24: Wednesday | M24: =IFERROR(__xludf.DUMMYFUNCTION("""COMPUTED_VALUE"""),"")
A25: 45378.495 | B25: Westin Palumbo | C25: FALSE | H25: 59 | J25: Lunch | K25: 45378 | L25: Wednesday | M25: =IFERROR(__xludf.DUMMYFUNCTION("""COMPUTED_VALUE"""),"")
A26: 45378.94 | B26: Bitanya Hailu | C26: FALSE | H26: 204 | K26: 45378 | L26: Wednesday | M26: =IFERROR(__xludf.DUMMYFUNCTION("""COMPUTED_VALUE"""),287.0) -> 287
A27: 45379.494 | B27: Katie Field | C27: FALSE | H27: 107 | J27: Lunch | K27: 45379 | L27: Thursday | M27: =IFERROR(__xludf.DUMMYFUNCTION("""COMPUTED_VALUE"""),"")
A28: 45379.668 | B28: Skyler Bobinski | C28: FALSE | H28: 78.8 | J28: Dinner | K28: 45379 | L28: Thursday | M28: =IFERROR(__xludf.DUMMYFUNCTION("""COMPUTED_VALUE"""),"")
A29: 45379.733 | B29: Skyler Bobinski | C29: FALSE | H29: 25 | J29: Dinner | K29: 45379 | L29: Thursday | M29: =IFERROR(__xludf.DUMMYFUNCTION("""COMPUTED_VALUE"""),210.8) -> 210.8
A30: 45380.395 | B30: Kayleigh O’Mealia | C30: FALSE | H30: 38 | J30: Breakfast | K30: 45380 | L30: Friday | M30: =IFERROR(__xludf.DUMMYFUNCTION("""COMPUTED_VALUE"""),38.0) -> 38
A31: 45383.396 | B31: Kayleigh O’Mealia | C31: FALSE | H31: 49 | J31: Breakfast | K31: 45383 | L31: Monday | M31: =IFERROR(__xludf.DUMMYFUNCTION("""COMPUTED_VALUE"""),"")
A32: 45383.491 | B32: Westin Palumbo | C32: FALSE | H32: 62 | J32: Lunch | K32: 45383 | L32: Monday | M32: =IFERROR(__xludf.DUMMYFUNCTION("""COMPUTED_VALUE"""),111.0) -> 111
A33: 45384.312 | B33: Bitanya | C33: FALSE | H33: 123 | J33: Breakfast | K33: 45384 | L33: Tuesday | M33: =IFERROR(__xludf.DUMMYFUNCTION("""COMPUTED_VALUE"""),"")
A34: 45384.495 | B34: Katherine Field | C34: FALSE | H34: 123 | J34: Lunch | K34: 45384 | L34: Tuesday | M34: =IFERROR(__xludf.DUMMYFUNCTION("""COMPUTED_VALUE"""),"")
A35: 45384.6 | B35: Kayleigh O’Mealia | C35: FALSE | H35: 78 | J35: Lunch | K35: 45384 | L35: Tuesday | M35: =IFERROR(__xludf.DUMMYFUNCTION("""COMPUTED_VALUE"""),"")
A36: 45384.668 | B36: Skyler Bobinski | C36: FALSE | H36: 81.4 | J36: Dinner | K36: 45384 | L36: Tuesday | M36: =IFERROR(__xludf.DUMMYFUNCTION("""COMPUTED_VALUE"""),405.4) -> 405.4
A37: 45385.395 | B37: Kayleigh O’Mealia | C37: FALSE | H37: 27 | J37: Breakfast | K37: 45385 | L37: Wednesday | M37: =IFERROR(__xludf.DUMMYFUNCTION("""COMPUTED_VALUE"""),"")
A38: 45385.494 | B38: Westin Palumbo | C38: FALSE | H38: 68 | J38: Lunch | K38: 45385 | L38: Wednesday | M38: =IFERROR(__xludf.DUMMYFUNCTION("""COMPUTED_VALUE"""),95.0) -> 95
A39: 45386.495 | B39: Katherine Field | C39: FALSE | H39: 101 | J39: Lunch | K39: 45386 | L39: Thursday | M39: =IFERROR(__xludf.DUMMYFUNCTION("""COMPUTED_VALUE"""),"")
A40: 45386.725 | B40: Skyler Bobinski | C40: FALSE | H40: 119.6 | J40: Dinner | K40: 45386 | L40: Thursday | M40: =IFERROR(__xludf.DUMMYFUNCTION("""COMPUTED_VALUE"""),220.6) -> 220.6
...

Sheet F24
A1: Timestamp | B1: Name | C1: double name | D1: start hour | E1: hours worked | F1: end hour | G1: hours pp | H1: Derived Weight | I1: lb/hr per shift | J1: period | K1: Date | L1: Weekday | M1: dining hall | N1: MF lbs td | O1: BF lbs td | P1: lbs td
A2: 45544.866 | B2: Lizzie Welch | C2: FALSE | H2: 87 | J2: Dinner | K2: 45544 | L2: Monday | M2: MF | N2: =IFERROR(__xludf.DUMMYFUNCTION("BYROW('F24'!K2:K282, LAMBDA(r, IF(r="""","""", LET( nextVal, IFERROR(INDEX('F24'!K2:K282, ROW(r)-ROW('F24'!K2)+2), """"), IF(r <> nextVal, IFERROR( SUM(FILTER('F24'!H2:H282, 'F24'!K2:K282 = r, 'F24'!M2:M282 = ""MF""))"&", """" ), """" ) ) ) ))"),"") | O2: =IFERROR(__xludf.DUMMYFUNCTION("BYROW('F24'!K2:K282, LAMBDA(r, IF(r="""","""", LET( nextVal, IFERROR(INDEX('F24'!K2:K282, ROW(r)-ROW('F24'!K2)+2), """"), IF(r <> nextVal, IFERROR( SUM(FILTER('F24'!H2:H282, 'F24'!K2:K282 = r, 'F24'!M2:M282 = ""BF""))"&", """" ), """" ) ) ) ))"),"") | P2: =IFERROR(__xludf.DUMMYFUNCTION("BYROW('F24'!K2:K282, LAMBDA(r, IF(r="""","""", LET( nextVal, IFERROR(INDEX('F24'!K2:K282, ROW(r)-ROW('F24'!K2)+2), """"), IF(r <> nextVal, IFERROR( SUM(FILTER('F24'!H2:H282, 'F24'!K2:K282 = r)), """" "&" ), """" ) ) ) )) "),"")
A3: 45545.363 | B3: Kayleigh Omealia | C3: FALSE | H3: 43 | J3: Dinner | K3: 45544 | L3: Monday | M3: BF | N3: =IFERROR(__xludf.DUMMYFUNCTION("""COMPUTED_VALUE"""),87.0) -> 87 | O3: =IFERROR(__xludf.DUMMYFUNCTION("""COMPUTED_VALUE"""),43.0) -> 43 | P3: =IFERROR(__xludf.DUMMYFUNCTION("""COMPUTED_VALUE"""),130.0) -> 130
A4: 45545.62 | B4: Kayleigh Omealia | C4: FALSE | H4: 42 | J4: Lunch | K4: 45545 | L4: Tuesday | M4: BF | N4: =IFERROR(__xludf.DUMMYFUNCTION("""COMPUTED_VALUE"""),"") | O4: =IFERROR(__xludf.DUMMYFUNCTION("""COMPUTED_VALUE"""),"") | P4: =IFERROR(__xludf.DUMMYFUNCTION("""COMPUTED_VALUE"""),"")
A5: 45545.878 | B5: Kaya Pernini | C5: FALSE | H5: 61 | J5: Dinner | K5: 45545 | L5: Tuesday | M5: BF | N5: =IFERROR(__xludf.DUMMYFUNCTION("""COMPUTED_VALUE"""),"") | O5: =IFERROR(__xludf.DUMMYFUNCTION("""COMPUTED_VALUE"""),"") | P5: =IFERROR(__xludf.DUMMYFUNCTION("""COMPUTED_VALUE"""),"")
A6: 45545.887 | B6: Bitanya Hailu | C6: FALSE | H6: 145 | J6: Dinner | K6: 45545 | L6: Tuesday | M6: MF | N6: =IFERROR(__xludf.DUMMYFUNCTION("""COMPUTED_VALUE"""),145.0) -> 145 | O6: =IFERROR(__xludf.DUMMYFUNCTION("""COMPUTED_VALUE"""),103.0) -> 103 | P6: =IFERROR(__xludf.DUMMYFUNCTION("""COMPUTED_VALUE"""),248.0) -> 248
A7: 45546.433 | B7: Skyler Bobinski | C7: FALSE | H7: 39 | J7: Breakfast | K7: 45546 | L7: Wednesday | M7: BF | N7: =IFERROR(__xludf.DUMMYFUNCTION("""COMPUTED_VALUE"""),"") | O7: =IFERROR(__xludf.DUMMYFUNCTION("""COMPUTED_VALUE"""),"") | P7: =IFERROR(__xludf.DUMMYFUNCTION("""COMPUTED_VALUE"""),"")
A8: 45546.626 | B8: Kaya Pernini | C8: FALSE | H8: 38 | J8: Lunch | K8: 45546 | L8: Wednesday | M8: BF | N8: =IFERROR(__xludf.DUMMYFUNCTION("""COMPUTED_VALUE"""),"") | O8: =IFERROR(__xludf.DUMMYFUNCTION("""COMPUTED_VALUE"""),"") | P8: =IFERROR(__xludf.DUMMYFUNCTION("""COMPUTED_VALUE"""),"")
A9: 45546.649 | B9: Lizzie Welch | C9: FALSE | H9: 89 | J9: Lunch | K9: 45546 | L9: Wednesday | M9: MF | N9: =IFERROR(__xludf.DUMMYFUNCTION("""COMPUTED_VALUE"""),"") | O9: =IFERROR(__xludf.DUMMYFUNCTION("""COMPUTED_VALUE"""),"") | P9: =IFERROR(__xludf.DUMMYFUNCTION("""COMPUTED_VALUE"""),"")
A10: 45546.783 | B10: Cassidy Haskell | C10: FALSE | H10: 27 | J10: Dinner | K10: 45546 | L10: Wednesday | M10: BF | N10: =IFERROR(__xludf.DUMMYFUNCTION("""COMPUTED_VALUE"""),"") | O10: =IFERROR(__xludf.DUMMYFUNCTION("""COMPUTED_VALUE"""),"") | P10: =IFERROR(__xludf.DUMMYFUNCTION("""COMPUTED_VALUE"""),"")
A11: 45547.562 | B11: astou dieng | C11: FALSE | H11: 31 | J11: Dinner | K11: 45546 | L11: Wednesday | M11: BF | N11: =IFERROR(__xludf.DUMMYFUNCTION("""COMPUTED_VALUE"""),89.0) -> 89 | O11: =IFERROR(__xludf.DUMMYFUNCTION("""COMPUTED_VALUE"""),135.0) -> 135 | P11: =IFERROR(__xludf.DUMMYFUNCTION("""COMPUTED_VALUE"""),224.0) -> 224
A12: 45547.596 | B12: Lucas Meier | C12: FALSE | H12: 48 | J12: Lunch | K12: 45547 | L12: Thursday | M12: MF | N12: =IFERROR(__xludf.DUMMYFUNCTION("""COMPUTED_VALUE"""),"") | O12: =IFERROR(__xludf.DUMMYFUNCTION("""COMPUTED_VALUE"""),"") | P12: =IFERROR(__xludf.DUMMYFUNCTION("""COMPUTED_VALUE"""),"")
A13: 45547.626 | B13: Kaya Pernini | C13: FALSE | H13: 66 | J13: Lunch | K13: 45547 | L13: Thursday | M13: BF | N13: =IFERROR(__xludf.DUMMYFUNCTION("""COMPUTED_VALUE"""),"") | O13: =IFERROR(__xludf.DUMMYFUNCTION("""COMPUTED_VALUE"""),"") | P13: =IFERROR(__xludf.DUMMYFUNCTION("""COMPUTED_VALUE"""),"")
A14: 45547.822 | B14: Lizzie Welch | C14: FALSE | H14: 156 | J14: Dinner | K14: 45547 | L14: Thursday | M14: BF | N14: =IFERROR(__xludf.DUMMYFUNCTION("""COMPUTED_VALUE"""),"") | O14: =IFERROR(__xludf.DUMMYFUNCTION("""COMPUTED_VALUE"""),"") | P14: =IFERROR(__xludf.DUMMYFUNCTION("""COMPUTED_VALUE"""),"")
A15: 45547.875 | B15: Lizzie Welch | C15: FALSE | H15: 52 | J15: Dinner | K15: 45547 | L15: Thursday | M15: BF | N15: =IFERROR(__xludf.DUMMYFUNCTION("""COMPUTED_VALUE"""),48.0) -> 48 | O15: =IFERROR(__xludf.DUMMYFUNCTION("""COMPUTED_VALUE"""),274.0) -> 274 | P15: =IFERROR(__xludf.DUMMYFUNCTION("""COMPUTED_VALUE"""),322.0) -> 322
A16: 45548.391 | B16: Skyler Bobinski | C16: FALSE | H16: 31 | J16: Breakfast | K16: 45548 | L16: Friday | M16: BF | N16: =IFERROR(__xludf.DUMMYFUNCTION("""COMPUTED_VALUE"""),"") | O16: =IFERROR(__xludf.DUMMYFUNCTION("""COMPUTED_VALUE"""),"") | P16: =IFERROR(__xludf.DUMMYFUNCTION("""COMPUTED_VALUE"""),"")
A17: 45548.559 | B17: astou dieng | C17: FALSE | H17: 125 | J17: Breakfast/Lunch | K17: 45548 | L17: Friday | M17: BF | N17: =IFERROR(__xludf.DUMMYFUNCTION("""COMPUTED_VALUE"""),"") | O17: =IFERROR(__xludf.DUMMYFUNCTION("""COMPUTED_VALUE"""),"") | P17: =IFERROR(__xludf.DUMMYFUNCTION("""COMPUTED_VALUE"""),"")
A18: 45548.643 | B18: Westin Palumbo | C18: FALSE | H18: 86 | J18: Lunch | K18: 45548 | L18: Friday | M18: MF | N18: =IFERROR(__xludf.DUMMYFUNCTION("""COMPUTED_VALUE"""),86.0) -> 86 | O18: =IFERROR(__xludf.DUMMYFUNCTION("""COMPUTED_VALUE"""),156.0) -> 156 | P18: =IFERROR(__xludf.DUMMYFUNCTION("""COMPUTED_VALUE"""),242.0) -> 242
A19: 45551.611 | B19: Kaya Pernini | C19: FALSE | H19: 23 | J19: Lunch | K19: 45551 | L19: Monday | M19: BF | N19: =IFERROR(__xludf.DUMMYFUNCTION("""COMPUTED_VALUE"""),"") | O19: =IFERROR(__xludf.DUMMYFUNCTION("""COMPUTED_VALUE"""),"") | P19: =IFERROR(__xludf.DUMMYFUNCTION("""COMPUTED_VALUE"""),"")
A20: 45554.815 | B20: Lizzie Welch | C20: FALSE | H20: 106 | J20: Dinner | K20: 45551 | L20: Monday | M20: BF | N20: =IFERROR(__xludf.DUMMYFUNCTION("""COMPUTED_VALUE"""),"") | O20: =IFERROR(__xludf.DUMMYFUNCTION("""COMPUTED_VALUE"""),"") | P20: =IFERROR(__xludf.DUMMYFUNCTION("""COMPUTED_VALUE"""),"")
A21: 45551.645 | B21: Lizzie Welch | C21: FALSE | H21: 110 | J21: Lunch | K21: 45551 | L21: Monday | M21: MF | N21: =IFERROR(__xludf.DUMMYFUNCTION("""COMPUTED_VALUE"""),"") | O21: =IFERROR(__xludf.DUMMYFUNCTION("""COMPUTED_VALUE"""),"") | P21: =IFERROR(__xludf.DUMMYFUNCTION("""COMPUTED_VALUE"""),"")
A22: 45551.757 | B22: Westin Palumbo | C22: FALSE | H22: 6 | J22: Lunch | K22: 45551 | L22: Monday | M22: MF | N22: =IFERROR(__xludf.DUMMYFUNCTION("""COMPUTED_VALUE"""),"") | O22: =IFERROR(__xludf.DUMMYFUNCTION("""COMPUTED_VALUE"""),"") | P22: =IFERROR(__xludf.DUMMYFUNCTION("""COMPUTED_VALUE"""),"")
A23: 45552.014 | B23: astou dieng | C23: FALSE | H23: 41 | J23: Dinner | K23: 45551 | L23: Monday | M23: BF | N23: =IFERROR(__xludf.DUMMYFUNCTION("""COMPUTED_VALUE"""),"") | O23: =IFERROR(__xludf.DUMMYFUNCTION("""COMPUTED_VALUE"""),"") | P23: =IFERROR(__xludf.DUMMYFUNCTION("""COMPUTED_VALUE"""),"")
A24: 45552.348 | B24: Kayleigh O’Mealia | C24: FALSE | H24: 31 | J24: Dinner | K24: 45551 | L24: Monday | M24: BF | N24: =IFERROR(__xludf.DUMMYFUNCTION("""COMPUTED_VALUE"""),"") | O24: =IFERROR(__xludf.DUMMYFUNCTION("""COMPUTED_VALUE"""),"") | P24: =IFERROR(__xludf.DUMMYFUNCTION("""COMPUTED_VALUE"""),"")
A25: 45554.322 | B25: Tyson Enes | C25: FALSE | H25: 60 | J25: Breakfast | K25: 45551 | L25: Monday | M25: BF | N25: =IFERROR(__xludf.DUMMYFUNCTION("""COMPUTED_VALUE"""),116.0) -> 116 | O25: =IFERROR(__xludf.DUMMYFUNCTION("""COMPUTED_VALUE"""),261.0) -> 261 | P25: =IFERROR(__xludf.DUMMYFUNCTION("""COMPUTED_VALUE"""),377.0) -> 377
A26: 45552.545 | B26: Cassidy Haskell | C26: FALSE | H26: 72 | J26: Lunch | K26: 45552 | L26: Tuesday | M26: MF | N26: =IFERROR(__xludf.DUMMYFUNCTION("""COMPUTED_VALUE"""),"") | O26: =IFERROR(__xludf.DUMMYFUNCTION("""COMPUTED_VALUE"""),"") | P26: =IFERROR(__xludf.DUMMYFUNCTION("""COMPUTED_VALUE"""),"")
A27: 45552.621 | B27: Lucas Meier | C27: FALSE | H27: 43 | J27: Lunch | K27: 45552 | L27: Tuesday | M27: MF | N27: =IFERROR(__xludf.DUMMYFUNCTION("""COMPUTED_VALUE"""),"") | O27: =IFERROR(__xludf.DUMMYFUNCTION("""COMPUTED_VALUE"""),"") | P27: =IFERROR(__xludf.DUMMYFUNCTION("""COMPUTED_VALUE"""),"")
A28: 45552.625 | B28: Kayleigh O’Mealia | C28: FALSE | H28: 66 | J28: Lunch | K28: 45552 | L28: Tuesday | M28: BF | N28: =IFERROR(__xludf.DUMMYFUNCTION("""COMPUTED_VALUE"""),"") | O28: =IFERROR(__xludf.DUMMYFUNCTION("""COMPUTED_VALUE"""),"") | P28: =IFERROR(__xludf.DUMMYFUNCTION("""COMPUTED_VALUE"""),"")
A29: 45552.871 | B29: Bitanya Hailu | C29: FALSE | H29: 228 | J29: Dinner | K29: 45552 | L29: Tuesday | M29: MF | N29: =IFERROR(__xludf.DUMMYFUNCTION("""COMPUTED_VALUE"""),"") | O29: =IFERROR(__xludf.DUMMYFUNCTION("""COMPUTED_VALUE"""),"") | P29: =IFERROR(__xludf.DUMMYFUNCTION("""COMPUTED_VALUE"""),"")
A30: 45552.873 | B30: Kaya Pernini | C30: FALSE | H30: 58 | J30: Dinner | K30: 45552 | L30: Tuesday | M30: BF | N30: =IFERROR(__xludf.DUMMYFUNCTION("""COMPUTED_VALUE"""),343.0) -> 343 | O30: =IFERROR(__xludf.DUMMYFUNCTION("""COMPUTED_VALUE"""),124.0) -> 124 | P30: =IFERROR(__xludf.DUMMYFUNCTION("""COMPUTED_VALUE"""),467.0) -> 467
A31: 45553.423 | B31: Skyler bobinski | C31: FALSE | H31: 56 | J31: Breakfast | K31: 45553 | L31: Wednesday | M31: BF | N31: =IFERROR(__xludf.DUMMYFUNCTION("""COMPUTED_VALUE"""),"") | O31: =IFERROR(__xludf.DUMMYFUNCTION("""COMPUTED_VALUE"""),"") | P31: =IFERROR(__xludf.DUMMYFUNCTION("""COMPUTED_VALUE"""),"")
A32: 45553.5 | B32: Westin Palumbo | C32: FALSE | H32: 4 | J32: Lunch | K32: 45553 | L32: Wednesday | M32: MF | N32: =IFERROR(__xludf.DUMMYFUNCTION("""COMPUTED_VALUE"""),"") | O32: =IFERROR(__xludf.DUMMYFUNCTION("""COMPUTED_VALUE"""),"") | P32: =IFERROR(__xludf.DUMMYFUNCTION("""COMPUTED_VALUE"""),"")
A33: 45553.646 | B33: Lizzie Welch | C33: FALSE | H33: 102 | J33: Lunch | K33: 45553 | L33: Wednesday | M33: MF | N33: =IFERROR(__xludf.DUMMYFUNCTION("""COMPUTED_VALUE"""),"") | O33: =IFERROR(__xludf.DUMMYFUNCTION("""COMPUTED_VALUE"""),"") | P33: =IFERROR(__xludf.DUMMYFUNCTION("""COMPUTED_VALUE"""),"")
A34: 45554.754 | B34: astou dieng | C34: FALSE | H34: 60 | J34: Dinner | K34: 45553 | L34: Wednesday | M34: BF | N34: =IFERROR(__xludf.DUMMYFUNCTION("""COMPUTED_VALUE"""),106.0) -> 106 | O34: =IFERROR(__xludf.DUMMYFUNCTION("""COMPUTED_VALUE"""),116.0) -> 116 | P34: =IFERROR(__xludf.DUMMYFUNCTION("""COMPUTED_VALUE"""),222.0) -> 222
A35: 45554.474 | B35: Tyson Enes | C35: FALSE | H35: 52 | J35: Breakfast | K35: 45554 | L35: Thursday | M35: BF | N35: =IFERROR(__xludf.DUMMYFUNCTION("""COMPUTED_VALUE"""),"") | O35: =IFERROR(__xludf.DUMMYFUNCTION("""COMPUTED_VALUE"""),"") | P35: =IFERROR(__xludf.DUMMYFUNCTION("""COMPUTED_VALUE"""),"")
A36: 45554.559 | B36: Cassidy Haskell | C36: FALSE | H36: 43 | J36: Lunch | K36: 45554 | L36: Thursday | M36: MF | N36: =IFERROR(__xludf.DUMMYFUNCTION("""COMPUTED_VALUE"""),"") | O36: =IFERROR(__xludf.DUMMYFUNCTION("""COMPUTED_VALUE"""),"") | P36: =IFERROR(__xludf.DUMMYFUNCTION("""COMPUTED_VALUE"""),"")
A37: 45554.627 | B37: Kaya Pernini | C37: FALSE | H37: 66 | J37: Lunch | K37: 45554 | L37: Thursday | M37: BF | N37: =IFERROR(__xludf.DUMMYFUNCTION("""COMPUTED_VALUE"""),"") | O37: =IFERROR(__xludf.DUMMYFUNCTION("""COMPUTED_VALUE"""),"") | P37: =IFERROR(__xludf.DUMMYFUNCTION("""COMPUTED_VALUE"""),"")
A38: 45554.875 | B38: Lizzie Welch | C38: FALSE | H38: 37 | J38: Dinner | K38: 45554 | L38: Thursday | M38: MF | N38: =IFERROR(__xludf.DUMMYFUNCTION("""COMPUTED_VALUE"""),"") | O38: =IFERROR(__xludf.DUMMYFUNCTION("""COMPUTED_VALUE"""),"") | P38: =IFERROR(__xludf.DUMMYFUNCTION("""COMPUTED_VALUE"""),"")
A39: 45554.953 | B39: Lucas Meier | C39: FALSE | H39: 54 | J39: Lunch | K39: 45554 | L39: Thursday | M39: MF | N39: =IFERROR(__xludf.DUMMYFUNCTION("""COMPUTED_VALUE"""),134.0) -> 134 | O39: =IFERROR(__xludf.DUMMYFUNCTION("""COMPUTED_VALUE"""),118.0) -> 118 | P39: =IFERROR(__xludf.DUMMYFUNCTION("""COMPUTED_VALUE"""),252.0) -> 252
A40: 45555.395 | B40: Skyler Bobinski | C40: FALSE | H40: 46 | J40: Breakfast | K40: 45555 | L40: Friday | M40: BF | N40: =IFERROR(__xludf.DUMMYFUNCTION("""COMPUTED_VALUE"""),"") | O40: =IFERROR(__xludf.DUMMYFUNCTION("""COMPUTED_VALUE"""),"") | P40: =IFERROR(__xludf.DUMMYFUNCTION("""COMPUTED_VALUE"""),"")
...

Sheet S25
A1: Timestamp | B1: Name | C1: double name | D1: start hour | E1: hours worked | F1: end hour | G1: hours pp | H1: Derived Weight | I1: lb/hr per shift | J1: period | K1: Date | L1: Weekday | M1: dining hall | N1: MF lbs td | O1: BF lbs td | P1: lbs td
A2: 45677 | B2: N/A | C2: FALSE | H2: 0 | K2: 45677 | L2: Monday
A3: 45681 | B3: N/A | C3: FALSE | H3: 0 | K3: 45681 | L3: Friday
A4: 45684.632 | B4: Tyson Enes | C4: FALSE | H4: 50 | J4: Lunch | K4: 45684 | L4: Monday | M4: BF | N4: =IFERROR(__xludf.DUMMYFUNCTION("BYROW('S25'!K4:K784, LAMBDA(r, IF(r="""","""", LET( nextVal, IFERROR(INDEX('S25'!K4:K784, ROW(r)-ROW('S25'!K4)+2), """"), IF(r <> nextVal, IFERROR( SUM(FILTER('S25'!H4:H784, 'S25'!K4:K784 = r, 'S25'!M4:M784 = ""MF""))"&", """" ), """" ) ) ) ))"),"") | O4: =IFERROR(__xludf.DUMMYFUNCTION("BYROW('S25'!K4:K784, LAMBDA(r, IF(r="""","""", LET( nextVal, IFERROR(INDEX('S25'!K4:K784, ROW(r)-ROW('S25'!K4)+2), """"), IF(r <> nextVal, IFERROR( SUM(FILTER('S25'!H4:H784, 'S25'!K4:K784 = r, 'S25'!M4:M784 = ""BF""))"&", """" ), """" ) ) ) ))"),"") | P4: =IFERROR(__xludf.DUMMYFUNCTION("BYROW('S25'!K4:K784, LAMBDA(r, IF(r="""","""", LET( nextVal, IFERROR(INDEX('S25'!K4:K784, ROW(r)-ROW('S25'!K4)+2), """"), IF(r <> nextVal, IFERROR( SUM(FILTER('S25'!H4:H784, 'S25'!K4:K784 = r)), """" "&" ), """" ) ) ) )) "),"")
A5: 45684.876 | B5: Kaya Pernini | C5: FALSE | H5: 204 | J5: Dinner | K5: 45684 | L5: Monday | M5: BF | N5: =IFERROR(__xludf.DUMMYFUNCTION("""COMPUTED_VALUE"""),"") | O5: =IFERROR(__xludf.DUMMYFUNCTION("""COMPUTED_VALUE"""),254.0) -> 254 | P5: =IFERROR(__xludf.DUMMYFUNCTION("""COMPUTED_VALUE"""),254.0) -> 254
A6: 45685.456 | B6: Marley Ahlijanian | C6: FALSE | H6: 94 | J6: Breakfast | K6: 45685 | L6: Tuesday | M6: BF | N6: =IFERROR(__xludf.DUMMYFUNCTION("""COMPUTED_VALUE"""),"") | O6: =IFERROR(__xludf.DUMMYFUNCTION("""COMPUTED_VALUE"""),"") | P6: =IFERROR(__xludf.DUMMYFUNCTION("""COMPUTED_VALUE"""),"")
A7: 45685.648 | B7: marley ahlijanian | C7: FALSE | H7: 142 | J7: Lunch | K7: 45685 | L7: Tuesday | M7: MF | N7: =IFERROR(__xludf.DUMMYFUNCTION("""COMPUTED_VALUE"""),"") | O7: =IFERROR(__xludf.DUMMYFUNCTION("""COMPUTED_VALUE"""),"") | P7: =IFERROR(__xludf.DUMMYFUNCTION("""COMPUTED_VALUE"""),"")
A8: 45685.724 | B8: Maureen Surgot | C8: FALSE | H8: 197 | J8: Dinner | K8: 45685 | L8: Tuesday | M8: MF | N8: =IFERROR(__xludf.DUMMYFUNCTION("""COMPUTED_VALUE"""),"") | O8: =IFERROR(__xludf.DUMMYFUNCTION("""COMPUTED_VALUE"""),"") | P8: =IFERROR(__xludf.DUMMYFUNCTION("""COMPUTED_VALUE"""),"")
A9: 45685.874 | B9: Anna Cunha | C9: FALSE | H9: 221 | J9: Dinner | K9: 45685 | L9: Tuesday | M9: MF | N9: =IFERROR(__xludf.DUMMYFUNCTION("""COMPUTED_VALUE"""),"") | O9: =IFERROR(__xludf.DUMMYFUNCTION("""COMPUTED_VALUE"""),"") | P9: =IFERROR(__xludf.DUMMYFUNCTION("""COMPUTED_VALUE"""),"")
A10: 45685.88 | B10: Kaya Pernini | C10: FALSE | H10: 127 | J10: Dinner | K10: 45685 | L10: Tuesday | M10: BF | N10: =IFERROR(__xludf.DUMMYFUNCTION("""COMPUTED_VALUE"""),560.0) -> 560 | O10: =IFERROR(__xludf.DUMMYFUNCTION("""COMPUTED_VALUE"""),221.0) -> 221 | P10: =IFERROR(__xludf.DUMMYFUNCTION("""COMPUTED_VALUE"""),781.0) -> 781
A11: 45686.554 | B11: Kaitlyn Deierlein | C11: FALSE | H11: 72 | J11: Breakfast | K11: 45686 | L11: Wednesday | M11: BF | N11: =IFERROR(__xludf.DUMMYFUNCTION("""COMPUTED_VALUE"""),"") | O11: =IFERROR(__xludf.DUMMYFUNCTION("""COMPUTED_VALUE"""),"") | P11: =IFERROR(__xludf.DUMMYFUNCTION("""COMPUTED_VALUE"""),"")
A12: 45686.65 | B12: Tyson Enes | C12: FALSE | H12: 178 | J12: Lunch | K12: 45686 | L12: Wednesday | M12: BF | N12: =IFERROR(__xludf.DUMMYFUNCTION("""COMPUTED_VALUE"""),"") | O12: =IFERROR(__xludf.DUMMYFUNCTION("""COMPUTED_VALUE"""),"") | P12: =IFERROR(__xludf.DUMMYFUNCTION("""COMPUTED_VALUE"""),"")
A13: 45686.884 | B13: Maureen Surgot | C13: FALSE | H13: 140 | J13: Dinner | K13: 45686 | L13: Wednesday | M13: MF | N13: =IFERROR(__xludf.DUMMYFUNCTION("""COMPUTED_VALUE"""),"") | O13: =IFERROR(__xludf.DUMMYFUNCTION("""COMPUTED_VALUE"""),"") | P13: =IFERROR(__xludf.DUMMYFUNCTION("""COMPUTED_VALUE"""),"")
A14: 45686.888 | B14: Leisly Aceituno | C14: FALSE | H14: 46 | J14: Lunch | K14: 45686 | L14: Wednesday | M14: MF | N14: =IFERROR(__xludf.DUMMYFUNCTION("""COMPUTED_VALUE"""),186.0) -> 186 | O14: =IFERROR(__xludf.DUMMYFUNCTION("""COMPUTED_VALUE"""),250.0) -> 250 | P14: =IFERROR(__xludf.DUMMYFUNCTION("""COMPUTED_VALUE"""),436.0) -> 436
A15: 45687.382 | B15: Skyler Bobinski | C15: FALSE | H15: 40 | J15: Breakfast | K15: 45687 | L15: Thursday | M15: BF | N15: =IFERROR(__xludf.DUMMYFUNCTION("""COMPUTED_VALUE"""),"") | O15: =IFERROR(__xludf.DUMMYFUNCTION("""COMPUTED_VALUE"""),"") | P15: =IFERROR(__xludf.DUMMYFUNCTION("""COMPUTED_VALUE"""),"")
A16: 45687.623 | B16: Lizzie Welch | C16: FALSE | H16: 107 | J16: Lunch | K16: 45687 | L16: Thursday | M16: BF | N16: =IFERROR(__xludf.DUMMYFUNCTION("""COMPUTED_VALUE"""),"") | O16: =IFERROR(__xludf.DUMMYFUNCTION("""COMPUTED_VALUE"""),"") | P16: =IFERROR(__xludf.DUMMYFUNCTION("""COMPUTED_VALUE"""),"")
A17: 45687.785 | B17: Kate Stanwood | C17: FALSE | H17: 190 | J17: Dinner | K17: 45687 | L17: Thursday | M17: MF | N17: =IFERROR(__xludf.DUMMYFUNCTION("""COMPUTED_VALUE"""),190.0) -> 190 | O17: =IFERROR(__xludf.DUMMYFUNCTION("""COMPUTED_VALUE"""),147.0) -> 147 | P17: =IFERROR(__xludf.DUMMYFUNCTION("""COMPUTED_VALUE"""),337.0) -> 337
A18: 45688.579 | B18: Kate Stanwood | C18: FALSE | H18: 174 | J18: Lunch | K18: 45688 | L18: Friday | M18: BF | N18: =IFERROR(__xludf.DUMMYFUNCTION("""COMPUTED_VALUE"""),"") | O18: =IFERROR(__xludf.DUMMYFUNCTION("""COMPUTED_VALUE"""),"") | P18: =IFERROR(__xludf.DUMMYFUNCTION("""COMPUTED_VALUE"""),"")
A19: 45688.643 | B19: Leisly Aceituno | C19: FALSE | H19: 143 | J19: Lunch | K19: 45688 | L19: Friday | M19: MF | N19: =IFERROR(__xludf.DUMMYFUNCTION("""COMPUTED_VALUE"""),"") | O19: =IFERROR(__xludf.DUMMYFUNCTION("""COMPUTED_VALUE"""),"") | P19: =IFERROR(__xludf.DUMMYFUNCTION("""COMPUTED_VALUE"""),"")
A20: 45688.927 | B20: Bitanya Hailu | C20: FALSE | H20: 167 | J20: Dinner | K20: 45688 | L20: Friday | M20: MF | N20: =IFERROR(__xludf.DUMMYFUNCTION("""COMPUTED_VALUE"""),310.0) -> 310 | O20: =IFERROR(__xludf.DUMMYFUNCTION("""COMPUTED_VALUE"""),174.0) -> 174 | P20: =IFERROR(__xludf.DUMMYFUNCTION("""COMPUTED_VALUE"""),484.0) -> 484
A21: 45691.438 | B21: Kaitlyn Deierlein | C21: FALSE | H21: 67 | J21: Breakfast | K21: 45691 | L21: Monday | M21: BF | N21: =IFERROR(__xludf.DUMMYFUNCTION("""COMPUTED_VALUE"""),"") | O21: =IFERROR(__xludf.DUMMYFUNCTION("""COMPUTED_VALUE"""),"") | P21: =IFERROR(__xludf.DUMMYFUNCTION("""COMPUTED_VALUE"""),"")
A22: 45691.876 | B22: Kaya Pernini | C22: FALSE | H22: 221 | J22: Dinner | K22: 45691 | L22: Monday | M22: BF | N22: =IFERROR(__xludf.DUMMYFUNCTION("""COMPUTED_VALUE"""),"") | O22: =IFERROR(__xludf.DUMMYFUNCTION("""COMPUTED_VALUE"""),"") | P22: =IFERROR(__xludf.DUMMYFUNCTION("""COMPUTED_VALUE"""),"")
A23: 45691.916 | B23: Maureen Surgot | C23: FALSE | H23: 189 | J23: Dinner | K23: 45691 | L23: Monday | M23: MF | N23: =IFERROR(__xludf.DUMMYFUNCTION("""COMPUTED_VALUE"""),"") | O23: =IFERROR(__xludf.DUMMYFUNCTION("""COMPUTED_VALUE"""),"") | P23: =IFERROR(__xludf.DUMMYFUNCTION("""COMPUTED_VALUE"""),"")
A24: 45714.518 | B24: Brynn Hornig | C24: FALSE | H24: 143 | J24: Lunch | K24: 45691 | L24: Monday | M24: MF | N24: =IFERROR(__xludf.DUMMYFUNCTION("""COMPUTED_VALUE"""),"") | O24: =IFERROR(__xludf.DUMMYFUNCTION("""COMPUTED_VALUE"""),"") | P24: =IFERROR(__xludf.DUMMYFUNCTION("""COMPUTED_VALUE"""),"")
A25: 45693.649 | B25: Tyson Enes | C25: FALSE | H25: 143 | J25: Lunch | K25: 45691 | L25: Monday | M25: BF | N25: =IFERROR(__xludf.DUMMYFUNCTION("""COMPUTED_VALUE"""),332.0) -> 332 | O25: =IFERROR(__xludf.DUMMYFUNCTION("""COMPUTED_VALUE"""),431.0) -> 431 | P25: =IFERROR(__xludf.DUMMYFUNCTION("""COMPUTED_VALUE"""),763.0) -> 763
A26: 45692.491 | B26: marley ahlijanian | C26: FALSE | H26: 83 | J26: Breakfast | K26: 45692 | L26: Tuesday | M26: BF | N26: =IFERROR(__xludf.DUMMYFUNCTION("""COMPUTED_VALUE"""),"") | O26: =IFERROR(__xludf.DUMMYFUNCTION("""COMPUTED_VALUE"""),"") | P26: =IFERROR(__xludf.DUMMYFUNCTION("""COMPUTED_VALUE"""),"")
A27: 45692.616 | B27: Lizzie Welch | C27: FALSE | H27: 117 | J27: Lunch | K27: 45692 | L27: Tuesday | M27: BF | N27: =IFERROR(__xludf.DUMMYFUNCTION("""COMPUTED_VALUE"""),"") | O27: =IFERROR(__xludf.DUMMYFUNCTION("""COMPUTED_VALUE"""),"") | P27: =IFERROR(__xludf.DUMMYFUNCTION("""COMPUTED_VALUE"""),"")
A28: 45692.82 | B28: Anna Cunha | C28: FALSE | H28: 241 | J28: Dinner | K28: 45692 | L28: Tuesday | M28: MF | N28: =IFERROR(__xludf.DUMMYFUNCTION("""COMPUTED_VALUE"""),"") | O28: =IFERROR(__xludf.DUMMYFUNCTION("""COMPUTED_VALUE"""),"") | P28: =IFERROR(__xludf.DUMMYFUNCTION("""COMPUTED_VALUE"""),"")
A29: 45692.918 | B29: Kaya Pernini | C29: FALSE | H29: 123 | J29: Dinner | K29: 45692 | L29: Tuesday | M29: BF | N29: =IFERROR(__xludf.DUMMYFUNCTION("""COMPUTED_VALUE"""),"") | O29: =IFERROR(__xludf.DUMMYFUNCTION("""COMPUTED_VALUE"""),"") | P29: =IFERROR(__xludf.DUMMYFUNCTION("""COMPUTED_VALUE"""),"")
A30: 45692.948 | B30: marley ahlijanian | C30: FALSE | H30: 105 | J30: Lunch | K30: 45692 | L30: Tuesday | M30: MF | N30: =IFERROR(__xludf.DUMMYFUNCTION("""COMPUTED_VALUE"""),346.0) -> 346 | O30: =IFERROR(__xludf.DUMMYFUNCTION("""COMPUTED_VALUE"""),323.0) -> 323 | P30: =IFERROR(__xludf.DUMMYFUNCTION("""COMPUTED_VALUE"""),669.0) -> 669
A31: 45693.376 | B31: Kaitlyn Deierlein | C31: FALSE | H31: 65 | J31: Breakfast | K31: 45693 | L31: Wednesday | M31: BF | N31: =IFERROR(__xludf.DUMMYFUNCTION("""COMPUTED_VALUE"""),"") | O31: =IFERROR(__xludf.DUMMYFUNCTION("""COMPUTED_VALUE"""),"") | P31: =IFERROR(__xludf.DUMMYFUNCTION("""COMPUTED_VALUE"""),"")
A32: 45693.441 | B32: Kaitlyn Deierlein | C32: FALSE | H32: 44 | J32: Breakfast | K32: 45693 | L32: Wednesday | M32: BF | N32: =IFERROR(__xludf.DUMMYFUNCTION("""COMPUTED_VALUE"""),"") | O32: =IFERROR(__xludf.DUMMYFUNCTION("""COMPUTED_VALUE"""),"") | P32: =IFERROR(__xludf.DUMMYFUNCTION("""COMPUTED_VALUE"""),"")
A33: 45693.57 | B33: Leisly Aceituno | C33: FALSE | H33: 71 | J33: Lunch | K33: 45693 | L33: Wednesday | M33: MF | N33: =IFERROR(__xludf.DUMMYFUNCTION("""COMPUTED_VALUE"""),"") | O33: =IFERROR(__xludf.DUMMYFUNCTION("""COMPUTED_VALUE"""),"") | P33: =IFERROR(__xludf.DUMMYFUNCTION("""COMPUTED_VALUE"""),"")
A34: 45693.988 | B34: Maureen Surgot | C34: FALSE | H34: 147 | J34: Dinner | K34: 45693 | L34: Wednesday | M34: MF | N34: =IFERROR(__xludf.DUMMYFUNCTION("""COMPUTED_VALUE"""),218.0) -> 218 | O34: =IFERROR(__xludf.DUMMYFUNCTION("""COMPUTED_VALUE"""),109.0) -> 109 | P34: =IFERROR(__xludf.DUMMYFUNCTION("""COMPUTED_VALUE"""),327.0) -> 327
A35: 45693.65 | B35: Tyson Enes | C35: FALSE | H35: 143 | J35: Lunch | K35: 45694 | L35: Thursday | M35: BF | N35: =IFERROR(__xludf.DUMMYFUNCTION("""COMPUTED_VALUE"""),"") | O35: =IFERROR(__xludf.DUMMYFUNCTION("""COMPUTED_VALUE"""),"") | P35: =IFERROR(__xludf.DUMMYFUNCTION("""COMPUTED_VALUE"""),"")
A36: 45694.421 | B36: Skyler Bobinski | C36: FALSE | H36: 40 | J36: Breakfast | K36: 45694 | L36: Thursday | M36: BF | N36: =IFERROR(__xludf.DUMMYFUNCTION("""COMPUTED_VALUE"""),"") | O36: =IFERROR(__xludf.DUMMYFUNCTION("""COMPUTED_VALUE"""),"") | P36: =IFERROR(__xludf.DUMMYFUNCTION("""COMPUTED_VALUE"""),"")
A37: 45694.623 | B37: Lizzie Welch | C37: FALSE | H37: 150 | J37: Lunch | K37: 45694 | L37: Thursday | M37: BF | N37: =IFERROR(__xludf.DUMMYFUNCTION("""COMPUTED_VALUE"""),"") | O37: =IFERROR(__xludf.DUMMYFUNCTION("""COMPUTED_VALUE"""),333.0) -> 333 | P37: =IFERROR(__xludf.DUMMYFUNCTION("""COMPUTED_VALUE"""),333.0) -> 333
A38: 45695.584 | B38: Leisly Aceituno | C38: FALSE | H38: 185 | J38: Lunch | K38: 45695 | L38: Friday | M38: MF | N38: =IFERROR(__xludf.DUMMYFUNCTION("""COMPUTED_VALUE"""),"") | O38: =IFERROR(__xludf.DUMMYFUNCTION("""COMPUTED_VALUE"""),"") | P38: =IFERROR(__xludf.DUMMYFUNCTION("""COMPUTED_VALUE"""),"")
A39: 45695.644 | B39: Leisly Aceituno | C39: FALSE | H39: 85 | J39: Lunch | K39: 45695 | L39: Friday | M39: MF | N39: =IFERROR(__xludf.DUMMYFUNCTION("""COMPUTED_VALUE"""),"") | O39: =IFERROR(__xludf.DUMMYFUNCTION("""COMPUTED_VALUE"""),"") | P39: =IFERROR(__xludf.DUMMYFUNCTION("""COMPUTED_VALUE"""),"")
A40: 45696.345 | B40: Bitanya Hailu | C40: FALSE | H40: 219 | J40: Dinner | K40: 45695 | L40: Friday | M40: MF | N40: =IFERROR(__xludf.DUMMYFUNCTION("""COMPUTED_VALUE"""),489.0) -> 489 | O40: =IFERROR(__xludf.DUMMYFUNCTION("""COMPUTED_VALUE"""),"") | P40: =IFERROR(__xludf.DUMMYFUNCTION("""COMPUTED_VALUE"""),489.0) -> 489
...

Sheet F25
