Workbook

Sheet Impact Calculations
A2: Methods:
A4: Functional unit: 1 short ton of mixed food waste Sector: Foodservice Food mix: ReFED standard mix Boundary: End-of-life only (no prevention) Time horizon: 100-year GWP (AR6) Destinations modeled: - Composting - Anaerobic digestion - Landfill (baseline only) | F4: Magic numbers
F5: the magic # | G5: =1 / 2000 * (G8 - (G6*G9 + G7*G10)) -> 0.000317765 | H5: metric tons of emissions impact
F6: Compost EF | G6: 1.13437 | H6: CO₂e / metric ton
F7: AD EF | G7: 1.17477 | H7: metric tons of CO₂e
F8: Landfill EF | G8: 1.7901 | H8: metric tons of CO₂e
F9: compost fraction | G9: 0.5 | H9: /1
F10: AD fraction | G10: 0.5 | H10: /1
A18: ReFED - Impact Calculator

Sheet Master of Masters
C1: YoY Composting Data
K2: Tab List:
K3: Master Spring 2024
K4: Master Fall 2024
A5: descriptions | B5: Mainfare Total Data | E5: Butterfield Total Data | H5: Total Data | K5: Master Spring 2025
A6: The total lbs collected | B6: Total lbs | C6: {=SUM( MAP( $K$3:$K1000, LAMBDA(s, IF( s="", 0, INDIRECT("'" & s & "'!C" & ROW()) ) ) ) )} -> 64036 | E6: Total lbs | F6: {=SUM( MAP( $K$3:$K1000, LAMBDA(s, IF( s="", 0, INDIRECT("'" & s & "'!F" & ROW()) ) ) ) )} -> 64026 | H6: Total lbs | I6: {=SUM( MAP( $K$3:$K1000, LAMBDA(s, IF( s="", 0, INDIRECT("'" & s & "'!I" & ROW()) ) ) ) )} -> 135172.86 | K6: Master Fall 2025
A7: The average of the total lbs collected each day | B7: avg lb p/wrkday | C7: =IFERROR(__xludf.DUMMYFUNCTION("LET( vals, MAP( $K$3:$K1000, LAMBDA(s, IF(s="""", """", INDIRECT(""'"" & s & ""'!C"" & ROW()) ) ) ), nums, FILTER(vals, ISNUMBER(vals)), IF(COUNTA(nums)=0, """", SUM(nums)/COUNTA(nums)) )"),244.1981358040307) -> 244.19814 | E7: avg lb p/wrkday | F7: =IFERROR(__xludf.DUMMYFUNCTION("LET( vals, MAP( $K$3:$K1000, LAMBDA(s, IF(s="""", """", INDIRECT(""'"" & s & ""'!F"" & ROW()) ) ) ), nums, FILTER(vals, ISNUMBER(vals)), IF(COUNTA(nums)=0, """", SUM(nums)/COUNTA(nums)) )"),257.38734452250844) -> 257.38734 | H7: avg lb p/wrkday | I7: =IFERROR(__xludf.DUMMYFUNCTION("LET( vals, MAP( $K$3:$K1000, LAMBDA(s, IF(s="""", """", INDIRECT(""'"" & s & ""'!I"" & ROW()) ) ) ), nums, FILTER(vals, ISNUMBER(vals)), IF(COUNTA(nums)=0, """", SUM(nums)/COUNTA(nums)) )"),426.06165298507466) -> 426.06165 | K7: Master Spring 2026
A8: The total lbs collected over the total hours worked | B8: Total lbs/hr | C8: {=SUM( MAP( $K$3:$K1000, LAMBDA(s, IF( s="", 0, INDIRECT("'" & s & "'!C" & ROW()) ) ) ) )} -> 112.41058 | E8: Total lbs/hr | F8: {=SUM( MAP( $K$3:$K1000, LAMBDA(s, IF( s="", 0, INDIRECT("'" & s & "'!F" & ROW()) ) ) ) )} -> 84.274844 | H8: Total lbs/hr | I8: {=SUM( MAP( $K$3:$K1000, LAMBDA(s, IF( s="", 0, INDIRECT("'" & s & "'!I" & ROW()) ) ) ) )} -> 96.944684
A9: The average of the hourly rate of each ambassador | B9: avg ambassador lb p/hr | C9: =IFERROR(__xludf.DUMMYFUNCTION("LET( vals, MAP( $K$3:$K1000, LAMBDA(s, IF(s="""", """", INDIRECT(""'"" & s & ""'!C"" & ROW()) ) ) ), nums, FILTER(vals, ISNUMBER(vals)), IF(COUNTA(nums)=0, """", SUM(nums)/COUNTA(nums)) )"),57.663306695244074) -> 57.663307 | E9: avg ambassador lb p/hr | F9: =IFERROR(__xludf.DUMMYFUNCTION("LET( vals, MAP( $K$3:$K1000, LAMBDA(s, IF(s="""", """", INDIRECT(""'"" & s & ""'!F"" & ROW()) ) ) ), nums, FILTER(vals, ISNUMBER(vals)), IF(COUNTA(nums)=0, """", SUM(nums)/COUNTA(nums)) )"),43.94825664995053) -> 43.948257 | H9: avg ambassador lb p/hr | I9: =IFERROR(__xludf.DUMMYFUNCTION("LET( vals, MAP( $K$3:$K1000, LAMBDA(s, IF(s="""", """", INDIRECT(""'"" & s & ""'!I"" & ROW()) ) ) ), nums, FILTER(vals, ISNUMBER(vals)), IF(COUNTA(nums)=0, """", SUM(nums)/COUNTA(nums)) )"),51.1387679836608) -> 51.138768
A10: The total hours worked | B10: Total hours | C10: {=SUM( MAP( $K$3:$K1000, LAMBDA(s, IF( s="", 0, INDIRECT("'" & s & "'!C" & ROW()) ) ) ) )} -> 564.19667 | E10: Total hours | F10: {=SUM( MAP( $K$3:$K1000, LAMBDA(s, IF( s="", 0, INDIRECT("'" & s & "'!F" & ROW()) ) ) ) )} -> 675.84667 | H10: Total hours | I10: {=SUM( MAP( $K$3:$K1000, LAMBDA(s, IF( s="", 0, INDIRECT("'" & s & "'!I" & ROW()) ) ) ) )} -> 1240.0533
A11: The average of all of the hours worked each day | B11: avg hrs/day | C11: =IFERROR(__xludf.DUMMYFUNCTION("LET( vals, MAP( $K$3:$K1000, LAMBDA(s, IF(s="""", """", INDIRECT(""'"" & s & ""'!C"" & ROW()) ) ) ), nums, FILTER(vals, ISNUMBER(vals)), IF(COUNTA(nums)=0, """", SUM(nums)/COUNTA(nums)) )"),0.20402475469940068) -> 0.20402475 | E11: avg hrs/day | F11: =IFERROR(__xludf.DUMMYFUNCTION("LET( vals, MAP( $K$3:$K1000, LAMBDA(s, IF(s="""", """", INDIRECT(""'"" & s & ""'!F"" & ROW()) ) ) ), nums, FILTER(vals, ISNUMBER(vals)), IF(COUNTA(nums)=0, """", SUM(nums)/COUNTA(nums)) )"),0.2568896053787011) -> 0.25688961 | H11: avg hrs/day | I11: =IFERROR(__xludf.DUMMYFUNCTION("LET( vals, MAP( $K$3:$K1000, LAMBDA(s, IF(s="""", """", INDIRECT(""'"" & s & ""'!I"" & ROW()) ) ) ), nums, FILTER(vals, ISNUMBER(vals)), IF(COUNTA(nums)=0, """", SUM(nums)/COUNTA(nums)) )"),0.43644848673321524) -> 0.43644849
A12: The number of lbs of CO2 not emitted due to diversion | B12: Impact [lbs of Co2e] | C12: =(C6*'Impact Calculations'!G5)*2000 -> 40696.799 | E12: Impact [lbs of Co2e] | F12: =(F6*'Impact Calculations'!G5)*2000 -> 40690.444 | H12: Impact [lbs of Co2e] | I12: =(I6*'Impact Calculations'!G5)*2000 -> 85906.408
H15: Total Data
H16: # of shifts worked | I16: {=SUM( MAP( $K$3:$K1000, LAMBDA(s, IF( s="", 0, IFERROR( INDIRECT("'" & s & "'!D" & ROW(D37)), 0 ) ) ) ) )} -> 1089
H17: avg lb/shift | I17: =I6/I16 -> 124.12567

Sheet Master Graphs
A1: Color Key
A2: Text | B2: Eco | C2: Mainfare & Butterfield | D2: Mainfare | E2: Butterfield
A3: Background | B3: Eco | C3: Mainfare & Butterfield | D3: Mainfare | E3: Butterfield | F3: Aggregate/General | G3: Period | L3: NOTE: | M3: interactive chart | N3: [under development]
A4: Bar Color | B4: S24 | C4: F24 | D4: S25 | E4: F25 | F4: S26 | G4: Mainfare & Butterfield | H4: Mainfare | I4: Butterfield | J4: Trend

Sheet YoY Data Sheet Tables
A1: =IFERROR(__xludf.DUMMYFUNCTION("IMPORTRANGE(""https://docs.google.com/spreadsheets/d/1CwrjPhJINZWO4jEU_saNz0V1dzS-UwSgU5fMaUfZ7VY/edit?gid=303306520#gid=303306520"", ""'YoY Viz Data'!A1:R225"")"),"Bulk Tab →") -> Bulk Tab → | B1: =IFERROR(__xludf.DUMMYFUNCTION("""COMPUTED_VALUE"""),"S24") -> S24 | C1: =IFERROR(__xludf.DUMMYFUNCTION("""COMPUTED_VALUE"""),"F24") -> F24 | D1: =IFERROR(__xludf.DUMMYFUNCTION("""COMPUTED_VALUE"""),"S25") -> S25 | E1: =IFERROR(__xludf.DUMMYFUNCTION("""COMPUTED_VALUE"""),"F25") -> F25 | F1: =IFERROR(__xludf.DUMMYFUNCTION("""COMPUTED_VALUE"""),"S26") -> S26
A2: =IFERROR(__xludf.DUMMYFUNCTION("""COMPUTED_VALUE"""),"Sem Start Date →") -> Sem Start Date → | B2: =IFERROR(__xludf.DUMMYFUNCTION("""COMPUTED_VALUE"""),45313.0) -> 45313 | C2: =IFERROR(__xludf.DUMMYFUNCTION("""COMPUTED_VALUE"""),45544.0) -> 45544 | D2: =IFERROR(__xludf.DUMMYFUNCTION("""COMPUTED_VALUE"""),45677.0) -> 45677 | E2: =IFERROR(__xludf.DUMMYFUNCTION("""COMPUTED_VALUE"""),45908.0) -> 45908 | F2: =IFERROR(__xludf.DUMMYFUNCTION("""COMPUTED_VALUE"""),46041.0) -> 46041
A4: =IFERROR(__xludf.DUMMYFUNCTION("""COMPUTED_VALUE"""),"T8 · lbs by Period per Semester → stacked bar chart") -> T8 · lbs by Period per Semester → stacked bar chart
A5: =IFERROR(__xludf.DUMMYFUNCTION("""COMPUTED_VALUE"""),"Period") -> Period | B5: =IFERROR(__xludf.DUMMYFUNCTION("""COMPUTED_VALUE"""),"S24") -> S24 | C5: =IFERROR(__xludf.DUMMYFUNCTION("""COMPUTED_VALUE"""),"F24") -> F24 | D5: =IFERROR(__xludf.DUMMYFUNCTION("""COMPUTED_VALUE"""),"S25") -> S25 | E5: =IFERROR(__xludf.DUMMYFUNCTION("""COMPUTED_VALUE"""),"F25") -> F25 | F5: =IFERROR(__xludf.DUMMYFUNCTION("""COMPUTED_VALUE"""),"S26*") -> S26*
A6: =IFERROR(__xludf.DUMMYFUNCTION("""COMPUTED_VALUE"""),"Breakfast") -> Breakfast | B6: =IFERROR(__xludf.DUMMYFUNCTION("""COMPUTED_VALUE"""),727.1800000000001) -> 727.18 | C6: =IFERROR(__xludf.DUMMYFUNCTION("""COMPUTED_VALUE"""),2685.0) -> 2685 | D6: =IFERROR(__xludf.DUMMYFUNCTION("""COMPUTED_VALUE"""),4199.0) -> 4199 | E6: =IFERROR(__xludf.DUMMYFUNCTION("""COMPUTED_VALUE"""),1851.0) -> 1851 | F6: =IFERROR(__xludf.DUMMYFUNCTION("""COMPUTED_VALUE"""),2634.0) -> 2634
A7: =IFERROR(__xludf.DUMMYFUNCTION("""COMPUTED_VALUE"""),"Lunch") -> Lunch | B7: =IFERROR(__xludf.DUMMYFUNCTION("""COMPUTED_VALUE"""),3747.78) -> 3747.78 | C7: =IFERROR(__xludf.DUMMYFUNCTION("""COMPUTED_VALUE"""),12163.0) -> 12163 | D7: =IFERROR(__xludf.DUMMYFUNCTION("""COMPUTED_VALUE"""),13311.0) -> 13311 | E7: =IFERROR(__xludf.DUMMYFUNCTION("""COMPUTED_VALUE"""),14184.5) -> 14184.5 | F7: =IFERROR(__xludf.DUMMYFUNCTION("""COMPUTED_VALUE"""),9821.0) -> 9821
A8: =IFERROR(__xludf.DUMMYFUNCTION("""COMPUTED_VALUE"""),"Dinner") -> Dinner | B8: =IFERROR(__xludf.DUMMYFUNCTION("""COMPUTED_VALUE"""),2431.9) -> 2431.9 | C8: =IFERROR(__xludf.DUMMYFUNCTION("""COMPUTED_VALUE"""),10619.0) -> 10619 | D8: =IFERROR(__xludf.DUMMYFUNCTION("""COMPUTED_VALUE"""),13563.0) -> 13563 | E8: =IFERROR(__xludf.DUMMYFUNCTION("""COMPUTED_VALUE"""),15726.5) -> 15726.5 | F8: =IFERROR(__xludf.DUMMYFUNCTION("""COMPUTED_VALUE"""),13964.0) -> 13964
A9: =IFERROR(__xludf.DUMMYFUNCTION("""COMPUTED_VALUE"""),"Breakfast/Lunch") -> Breakfast/Lunch | B9: =IFERROR(__xludf.DUMMYFUNCTION("""COMPUTED_VALUE"""),0.0) -> 0 | C9: =IFERROR(__xludf.DUMMYFUNCTION("""COMPUTED_VALUE"""),919.0) -> 919 | D9: =IFERROR(__xludf.DUMMYFUNCTION("""COMPUTED_VALUE"""),0.0) -> 0 | E9: =IFERROR(__xludf.DUMMYFUNCTION("""COMPUTED_VALUE"""),1675.0) -> 1675 | F9: =IFERROR(__xludf.DUMMYFUNCTION("""COMPUTED_VALUE"""),2141.0) -> 2141
A10: =IFERROR(__xludf.DUMMYFUNCTION("""COMPUTED_VALUE"""),"Total") -> Total | B10: =IFERROR(__xludf.DUMMYFUNCTION("""COMPUTED_VALUE"""),6906.860000000001) -> 6906.86 | C10: =IFERROR(__xludf.DUMMYFUNCTION("""COMPUTED_VALUE"""),26386.0) -> 26386 | D10: =IFERROR(__xludf.DUMMYFUNCTION("""COMPUTED_VALUE"""),31073.0) -> 31073 | E10: =IFERROR(__xludf.DUMMYFUNCTION("""COMPUTED_VALUE"""),33437.0) -> 33437 | F10: =IFERROR(__xludf.DUMMYFUNCTION("""COMPUTED_VALUE"""),28560.0) -> 28560
A11: =IFERROR(__xludf.DUMMYFUNCTION("""COMPUTED_VALUE"""),"† S24: period approximated from timestamp hour (B: 6–11am, L: 11am–4pm, D: 4–10pm). Dining Hall unavailable for S24.") -> † S24: period approximated from timestamp hour (B: 6–11am, L: 11am–4pm, D: 4–10pm). Dining Hall unavailable for S24.
A13: =IFERROR(__xludf.DUMMYFUNCTION("""COMPUTED_VALUE"""),"T9 · lbs by Period × Hall per Semester → grouped bar / heatmap") -> T9 · lbs by Period × Hall per Semester → grouped bar / heatmap
A14: =IFERROR(__xludf.DUMMYFUNCTION("""COMPUTED_VALUE"""),"Period") -> Period | B14: =IFERROR(__xludf.DUMMYFUNCTION("""COMPUTED_VALUE"""),"Hall") -> Hall | C14: =IFERROR(__xludf.DUMMYFUNCTION("""COMPUTED_VALUE"""),"S24") -> S24 | D14: =IFERROR(__xludf.DUMMYFUNCTION("""COMPUTED_VALUE"""),"F24") -> F24 | E14: =IFERROR(__xludf.DUMMYFUNCTION("""COMPUTED_VALUE"""),"S25") -> S25 | F14: =IFERROR(__xludf.DUMMYFUNCTION("""COMPUTED_VALUE"""),"F25") -> F25 | G14: =IFERROR(__xludf.DUMMYFUNCTION("""COMPUTED_VALUE"""),"S26*") -> S26*
A15: =IFERROR(__xludf.DUMMYFUNCTION("""COMPUTED_VALUE"""),"Dinner") -> Dinner | B15: =IFERROR(__xludf.DUMMYFUNCTION("""COMPUTED_VALUE"""),"MF") -> MF | C15: =IFERROR(__xludf.DUMMYFUNCTION("""COMPUTED_VALUE"""),0.0) -> 0 | D15: =IFERROR(__xludf.DUMMYFUNCTION("""COMPUTED_VALUE"""),5145.0) -> 5145 | E15: =IFERROR(__xludf.DUMMYFUNCTION("""COMPUTED_VALUE"""),7476.0) -> 7476 | F15: =IFERROR(__xludf.DUMMYFUNCTION("""COMPUTED_VALUE"""),8260.0) -> 8260 | G15: =IFERROR(__xludf.DUMMYFUNCTION("""COMPUTED_VALUE"""),8696.0) -> 8696
A16: =IFERROR(__xludf.DUMMYFUNCTION("""COMPUTED_VALUE"""),"Dinner") -> Dinner | B16: =IFERROR(__xludf.DUMMYFUNCTION("""COMPUTED_VALUE"""),"BF") -> BF | C16: =IFERROR(__xludf.DUMMYFUNCTION("""COMPUTED_VALUE"""),0.0) -> 0 | D16: =IFERROR(__xludf.DUMMYFUNCTION("""COMPUTED_VALUE"""),5474.0) -> 5474 | E16: =IFERROR(__xludf.DUMMYFUNCTION("""COMPUTED_VALUE"""),6087.0) -> 6087 | F16: =IFERROR(__xludf.DUMMYFUNCTION("""COMPUTED_VALUE"""),7466.5) -> 7466.5 | G16: =IFERROR(__xludf.DUMMYFUNCTION("""COMPUTED_VALUE"""),5268.0) -> 5268
A17: =IFERROR(__xludf.DUMMYFUNCTION("""COMPUTED_VALUE"""),"Lunch") -> Lunch | B17: =IFERROR(__xludf.DUMMYFUNCTION("""COMPUTED_VALUE"""),"MF") -> MF | C17: =IFERROR(__xludf.DUMMYFUNCTION("""COMPUTED_VALUE"""),0.0) -> 0 | D17: =IFERROR(__xludf.DUMMYFUNCTION("""COMPUTED_VALUE"""),6636.0) -> 6636 | E17: =IFERROR(__xludf.DUMMYFUNCTION("""COMPUTED_VALUE"""),6793.0) -> 6793 | F17: =IFERROR(__xludf.DUMMYFUNCTION("""COMPUTED_VALUE"""),9189.0) -> 9189 | G17: =IFERROR(__xludf.DUMMYFUNCTION("""COMPUTED_VALUE"""),6214.0) -> 6214
A18: =IFERROR(__xludf.DUMMYFUNCTION("""COMPUTED_VALUE"""),"Lunch") -> Lunch | B18: =IFERROR(__xludf.DUMMYFUNCTION("""COMPUTED_VALUE"""),"BF") -> BF | C18: =IFERROR(__xludf.DUMMYFUNCTION("""COMPUTED_VALUE"""),0.0) -> 0 | D18: =IFERROR(__xludf.DUMMYFUNCTION("""COMPUTED_VALUE"""),5527.0) -> 5527 | E18: =IFERROR(__xludf.DUMMYFUNCTION("""COMPUTED_VALUE"""),6518.0) -> 6518 | F18: =IFERROR(__xludf.DUMMYFUNCTION("""COMPUTED_VALUE"""),4995.5) -> 4995.5 | G18: =IFERROR(__xludf.DUMMYFUNCTION("""COMPUTED_VALUE"""),3607.0) -> 3607
A19: =IFERROR(__xludf.DUMMYFUNCTION("""COMPUTED_VALUE"""),"Breakfast") -> Breakfast | B19: =IFERROR(__xludf.DUMMYFUNCTION("""COMPUTED_VALUE"""),"BF") -> BF | C19: =IFERROR(__xludf.DUMMYFUNCTION("""COMPUTED_VALUE"""),0.0) -> 0 | D19: =IFERROR(__xludf.DUMMYFUNCTION("""COMPUTED_VALUE"""),2685.0) -> 2685 | E19: =IFERROR(__xludf.DUMMYFUNCTION("""COMPUTED_VALUE"""),4199.0) -> 4199 | F19: =IFERROR(__xludf.DUMMYFUNCTION("""COMPUTED_VALUE"""),1851.0) -> 1851 | G19: =IFERROR(__xludf.DUMMYFUNCTION("""COMPUTED_VALUE"""),2616.0) -> 2616
A20: =IFERROR(__xludf.DUMMYFUNCTION("""COMPUTED_VALUE"""),"Breakfast/Lunch") -> Breakfast/Lunch | B20: =IFERROR(__xludf.DUMMYFUNCTION("""COMPUTED_VALUE"""),"BF") -> BF | C20: =IFERROR(__xludf.DUMMYFUNCTION("""COMPUTED_VALUE"""),0.0) -> 0 | D20: =IFERROR(__xludf.DUMMYFUNCTION("""COMPUTED_VALUE"""),919.0) -> 919 | E20: =IFERROR(__xludf.DUMMYFUNCTION("""COMPUTED_VALUE"""),0.0) -> 0 | F20: =IFERROR(__xludf.DUMMYFUNCTION("""COMPUTED_VALUE"""),1675.0) -> 1675 | G20: =IFERROR(__xludf.DUMMYFUNCTION("""COMPUTED_VALUE"""),2141.0) -> 2141
A21: =IFERROR(__xludf.DUMMYFUNCTION("""COMPUTED_VALUE"""),"† S24: Dining Hall not collected — all S24 values are 0. Rows with < 50 lbs total pruned.") -> † S24: Dining Hall not collected — all S24 values are 0. Rows with < 50 lbs total pruned.
A23: =IFERROR(__xludf.DUMMYFUNCTION("""COMPUTED_VALUE"""),"T10 · Weekly lbs within Semester → multi-line overlay chart") -> T10 · Weekly lbs within Semester → multi-line overlay chart
A24: =IFERROR(__xludf.DUMMYFUNCTION("""COMPUTED_VALUE"""),"Week") -> Week | B24: =IFERROR(__xludf.DUMMYFUNCTION("""COMPUTED_VALUE"""),"Average") -> Average | C24: =IFERROR(__xludf.DUMMYFUNCTION("""COMPUTED_VALUE"""),"S24") -> S24 | D24: =IFERROR(__xludf.DUMMYFUNCTION("""COMPUTED_VALUE"""),"S24 date") -> S24 date | E24: =IFERROR(__xludf.DUMMYFUNCTION("""COMPUTED_VALUE"""),"S24 notes") -> S24 notes | F24: =IFERROR(__xludf.DUMMYFUNCTION("""COMPUTED_VALUE"""),"F24") -> F24 | G24: =IFERROR(__xludf.DUMMYFUNCTION("""COMPUTED_VALUE"""),"F24 date") -> F24 date | H24: =IFERROR(__xludf.DUMMYFUNCTION("""COMPUTED_VALUE"""),"F24 notes") -> F24 notes | I24: =IFERROR(__xludf.DUMMYFUNCTION("""COMPUTED_VALUE"""),"S25") -> S25 | J24: =IFERROR(__xludf.DUMMYFUNCTION("""COMPUTED_VALUE"""),"S25 date") -> S25 date | K24: =IFERROR(__xludf.DUMMYFUNCTION("""COMPUTED_VALUE"""),"S25 notes") -> S25 notes | L24: =IFERROR(__xludf.DUMMYFUNCTION("""COMPUTED_VALUE"""),"F25") -> F25 | M24: =IFERROR(__xludf.DUMMYFUNCTION("""COMPUTED_VALUE"""),"F25 date") -> F25 date | N24: =IFERROR(__xludf.DUMMYFUNCTION("""COMPUTED_VALUE"""),"F25 notes") -> F25 notes | O24: =IFERROR(__xludf.DUMMYFUNCTION("""COMPUTED_VALUE"""),"S26*") -> S26* | P24: =IFERROR(__xludf.DUMMYFUNCTION("""COMPUTED_VALUE"""),"S26* date") -> S26* date | Q24: =IFERROR(__xludf.DUMMYFUNCTION("""COMPUTED_VALUE"""),"S26* notes") -> S26* notes
A25: =IFERROR(__xludf.DUMMYFUNCTION("""COMPUTED_VALUE"""),1.0) -> 1 | B25: =IFERROR(__xludf.DUMMYFUNCTION("""COMPUTED_VALUE"""),1201.6666666666667) -> 1201.6667 | C25: =IFERROR(__xludf.DUMMYFUNCTION("""COMPUTED_VALUE"""),"") | D25: =IFERROR(__xludf.DUMMYFUNCTION("""COMPUTED_VALUE"""),"S24 · Jan 22, 2024") -> S24 · Jan 22, 2024 | F25: =IFERROR(__xludf.DUMMYFUNCTION("""COMPUTED_VALUE"""),1079.0) -> 1079 | G25: =IFERROR(__xludf.DUMMYFUNCTION("""COMPUTED_VALUE"""),"F24 · Sep 9, 2024") -> F24 · Sep 9, 2024 | I25: =IFERROR(__xludf.DUMMYFUNCTION("""COMPUTED_VALUE"""),"") | J25: =IFERROR(__xludf.DUMMYFUNCTION("""COMPUTED_VALUE"""),"S25 · Jan 20, 2025") -> S25 · Jan 20, 2025 | L25: =IFERROR(__xludf.DUMMYFUNCTION("""COMPUTED_VALUE"""),2036.0) -> 2036 | M25: =IFERROR(__xludf.DUMMYFUNCTION("""COMPUTED_VALUE"""),"F25 · Sep 8, 2025") -> F25 · Sep 8, 2025 | O25: =IFERROR(__xludf.DUMMYFUNCTION("""COMPUTED_VALUE"""),490.0) -> 490 | P25: =IFERROR(__xludf.DUMMYFUNCTION("""COMPUTED_VALUE"""),"S26* · Jan 19, 2026") -> S26* · Jan 19, 2026
A26: =IFERROR(__xludf.DUMMYFUNCTION("""COMPUTED_VALUE"""),2.0) -> 2 | B26: =IFERROR(__xludf.DUMMYFUNCTION("""COMPUTED_VALUE"""),1950.25) -> 1950.25 | C26: =IFERROR(__xludf.DUMMYFUNCTION("""COMPUTED_VALUE"""),"") | D26: =IFERROR(__xludf.DUMMYFUNCTION("""COMPUTED_VALUE"""),"S24 · Jan 29, 2024") -> S24 · Jan 29, 2024 | F26: =IFERROR(__xludf.DUMMYFUNCTION("""COMPUTED_VALUE"""),1634.0) -> 1634 | G26: =IFERROR(__xludf.DUMMYFUNCTION("""COMPUTED_VALUE"""),"F24 · Sep 16, 2024") -> F24 · Sep 16, 2024 | I26: =IFERROR(__xludf.DUMMYFUNCTION("""COMPUTED_VALUE"""),2292.0) -> 2292 | J26: =IFERROR(__xludf.DUMMYFUNCTION("""COMPUTED_VALUE"""),"S25 · Jan 27, 2025") -> S25 · Jan 27, 2025 | L26: =IFERROR(__xludf.DUMMYFUNCTION("""COMPUTED_VALUE"""),2521.0) -> 2521 | M26: =IFERROR(__xludf.DUMMYFUNCTION("""COMPUTED_VALUE"""),"F25 · Sep 15, 2025") -> F25 · Sep 15, 2025 | O26: =IFERROR(__xludf.DUMMYFUNCTION("""COMPUTED_VALUE"""),1354.0) -> 1354 | P26: =IFERROR(__xludf.DUMMYFUNCTION("""COMPUTED_VALUE"""),"S26* · Jan 26, 2026") -> S26* · Jan 26, 2026
A27: =IFERROR(__xludf.DUMMYFUNCTION("""COMPUTED_VALUE"""),3.0) -> 3 | B27: =IFERROR(__xludf.DUMMYFUNCTION("""COMPUTED_VALUE"""),2583.5) -> 2583.5 | C27: =IFERROR(__xludf.DUMMYFUNCTION("""COMPUTED_VALUE"""),"") | D27: =IFERROR(__xludf.DUMMYFUNCTION("""COMPUTED_VALUE"""),"S24 · Feb 5, 2024") -> S24 · Feb 5, 2024 | F27: =IFERROR(__xludf.DUMMYFUNCTION("""COMPUTED_VALUE"""),1502.0) -> 1502 | G27: =IFERROR(__xludf.DUMMYFUNCTION("""COMPUTED_VALUE"""),"F24 · Sep 23, 2024") -> F24 · Sep 23, 2024 | I27: =IFERROR(__xludf.DUMMYFUNCTION("""COMPUTED_VALUE"""),2581.0) -> 2581 | J27: =IFERROR(__xludf.DUMMYFUNCTION("""COMPUTED_VALUE"""),"S25 · Feb 3, 2025") -> S25 · Feb 3, 2025 | L27: =IFERROR(__xludf.DUMMYFUNCTION("""COMPUTED_VALUE"""),2807.0) -> 2807 | M27: =IFERROR(__xludf.DUMMYFUNCTION("""COMPUTED_VALUE"""),"F25 · Sep 22, 2025") -> F25 · Sep 22, 2025 | O27: =IFERROR(__xludf.DUMMYFUNCTION("""COMPUTED_VALUE"""),3444.0) -> 3444 | P27: =IFERROR(__xludf.DUMMYFUNCTION("""COMPUTED_VALUE"""),"S26* · Feb 2, 2026") -> S26* · Feb 2, 2026
A28: =IFERROR(__xludf.DUMMYFUNCTION("""COMPUTED_VALUE"""),4.0) -> 4 | B28: =IFERROR(__xludf.DUMMYFUNCTION("""COMPUTED_VALUE"""),2654.0) -> 2654 | C28: =IFERROR(__xludf.DUMMYFUNCTION("""COMPUTED_VALUE"""),"") | D28: =IFERROR(__xludf.DUMMYFUNCTION("""COMPUTED_VALUE"""),"S24 · Feb 12, 2024") -> S24 · Feb 12, 2024 | F28: =IFERROR(__xludf.DUMMYFUNCTION("""COMPUTED_VALUE"""),2521.0) -> 2521 | G28: =IFERROR(__xludf.DUMMYFUNCTION("""COMPUTED_VALUE"""),"F24 · Sep 30, 2024") -> F24 · Sep 30, 2024 | I28: =IFERROR(__xludf.DUMMYFUNCTION("""COMPUTED_VALUE"""),2857.0) -> 2857 | J28: =IFERROR(__xludf.DUMMYFUNCTION("""COMPUTED_VALUE"""),"S25 · Feb 10, 2025") -> S25 · Feb 10, 2025 | L28: =IFERROR(__xludf.DUMMYFUNCTION("""COMPUTED_VALUE"""),2637.0) -> 2637 | M28: =IFERROR(__xludf.DUMMYFUNCTION("""COMPUTED_VALUE"""),"F25 · Sep 29, 2025") -> F25 · Sep 29, 2025 | O28: =IFERROR(__xludf.DUMMYFUNCTION("""COMPUTED_VALUE"""),2601.0) -> 2601 | P28: =IFERROR(__xludf.DUMMYFUNCTION("""COMPUTED_VALUE"""),"S26* · Feb 9, 2026") -> S26* · Feb 9, 2026
A29: =IFERROR(__xludf.DUMMYFUNCTION("""COMPUTED_VALUE"""),5.0) -> 5 | B29: =IFERROR(__xludf.DUMMYFUNCTION("""COMPUTED_VALUE"""),2372.0) -> 2372 | C29: =IFERROR(__xludf.DUMMYFUNCTION("""COMPUTED_VALUE"""),"") | D29: =IFERROR(__xludf.DUMMYFUNCTION("""COMPUTED_VALUE"""),"S24 · Feb 19, 2024") -> S24 · Feb 19, 2024 | F29: =IFERROR(__xludf.DUMMYFUNCTION("""COMPUTED_VALUE"""),2246.0) -> 2246 | G29: =IFERROR(__xludf.DUMMYFUNCTION("""COMPUTED_VALUE"""),"F24 · Oct 7, 2024") -> F24 · Oct 7, 2024 | I29: =IFERROR(__xludf.DUMMYFUNCTION("""COMPUTED_VALUE"""),2372.0) -> 2372 | J29: =IFERROR(__xludf.DUMMYFUNCTION("""COMPUTED_VALUE"""),"S25 · Feb 17, 2025") -> S25 · Feb 17, 2025 | L29: =IFERROR(__xludf.DUMMYFUNCTION("""COMPUTED_VALUE"""),2198.0) -> 2198 | M29: =IFERROR(__xludf.DUMMYFUNCTION("""COMPUTED_VALUE"""),"F25 · Oct 6, 2025") -> F25 · Oct 6, 2025 | O29: =IFERROR(__xludf.DUMMYFUNCTION("""COMPUTED_VALUE"""),2672.0) -> 2672 | P29: =IFERROR(__xludf.DUMMYFUNCTION("""COMPUTED_VALUE"""),"S26* · Feb 16, 2026") -> S26* · Feb 16, 2026
A30: =IFERROR(__xludf.DUMMYFUNCTION("""COMPUTED_VALUE"""),6.0) -> 6 | B30: =IFERROR(__xludf.DUMMYFUNCTION("""COMPUTED_VALUE"""),1751.0) -> 1751 | C30: =IFERROR(__xludf.DUMMYFUNCTION("""COMPUTED_VALUE"""),"") | D30: =IFERROR(__xludf.DUMMYFUNCTION("""COMPUTED_VALUE"""),"S24 · Feb 26, 2024") -> S24 · Feb 26, 2024 | F30: =IFERROR(__xludf.DUMMYFUNCTION("""COMPUTED_VALUE"""),1921.0) -> 1921 | G30: =IFERROR(__xludf.DUMMYFUNCTION("""COMPUTED_VALUE"""),"F24 · Oct 14, 2024") -> F24 · Oct 14, 2024 | H30: =IFERROR(__xludf.DUMMYFUNCTION("""COMPUTED_VALUE"""),"Columbus Day") -> Columbus Day | I30: =IFERROR(__xludf.DUMMYFUNCTION("""COMPUTED_VALUE"""),2607.0) -> 2607 | J30: =IFERROR(__xludf.DUMMYFUNCTION("""COMPUTED_VALUE"""),"S25 · Feb 24, 2025") -> S25 · Feb 24, 2025 | L30: =IFERROR(__xludf.DUMMYFUNCTION("""COMPUTED_VALUE"""),1860.0) -> 1860 | M30: =IFERROR(__xludf.DUMMYFUNCTION("""COMPUTED_VALUE"""),"F25 · Oct 13, 2025") -> F25 · Oct 13, 2025 | N30: =IFERROR(__xludf.DUMMYFUNCTION("""COMPUTED_VALUE"""),"Columbus Day") -> Columbus Day | O30: =IFERROR(__xludf.DUMMYFUNCTION("""COMPUTED_VALUE"""),616.0) -> 616 | P30: =IFERROR(__xludf.DUMMYFUNCTION("""COMPUTED_VALUE"""),"S26* · Feb 23, 2026") -> S26* · Feb 23, 2026 | Q30: =IFERROR(__xludf.DUMMYFUNCTION("""COMPUTED_VALUE"""),"3 snow days") -> 3 snow days
A31: =IFERROR(__xludf.DUMMYFUNCTION("""COMPUTED_VALUE"""),7.0) -> 7 | B31: =IFERROR(__xludf.DUMMYFUNCTION("""COMPUTED_VALUE"""),2558.75) -> 2558.75 | C31: =IFERROR(__xludf.DUMMYFUNCTION("""COMPUTED_VALUE"""),"") | D31: =IFERROR(__xludf.DUMMYFUNCTION("""COMPUTED_VALUE"""),"S24 · Mar 4, 2024") -> S24 · Mar 4, 2024 | F31: =IFERROR(__xludf.DUMMYFUNCTION("""COMPUTED_VALUE"""),2697.0) -> 2697 | G31: =IFERROR(__xludf.DUMMYFUNCTION("""COMPUTED_VALUE"""),"F24 · Oct 21, 2024") -> F24 · Oct 21, 2024 | I31: =IFERROR(__xludf.DUMMYFUNCTION("""COMPUTED_VALUE"""),2059.0) -> 2059 | J31: =IFERROR(__xludf.DUMMYFUNCTION("""COMPUTED_VALUE"""),"S25 · Mar 3, 2025") -> S25 · Mar 3, 2025 | L31: =IFERROR(__xludf.DUMMYFUNCTION("""COMPUTED_VALUE"""),2852.0) -> 2852 | M31: =IFERROR(__xludf.DUMMYFUNCTION("""COMPUTED_VALUE"""),"F25 · Oct 20, 2025") -> F25 · Oct 20, 2025 | O31: =IFERROR(__xludf.DUMMYFUNCTION("""COMPUTED_VALUE"""),2627.0) -> 2627 | P31: =IFERROR(__xludf.DUMMYFUNCTION("""COMPUTED_VALUE"""),"S26* · Mar 2, 2026") -> S26* · Mar 2, 2026
A32: =IFERROR(__xludf.DUMMYFUNCTION("""COMPUTED_VALUE"""),8.0) -> 8 | B32: =IFERROR(__xludf.DUMMYFUNCTION("""COMPUTED_VALUE"""),2717.0) -> 2717 | C32: =IFERROR(__xludf.DUMMYFUNCTION("""COMPUTED_VALUE"""),"") | D32: =IFERROR(__xludf.DUMMYFUNCTION("""COMPUTED_VALUE"""),"S24 · Mar 11, 2024") -> S24 · Mar 11, 2024 | F32: =IFERROR(__xludf.DUMMYFUNCTION("""COMPUTED_VALUE"""),2343.0) -> 2343 | G32: =IFERROR(__xludf.DUMMYFUNCTION("""COMPUTED_VALUE"""),"F24 · Oct 28, 2024") -> F24 · Oct 28, 2024 | I32: =IFERROR(__xludf.DUMMYFUNCTION("""COMPUTED_VALUE"""),"") | J32: =IFERROR(__xludf.DUMMYFUNCTION("""COMPUTED_VALUE"""),"S25 · Mar 10, 2025") -> S25 · Mar 10, 2025 | K32: =IFERROR(__xludf.DUMMYFUNCTION("""COMPUTED_VALUE"""),"spring break") -> spring break | L32: =IFERROR(__xludf.DUMMYFUNCTION("""COMPUTED_VALUE"""),3078.0) -> 3078 | M32: =IFERROR(__xludf.DUMMYFUNCTION("""COMPUTED_VALUE"""),"F25 · Oct 27, 2025") -> F25 · Oct 27, 2025 | O32: =IFERROR(__xludf.DUMMYFUNCTION("""COMPUTED_VALUE"""),2730.0) -> 2730 | P32: =IFERROR(__xludf.DUMMYFUNCTION("""COMPUTED_VALUE"""),"S26* · Mar 9, 2026") -> S26* · Mar 9, 2026
A33: =IFERROR(__xludf.DUMMYFUNCTION("""COMPUTED_VALUE"""),9.0) -> 9 | B33: =IFERROR(__xludf.DUMMYFUNCTION("""COMPUTED_VALUE"""),2023.115) -> 2023.115 | C33: =IFERROR(__xludf.DUMMYFUNCTION("""COMPUTED_VALUE"""),744.46) -> 744.46 | D33: =IFERROR(__xludf.DUMMYFUNCTION("""COMPUTED_VALUE"""),"S24 · Mar 18, 2024") -> S24 · Mar 18, 2024 | F33: =IFERROR(__xludf.DUMMYFUNCTION("""COMPUTED_VALUE"""),2007.0) -> 2007 | G33: =IFERROR(__xludf.DUMMYFUNCTION("""COMPUTED_VALUE"""),"F24 · Oct 29, 2024") -> F24 · Oct 29, 2024 | I33: =IFERROR(__xludf.DUMMYFUNCTION("""COMPUTED_VALUE"""),2401.0) -> 2401 | J33: =IFERROR(__xludf.DUMMYFUNCTION("""COMPUTED_VALUE"""),"S25 · Mar 17, 2025") -> S25 · Mar 17, 2025 | L33: =IFERROR(__xludf.DUMMYFUNCTION("""COMPUTED_VALUE"""),2940.0) -> 2940 | M33: =IFERROR(__xludf.DUMMYFUNCTION("""COMPUTED_VALUE"""),"F25 · Oct 28, 2025") -> F25 · Oct 28, 2025 | O33: =IFERROR(__xludf.DUMMYFUNCTION("""COMPUTED_VALUE"""),"") | P33: =IFERROR(__xludf.DUMMYFUNCTION("""COMPUTED_VALUE"""),"S26* · Mar 16, 2026") -> S26* · Mar 16, 2026 | Q33: =IFERROR(__xludf.DUMMYFUNCTION("""COMPUTED_VALUE"""),"spring break") -> spring break
A34: =IFERROR(__xludf.DUMMYFUNCTION("""COMPUTED_VALUE"""),10.0) -> 10 | B34: =IFERROR(__xludf.DUMMYFUNCTION("""COMPUTED_VALUE"""),2111.02) -> 2111.02 | C34: =IFERROR(__xludf.DUMMYFUNCTION("""COMPUTED_VALUE"""),1473.1) -> 1473.1 | D34: =IFERROR(__xludf.DUMMYFUNCTION("""COMPUTED_VALUE"""),"S24 · Mar 25, 2024") -> S24 · Mar 25, 2024 | F34: =IFERROR(__xludf.DUMMYFUNCTION("""COMPUTED_VALUE"""),1977.0) -> 1977 | G34: =IFERROR(__xludf.DUMMYFUNCTION("""COMPUTED_VALUE"""),"F24 · Nov 4, 2024") -> F24 · Nov 4, 2024 | I34: =IFERROR(__xludf.DUMMYFUNCTION("""COMPUTED_VALUE"""),2181.0) -> 2181 | J34: =IFERROR(__xludf.DUMMYFUNCTION("""COMPUTED_VALUE"""),"S25 · Mar 24, 2025") -> S25 · Mar 24, 2025 | L34: =IFERROR(__xludf.DUMMYFUNCTION("""COMPUTED_VALUE"""),2468.0) -> 2468 | M34: =IFERROR(__xludf.DUMMYFUNCTION("""COMPUTED_VALUE"""),"F25 · Nov 3, 2025") -> F25 · Nov 3, 2025 | O34: =IFERROR(__xludf.DUMMYFUNCTION("""COMPUTED_VALUE"""),2456.0) -> 2456 | P34: =IFERROR(__xludf.DUMMYFUNCTION("""COMPUTED_VALUE"""),"S26* · Mar 23, 2026") -> S26* · Mar 23, 2026
A35: =IFERROR(__xludf.DUMMYFUNCTION("""COMPUTED_VALUE"""),11.0) -> 11 | B35: =IFERROR(__xludf.DUMMYFUNCTION("""COMPUTED_VALUE"""),2227.6) -> 2227.6 | C35: =IFERROR(__xludf.DUMMYFUNCTION("""COMPUTED_VALUE"""),877.0) -> 877 | D35: =IFERROR(__xludf.DUMMYFUNCTION("""COMPUTED_VALUE"""),"S24 · Apr 1, 2024") -> S24 · Apr 1, 2024 | F35: =IFERROR(__xludf.DUMMYFUNCTION("""COMPUTED_VALUE"""),2065.0) -> 2065 | G35: =IFERROR(__xludf.DUMMYFUNCTION("""COMPUTED_VALUE"""),"F24 · Nov 11, 2024") -> F24 · Nov 11, 2024 | I35: =IFERROR(__xludf.DUMMYFUNCTION("""COMPUTED_VALUE"""),2134.0) -> 2134 | J35: =IFERROR(__xludf.DUMMYFUNCTION("""COMPUTED_VALUE"""),"S25 · Mar 31, 2025") -> S25 · Mar 31, 2025 | L35: =IFERROR(__xludf.DUMMYFUNCTION("""COMPUTED_VALUE"""),3196.0) -> 3196 | M35: =IFERROR(__xludf.DUMMYFUNCTION("""COMPUTED_VALUE"""),"F25 · Nov 10, 2025") -> F25 · Nov 10, 2025 | O35: =IFERROR(__xludf.DUMMYFUNCTION("""COMPUTED_VALUE"""),2866.0) -> 2866 | P35: =IFERROR(__xludf.DUMMYFUNCTION("""COMPUTED_VALUE"""),"S26* · Mar 30, 2026") -> S26* · Mar 30, 2026
A36: =IFERROR(__xludf.DUMMYFUNCTION("""COMPUTED_VALUE"""),12.0) -> 12 | B36: =IFERROR(__xludf.DUMMYFUNCTION("""COMPUTED_VALUE"""),1567.8799999999999) -> 1567.88 | C36: =IFERROR(__xludf.DUMMYFUNCTION("""COMPUTED_VALUE"""),1328.4) -> 1328.4 | D36: =IFERROR(__xludf.DUMMYFUNCTION("""COMPUTED_VALUE"""),"S24 · Apr 8, 2024") -> S24 · Apr 8, 2024 | F36: =IFERROR(__xludf.DUMMYFUNCTION("""COMPUTED_VALUE"""),322.0) -> 322 | G36: =IFERROR(__xludf.DUMMYFUNCTION("""COMPUTED_VALUE"""),"F24 · Nov 18, 2024") -> F24 · Nov 18, 2024 | H36: =IFERROR(__xludf.DUMMYFUNCTION("""COMPUTED_VALUE"""),"Thanksgiving") -> Thanksgiving | I36: =IFERROR(__xludf.DUMMYFUNCTION("""COMPUTED_VALUE"""),2389.0) -> 2389 | J36: =IFERROR(__xludf.DUMMYFUNCTION("""COMPUTED_VALUE"""),"S25 · Apr 7, 2025") -> S25 · Apr 7, 2025 | L36: =IFERROR(__xludf.DUMMYFUNCTION("""COMPUTED_VALUE"""),674.0) -> 674 | M36: =IFERROR(__xludf.DUMMYFUNCTION("""COMPUTED_VALUE"""),"F25 · Nov 17, 2025") -> F25 · Nov 17, 2025 | N36: =IFERROR(__xludf.DUMMYFUNCTION("""COMPUTED_VALUE"""),"Thanksgiving") -> Thanksgiving | O36: =IFERROR(__xludf.DUMMYFUNCTION("""COMPUTED_VALUE"""),3126.0) -> 3126 | P36: =IFERROR(__xludf.DUMMYFUNCTION("""COMPUTED_VALUE"""),"S26* · Apr 6, 2026") -> S26* · Apr 6, 2026
A37: =IFERROR(__xludf.DUMMYFUNCTION("""COMPUTED_VALUE"""),13.0) -> 13 | B37: =IFERROR(__xludf.DUMMYFUNCTION("""COMPUTED_VALUE"""),2323.58) -> 2323.58 | C37: =IFERROR(__xludf.DUMMYFUNCTION("""COMPUTED_VALUE"""),1418.9) -> 1418.9 | D37: =IFERROR(__xludf.DUMMYFUNCTION("""COMPUTED_VALUE"""),"S24 · Apr 15, 2024") -> S24 · Apr 15, 2024 | F37: =IFERROR(__xludf.DUMMYFUNCTION("""COMPUTED_VALUE"""),2408.0) -> 2408 | G37: =IFERROR(__xludf.DUMMYFUNCTION("""COMPUTED_VALUE"""),"F24 · Nov 25, 2024") -> F24 · Nov 25, 2024 | I37: =IFERROR(__xludf.DUMMYFUNCTION("""COMPUTED_VALUE"""),2647.0) -> 2647 | J37: =IFERROR(__xludf.DUMMYFUNCTION("""COMPUTED_VALUE"""),"S25 · Apr 14, 2025") -> S25 · Apr 14, 2025 | L37: =IFERROR(__xludf.DUMMYFUNCTION("""COMPUTED_VALUE"""),2701.0) -> 2701 | M37: =IFERROR(__xludf.DUMMYFUNCTION("""COMPUTED_VALUE"""),"F25 · Nov 24, 2025") -> F25 · Nov 24, 2025 | O37: =IFERROR(__xludf.DUMMYFUNCTION("""COMPUTED_VALUE"""),2443.0) -> 2443 | P37: =IFERROR(__xludf.DUMMYFUNCTION("""COMPUTED_VALUE"""),"S26* · Apr 13, 2026") -> S26* · Apr 13, 2026
A38: =IFERROR(__xludf.DUMMYFUNCTION("""COMPUTED_VALUE"""),14.0) -> 14 | B38: =IFERROR(__xludf.DUMMYFUNCTION("""COMPUTED_VALUE"""),1599.4) -> 1599.4 | C38: =IFERROR(__xludf.DUMMYFUNCTION("""COMPUTED_VALUE"""),1116.0) -> 1116 | D38: =IFERROR(__xludf.DUMMYFUNCTION("""COMPUTED_VALUE"""),"S24 · Apr 22, 2024") -> S24 · Apr 22, 2024 | F38: =IFERROR(__xludf.DUMMYFUNCTION("""COMPUTED_VALUE"""),1577.0) -> 1577 | G38: =IFERROR(__xludf.DUMMYFUNCTION("""COMPUTED_VALUE"""),"F24 · Dec 2, 2024") -> F24 · Dec 2, 2024 | I38: =IFERROR(__xludf.DUMMYFUNCTION("""COMPUTED_VALUE"""),2700.0) -> 2700 | J38: =IFERROR(__xludf.DUMMYFUNCTION("""COMPUTED_VALUE"""),"S25 · Apr 21, 2025") -> S25 · Apr 21, 2025 | L38: =IFERROR(__xludf.DUMMYFUNCTION("""COMPUTED_VALUE"""),1469.0) -> 1469 | M38: =IFERROR(__xludf.DUMMYFUNCTION("""COMPUTED_VALUE"""),"F25 · Dec 1, 2025") -> F25 · Dec 1, 2025 | O38: =IFERROR(__xludf.DUMMYFUNCTION("""COMPUTED_VALUE"""),1135.0) -> 1135 | P38: =IFERROR(__xludf.DUMMYFUNCTION("""COMPUTED_VALUE"""),"S26* · Apr 20, 2026") -> S26* · Apr 20, 2026
A39: =IFERROR(__xludf.DUMMYFUNCTION("""COMPUTED_VALUE"""),"† Tooltip date cols (italic headers) show the actual calendar date per semester per week. In chart editor: select each ""[sem] date"" column → Column role → Tooltip.") -> † Tooltip date cols (italic headers) show the actual calendar date per semester per week. In chart editor: select each "[sem] date" column → Column role → Tooltip.
A41: =IFERROR(__xludf.DUMMYFUNCTION("""COMPUTED_VALUE"""),"T11 · Program Progress → color-coded scatter by semester") -> T11 · Program Progress → color-coded scatter by semester
B42: =IFERROR(__xludf.DUMMYFUNCTION("""COMPUTED_VALUE"""),"lifetime lbs ──▶") -> lifetime lbs ──▶ | G42: =IFERROR(__xludf.DUMMYFUNCTION("""COMPUTED_VALUE"""),"lbs this week ──▶") -> lbs this week ──▶
A43: =IFERROR(__xludf.DUMMYFUNCTION("""COMPUTED_VALUE"""),"Week") -> Week | B43: =IFERROR(__xludf.DUMMYFUNCTION("""COMPUTED_VALUE"""),"S24") -> S24 | C43: =IFERROR(__xludf.DUMMYFUNCTION("""COMPUTED_VALUE"""),"F24") -> F24 | D43: =IFERROR(__xludf.DUMMYFUNCTION("""COMPUTED_VALUE"""),"S25") -> S25 | E43: =IFERROR(__xludf.DUMMYFUNCTION("""COMPUTED_VALUE"""),"F25") -> F25 | F43: =IFERROR(__xludf.DUMMYFUNCTION("""COMPUTED_VALUE"""),"S26*") -> S26* | G43: =IFERROR(__xludf.DUMMYFUNCTION("""COMPUTED_VALUE"""),"S24") -> S24 | H43: =IFERROR(__xludf.DUMMYFUNCTION("""COMPUTED_VALUE"""),"F24") -> F24 | I43: =IFERROR(__xludf.DUMMYFUNCTION("""COMPUTED_VALUE"""),"S25") -> S25 | J43: =IFERROR(__xludf.DUMMYFUNCTION("""COMPUTED_VALUE"""),"F25") -> F25 | K43: =IFERROR(__xludf.DUMMYFUNCTION("""COMPUTED_VALUE"""),"S26*") -> S26*
A44: =IFERROR(__xludf.DUMMYFUNCTION("""COMPUTED_VALUE"""),45313.0) -> 45313 | B44: =IFERROR(__xludf.DUMMYFUNCTION("""COMPUTED_VALUE"""),"") | G44: =IFERROR(__xludf.DUMMYFUNCTION("""COMPUTED_VALUE"""),"")
...

Sheet YoY Chart Data
A1: T1 · Semester Totals + Cumulative lbs → bar + line chart | E1: T2 · Mainfare vs. Butterfield lbs → grouped bar chart | I1: T3 · CO₂e Avoided → bar / area chart | N1: T4 · Team Size vs. Output → dual-axis | Per-Ambassador table
A2: Semester | B2: Total lbs | C2: Cumulative lbs | E2: Semester | F2: Mainfare lbs | G2: Butterfield lbs | I2: Semester | J2: CO₂e (lbs) | K2: CO₂e (tons) | L2: Miles Not Driven ‡ | N2: Semester | O2: # Ambassadors | P2: Total lbs | Q2: lbs / Ambassador
A3: S24 | B3: {=IF('Master of Masters'!K3="","",IFERROR(IF(ISNUMBER(INDIRECT("'"&'Master of Masters'!K3&"'!I6",TRUE)),INDIRECT("'"&'Master of Masters'!K3&"'!I6",TRUE),"N/A"),"N/A"))} -> 7110.86 | C3: =IF(B3="","",SUMPRODUCT((ISNUMBER(B$3:B3))*IF(ISNUMBER(B$3:B3),B$3:B3,0))) -> 7110.86 | E3: =IF(A3="","",A3) -> S24 | F3: {=IF('Master of Masters'!K3="","",IFERROR(IF(ISNUMBER(INDIRECT("'"&'Master of Masters'!K3&"'!C6",TRUE)),INDIRECT("'"&'Master of Masters'!K3&"'!C6",TRUE),"N/A"),"N/A"))} -> N/A | G3: {=IF('Master of Masters'!K3="","",IFERROR(IF(ISNUMBER(INDIRECT("'"&'Master of Masters'!K3&"'!F6",TRUE)),INDIRECT("'"&'Master of Masters'!K3&"'!F6",TRUE),"N/A"),"N/A"))} -> N/A | I3: =IF(A3="","",A3) -> S24 | J3: {=IF('Master of Masters'!K3="","",IFERROR(IF(ISNUMBER(INDIRECT("'"&'Master of Masters'!K3&"'!I12",TRUE)),INDIRECT("'"&'Master of Masters'!K3&"'!I12",TRUE),"N/A"),"N/A"))} -> 4519.1649 | K3: =IF(J3="","",IF(NOT(ISNUMBER(J3)),"N/A",ROUND(J3/2000,2))) -> 2.26 | L3: =IF(J3="","",IF(NOT(ISNUMBER(J3)),"N/A",ROUND(J3/0.891,0))) -> 5072 | N3: =IF(A3="","",A3) -> S24 | O3: {=IF('Master of Masters'!K3="","",IFERROR(IF(ISNUMBER(INDIRECT("'"&'Master of Masters'!K3&"'!A4",TRUE)),INDIRECT("'"&'Master of Masters'!K3&"'!A4",TRUE),"N/A"),"N/A"))} -> 8 | P3: =IF(B3="","",B3) -> 7110.86 | Q3: =IF(OR(O3="",P3="",NOT(ISNUMBER(O3)),NOT(ISNUMBER(P3))),"",ROUND(P3/O3,0)) -> 889
A4: F24 | B4: {=IF('Master of Masters'!K4="","",IFERROR(IF(ISNUMBER(INDIRECT("'"&'Master of Masters'!K4&"'!I6",TRUE)),INDIRECT("'"&'Master of Masters'!K4&"'!I6",TRUE),"N/A"),"N/A"))} -> 26386 | C4: =IF(B4="","",SUMPRODUCT((ISNUMBER(B$3:B4))*IF(ISNUMBER(B$3:B4),B$3:B4,0))) -> 33496.86 | E4: =IF(A4="","",A4) -> F24 | F4: {=IF('Master of Masters'!K4="","",IFERROR(IF(ISNUMBER(INDIRECT("'"&'Master of Masters'!K4&"'!C6",TRUE)),INDIRECT("'"&'Master of Masters'!K4&"'!C6",TRUE),"N/A"),"N/A"))} -> 11781 | G4: {=IF('Master of Masters'!K4="","",IFERROR(IF(ISNUMBER(INDIRECT("'"&'Master of Masters'!K4&"'!F6",TRUE)),INDIRECT("'"&'Master of Masters'!K4&"'!F6",TRUE),"N/A"),"N/A"))} -> 14605 | I4: =IF(A4="","",A4) -> F24 | J4: {=IF('Master of Masters'!K4="","",IFERROR(IF(ISNUMBER(INDIRECT("'"&'Master of Masters'!K4&"'!I12",TRUE)),INDIRECT("'"&'Master of Masters'!K4&"'!I12",TRUE),"N/A"),"N/A"))} -> 16769.095 | K4: =IF(J4="","",IF(NOT(ISNUMBER(J4)),"N/A",ROUND(J4/2000,2))) -> 8.38 | L4: =IF(J4="","",IF(NOT(ISNUMBER(J4)),"N/A",ROUND(J4/0.891,0))) -> 18821 | N4: =IF(A4="","",A4) -> F24 | O4: {=IF('Master of Masters'!K4="","",IFERROR(IF(ISNUMBER(INDIRECT("'"&'Master of Masters'!K4&"'!A4",TRUE)),INDIRECT("'"&'Master of Masters'!K4&"'!A4",TRUE),"N/A"),"N/A"))} -> 10 | P4: =IF(B4="","",B4) -> 26386 | Q4: =IF(OR(O4="",P4="",NOT(ISNUMBER(O4)),NOT(ISNUMBER(P4))),"",ROUND(P4/O4,0)) -> 2639
A5: S25 | B5: {=IF('Master of Masters'!K5="","",IFERROR(IF(ISNUMBER(INDIRECT("'"&'Master of Masters'!K5&"'!I6",TRUE)),INDIRECT("'"&'Master of Masters'!K5&"'!I6",TRUE),"N/A"),"N/A"))} -> 31073 | C5: =IF(B5="","",SUMPRODUCT((ISNUMBER(B$3:B5))*IF(ISNUMBER(B$3:B5),B$3:B5,0))) -> 64569.86 | E5: =IF(A5="","",A5) -> S25 | F5: {=IF('Master of Masters'!K5="","",IFERROR(IF(ISNUMBER(INDIRECT("'"&'Master of Masters'!K5&"'!C6",TRUE)),INDIRECT("'"&'Master of Masters'!K5&"'!C6",TRUE),"N/A"),"N/A"))} -> 14269 | G5: {=IF('Master of Masters'!K5="","",IFERROR(IF(ISNUMBER(INDIRECT("'"&'Master of Masters'!K5&"'!F6",TRUE)),INDIRECT("'"&'Master of Masters'!K5&"'!F6",TRUE),"N/A"),"N/A"))} -> 16804 | I5: =IF(A5="","",A5) -> S25 | J5: {=IF('Master of Masters'!K5="","",IFERROR(IF(ISNUMBER(INDIRECT("'"&'Master of Masters'!K5&"'!I12",TRUE)),INDIRECT("'"&'Master of Masters'!K5&"'!I12",TRUE),"N/A"),"N/A"))} -> 19747.824 | K5: =IF(J5="","",IF(NOT(ISNUMBER(J5)),"N/A",ROUND(J5/2000,2))) -> 9.87 | L5: =IF(J5="","",IF(NOT(ISNUMBER(J5)),"N/A",ROUND(J5/0.891,0))) -> 22164 | N5: =IF(A5="","",A5) -> S25 | O5: {=IF('Master of Masters'!K5="","",IFERROR(IF(ISNUMBER(INDIRECT("'"&'Master of Masters'!K5&"'!A4",TRUE)),INDIRECT("'"&'Master of Masters'!K5&"'!A4",TRUE),"N/A"),"N/A"))} -> 13 | P5: =IF(B5="","",B5) -> 31073 | Q5: =IF(OR(O5="",P5="",NOT(ISNUMBER(O5)),NOT(ISNUMBER(P5))),"",ROUND(P5/O5,0)) -> 2390
A6: F25 | B6: {=IF('Master of Masters'!K6="","",IFERROR(IF(ISNUMBER(INDIRECT("'"&'Master of Masters'!K6&"'!I6",TRUE)),INDIRECT("'"&'Master of Masters'!K6&"'!I6",TRUE),"N/A"),"N/A"))} -> 36594 | C6: =IF(B6="","",SUMPRODUCT((ISNUMBER(B$3:B6))*IF(ISNUMBER(B$3:B6),B$3:B6,0))) -> 101163.86 | E6: =IF(A6="","",A6) -> F25 | F6: {=IF('Master of Masters'!K6="","",IFERROR(IF(ISNUMBER(INDIRECT("'"&'Master of Masters'!K6&"'!C6",TRUE)),INDIRECT("'"&'Master of Masters'!K6&"'!C6",TRUE),"N/A"),"N/A"))} -> 20069 | G6: {=IF('Master of Masters'!K6="","",IFERROR(IF(ISNUMBER(INDIRECT("'"&'Master of Masters'!K6&"'!F6",TRUE)),INDIRECT("'"&'Master of Masters'!K6&"'!F6",TRUE),"N/A"),"N/A"))} -> 16525 | I6: =IF(A6="","",A6) -> F25 | J6: {=IF('Master of Masters'!K6="","",IFERROR(IF(ISNUMBER(INDIRECT("'"&'Master of Masters'!K6&"'!I12",TRUE)),INDIRECT("'"&'Master of Masters'!K6&"'!I12",TRUE),"N/A"),"N/A"))} -> 23256.585 | K6: =IF(J6="","",IF(NOT(ISNUMBER(J6)),"N/A",ROUND(J6/2000,2))) -> 11.63 | L6: =IF(J6="","",IF(NOT(ISNUMBER(J6)),"N/A",ROUND(J6/0.891,0))) -> 26102 | N6: =IF(A6="","",A6) -> F25 | O6: {=IF('Master of Masters'!K6="","",IFERROR(IF(ISNUMBER(INDIRECT("'"&'Master of Masters'!K6&"'!A4",TRUE)),INDIRECT("'"&'Master of Masters'!K6&"'!A4",TRUE),"N/A"),"N/A"))} -> 14 | P6: =IF(B6="","",B6) -> 36594 | Q6: =IF(OR(O6="",P6="",NOT(ISNUMBER(O6)),NOT(ISNUMBER(P6))),"",ROUND(P6/O6,0)) -> 2614
A7: S26* | B7: {=IF('Master of Masters'!K7="","",IFERROR(IF(ISNUMBER(INDIRECT("'"&'Master of Masters'!K7&"'!I6",TRUE)),INDIRECT("'"&'Master of Masters'!K7&"'!I6",TRUE),"N/A"),"N/A"))} -> 34009 | C7: =IF(B7="","",SUMPRODUCT((ISNUMBER(B$3:B7))*IF(ISNUMBER(B$3:B7),B$3:B7,0))) -> 135172.86 | E7: =IF(A7="","",A7) -> S26* | F7: {=IF('Master of Masters'!K7="","",IFERROR(IF(ISNUMBER(INDIRECT("'"&'Master of Masters'!K7&"'!C6",TRUE)),INDIRECT("'"&'Master of Masters'!K7&"'!C6",TRUE),"N/A"),"N/A"))} -> 17917 | G7: {=IF('Master of Masters'!K7="","",IFERROR(IF(ISNUMBER(INDIRECT("'"&'Master of Masters'!K7&"'!F6",TRUE)),INDIRECT("'"&'Master of Masters'!K7&"'!F6",TRUE),"N/A"),"N/A"))} -> 16092 | I7: =IF(A7="","",A7) -> S26* | J7: {=IF('Master of Masters'!K7="","",IFERROR(IF(ISNUMBER(INDIRECT("'"&'Master of Masters'!K7&"'!I12",TRUE)),INDIRECT("'"&'Master of Masters'!K7&"'!I12",TRUE),"N/A"),"N/A"))} -> 21613.74 | K7: =IF(J7="","",IF(NOT(ISNUMBER(J7)),"N/A",ROUND(J7/2000,2))) -> 10.81 | L7: =IF(J7="","",IF(NOT(ISNUMBER(J7)),"N/A",ROUND(J7/0.891,0))) -> 24258 | N7: =IF(A7="","",A7) -> S26* | O7: {=IF('Master of Masters'!K7="","",IFERROR(IF(ISNUMBER(INDIRECT("'"&'Master of Masters'!K7&"'!A4",TRUE)),INDIRECT("'"&'Master of Masters'!K7&"'!A4",TRUE),"N/A"),"N/A"))} -> 14 | P7: =IF(B7="","",B7) -> 34009 | Q7: =IF(OR(O7="",P7="",NOT(ISNUMBER(O7)),NOT(ISNUMBER(P7))),"",ROUND(P7/O7,0)) -> 2429
A8: =IF('Master of Masters'!K8="","",IF(ISNUMBER(SEARCH("Spring",'Master of Masters'!K8)),"S",IF(ISNUMBER(SEARCH("Fall",'Master of Masters'!K8)),"F","?"))&RIGHT('Master of Masters'!K8,2)) | B8: {=IF('Master of Masters'!K8="","",IFERROR(IF(ISNUMBER(INDIRECT("'"&'Master of Masters'!K8&"'!I6",TRUE)),INDIRECT("'"&'Master of Masters'!K8&"'!I6",TRUE),"N/A"),"N/A"))} | C8: =IF(B8="","",SUMPRODUCT((ISNUMBER(B$3:B8))*IF(ISNUMBER(B$3:B8),B$3:B8,0))) | E8: =IF(A8="","",A8) | F8: {=IF('Master of Masters'!K8="","",IFERROR(IF(ISNUMBER(INDIRECT("'"&'Master of Masters'!K8&"'!C6",TRUE)),INDIRECT("'"&'Master of Masters'!K8&"'!C6",TRUE),"N/A"),"N/A"))} | G8: {=IF('Master of Masters'!K8="","",IFERROR(IF(ISNUMBER(INDIRECT("'"&'Master of Masters'!K8&"'!F6",TRUE)),INDIRECT("'"&'Master of Masters'!K8&"'!F6",TRUE),"N/A"),"N/A"))} | I8: =IF(A8="","",A8) | J8: {=IF('Master of Masters'!K8="","",IFERROR(IF(ISNUMBER(INDIRECT("'"&'Master of Masters'!K8&"'!I12",TRUE)),INDIRECT("'"&'Master of Masters'!K8&"'!I12",TRUE),"N/A"),"N/A"))} | K8: =IF(J8="","",IF(NOT(ISNUMBER(J8)),"N/A",ROUND(J8/2000,2))) | L8: =IF(J8="","",IF(NOT(ISNUMBER(J8)),"N/A",ROUND(J8/0.891,0))) | N8: =IF(A8="","",A8) | O8: {=IF('Master of Masters'!K8="","",IFERROR(IF(ISNUMBER(INDIRECT("'"&'Master of Masters'!K8&"'!A4",TRUE)),INDIRECT("'"&'Master of Masters'!K8&"'!A4",TRUE),"N/A"),"N/A"))} | P8: =IF(B8="","",B8) | Q8: =IF(OR(O8="",P8="",NOT(ISNUMBER(O8)),NOT(ISNUMBER(P8))),"",ROUND(P8/O8,0))
A9: =IF('Master of Masters'!K9="","",IF(ISNUMBER(SEARCH("Spring",'Master of Masters'!K9)),"S",IF(ISNUMBER(SEARCH("Fall",'Master of Masters'!K9)),"F","?"))&RIGHT('Master of Masters'!K9,2)) | B9: {=IF('Master of Masters'!K9="","",IFERROR(IF(ISNUMBER(INDIRECT("'"&'Master of Masters'!K9&"'!I6",TRUE)),INDIRECT("'"&'Master of Masters'!K9&"'!I6",TRUE),"N/A"),"N/A"))} | C9: =IF(B9="","",SUMPRODUCT((ISNUMBER(B$3:B9))*IF(ISNUMBER(B$3:B9),B$3:B9,0))) | E9: =IF(A9="","",A9) | F9: {=IF('Master of Masters'!K9="","",IFERROR(IF(ISNUMBER(INDIRECT("'"&'Master of Masters'!K9&"'!C6",TRUE)),INDIRECT("'"&'Master of Masters'!K9&"'!C6",TRUE),"N/A"),"N/A"))} | G9: {=IF('Master of Masters'!K9="","",IFERROR(IF(ISNUMBER(INDIRECT("'"&'Master of Masters'!K9&"'!F6",TRUE)),INDIRECT("'"&'Master of Masters'!K9&"'!F6",TRUE),"N/A"),"N/A"))} | I9: =IF(A9="","",A9) | J9: {=IF('Master of Masters'!K9="","",IFERROR(IF(ISNUMBER(INDIRECT("'"&'Master of Masters'!K9&"'!I12",TRUE)),INDIRECT("'"&'Master of Masters'!K9&"'!I12",TRUE),"N/A"),"N/A"))} | K9: =IF(J9="","",IF(NOT(ISNUMBER(J9)),"N/A",ROUND(J9/2000,2))) | L9: =IF(J9="","",IF(NOT(ISNUMBER(J9)),"N/A",ROUND(J9/0.891,0))) | N9: =IF(A9="","",A9) | O9: {=IF('Master of Masters'!K9="","",IFERROR(IF(ISNUMBER(INDIRECT("'"&'Master of Masters'!K9&"'!A4",TRUE)),INDIRECT("'"&'Master of Masters'!K9&"'!A4",TRUE),"N/A"),"N/A"))} | P9: =IF(B9="","",B9) | Q9: =IF(OR(O9="",P9="",NOT(ISNUMBER(O9)),NOT(ISNUMBER(P9))),"",ROUND(P9/O9,0))
A10: =IF('Master of Masters'!K10="","",IF(ISNUMBER(SEARCH("Spring",'Master of Masters'!K10)),"S",IF(ISNUMBER(SEARCH("Fall",'Master of Masters'!K10)),"F","?"))&RIGHT('Master of Masters'!K10,2)) | B10: {=IF('Master of Masters'!K10="","",IFERROR(IF(ISNUMBER(INDIRECT("'"&'Master of Masters'!K10&"'!I6",TRUE)),INDIRECT("'"&'Master of Masters'!K10&"'!I6",TRUE),"N/A"),"N/A"))} | C10: =IF(B10="","",SUMPRODUCT((ISNUMBER(B$3:B10))*IF(ISNUMBER(B$3:B10),B$3:B10,0))) | E10: =IF(A10="","",A10) | F10: {=IF('Master of Masters'!K10="","",IFERROR(IF(ISNUMBER(INDIRECT("'"&'Master of Masters'!K10&"'!C6",TRUE)),INDIRECT("'"&'Master of Masters'!K10&"'!C6",TRUE),"N/A"),"N/A"))} | G10: {=IF('Master of Masters'!K10="","",IFERROR(IF(ISNUMBER(INDIRECT("'"&'Master of Masters'!K10&"'!F6",TRUE)),INDIRECT("'"&'Master of Masters'!K10&"'!F6",TRUE),"N/A"),"N/A"))} | I10: =IF(A10="","",A10) | J10: {=IF('Master of Masters'!K10="","",IFERROR(IF(ISNUMBER(INDIRECT("'"&'Master of Masters'!K10&"'!I12",TRUE)),INDIRECT("'"&'Master of Masters'!K10&"'!I12",TRUE),"N/A"),"N/A"))} | K10: =IF(J10="","",IF(NOT(ISNUMBER(J10)),"N/A",ROUND(J10/2000,2))) | L10: =IF(J10="","",IF(NOT(ISNUMBER(J10)),"N/A",ROUND(J10/0.891,0))) | N10: =IF(A10="","",A10) | O10: {=IF('Master of Masters'!K10="","",IFERROR(IF(ISNUMBER(INDIRECT("'"&'Master of Masters'!K10&"'!A4",TRUE)),INDIRECT("'"&'Master of Masters'!K10&"'!A4",TRUE),"N/A"),"N/A"))} | P10: =IF(B10="","",B10) | Q10: =IF(OR(O10="",P10="",NOT(ISNUMBER(O10)),NOT(ISNUMBER(P10))),"",ROUND(P10/O10,0))
A11: =IF('Master of Masters'!K11="","",IF(ISNUMBER(SEARCH("Spring",'Master of Masters'!K11)),"S",IF(ISNUMBER(SEARCH("Fall",'Master of Masters'!K11)),"F","?"))&RIGHT('Master of Masters'!K11,2)) | B11: {=IF('Master of Masters'!K11="","",IFERROR(IF(ISNUMBER(INDIRECT("'"&'Master of Masters'!K11&"'!I6",TRUE)),INDIRECT("'"&'Master of Masters'!K11&"'!I6",TRUE),"N/A"),"N/A"))} | C11: =IF(B11="","",SUMPRODUCT((ISNUMBER(B$3:B11))*IF(ISNUMBER(B$3:B11),B$3:B11,0))) | E11: =IF(A11="","",A11) | F11: {=IF('Master of Masters'!K11="","",IFERROR(IF(ISNUMBER(INDIRECT("'"&'Master of Masters'!K11&"'!C6",TRUE)),INDIRECT("'"&'Master of Masters'!K11&"'!C6",TRUE),"N/A"),"N/A"))} | G11: {=IF('Master of Masters'!K11="","",IFERROR(IF(ISNUMBER(INDIRECT("'"&'Master of Masters'!K11&"'!F6",TRUE)),INDIRECT("'"&'Master of Masters'!K11&"'!F6",TRUE),"N/A"),"N/A"))} | I11: =IF(A11="","",A11) | J11: {=IF('Master of Masters'!K11="","",IFERROR(IF(ISNUMBER(INDIRECT("'"&'Master of Masters'!K11&"'!I12",TRUE)),INDIRECT("'"&'Master of Masters'!K11&"'!I12",TRUE),"N/A"),"N/A"))} | K11: =IF(J11="","",IF(NOT(ISNUMBER(J11)),"N/A",ROUND(J11/2000,2))) | L11: =IF(J11="","",IF(NOT(ISNUMBER(J11)),"N/A",ROUND(J11/0.891,0))) | N11: =IF(A11="","",A11) | O11: {=IF('Master of Masters'!K11="","",IFERROR(IF(ISNUMBER(INDIRECT("'"&'Master of Masters'!K11&"'!A4",TRUE)),INDIRECT("'"&'Master of Masters'!K11&"'!A4",TRUE),"N/A"),"N/A"))} | P11: =IF(B11="","",B11) | Q11: =IF(OR(O11="",P11="",NOT(ISNUMBER(O11)),NOT(ISNUMBER(P11))),"",ROUND(P11/O11,0))
A12: =IF('Master of Masters'!K12="","",IF(ISNUMBER(SEARCH("Spring",'Master of Masters'!K12)),"S",IF(ISNUMBER(SEARCH("Fall",'Master of Masters'!K12)),"F","?"))&RIGHT('Master of Masters'!K12,2)) | B12: {=IF('Master of Masters'!K12="","",IFERROR(IF(ISNUMBER(INDIRECT("'"&'Master of Masters'!K12&"'!I6",TRUE)),INDIRECT("'"&'Master of Masters'!K12&"'!I6",TRUE),"N/A"),"N/A"))} | C12: =IF(B12="","",SUMPRODUCT((ISNUMBER(B$3:B12))*IF(ISNUMBER(B$3:B12),B$3:B12,0))) | E12: =IF(A12="","",A12) | F12: {=IF('Master of Masters'!K12="","",IFERROR(IF(ISNUMBER(INDIRECT("'"&'Master of Masters'!K12&"'!C6",TRUE)),INDIRECT("'"&'Master of Masters'!K12&"'!C6",TRUE),"N/A"),"N/A"))} | G12: {=IF('Master of Masters'!K12="","",IFERROR(IF(ISNUMBER(INDIRECT("'"&'Master of Masters'!K12&"'!F6",TRUE)),INDIRECT("'"&'Master of Masters'!K12&"'!F6",TRUE),"N/A"),"N/A"))} | I12: =IF(A12="","",A12) | J12: {=IF('Master of Masters'!K12="","",IFERROR(IF(ISNUMBER(INDIRECT("'"&'Master of Masters'!K12&"'!I12",TRUE)),INDIRECT("'"&'Master of Masters'!K12&"'!I12",TRUE),"N/A"),"N/A"))} | K12: =IF(J12="","",IF(NOT(ISNUMBER(J12)),"N/A",ROUND(J12/2000,2))) | L12: =IF(J12="","",IF(NOT(ISNUMBER(J12)),"N/A",ROUND(J12/0.891,0))) | N12: =IF(A12="","",A12) | O12: {=IF('Master of Masters'!K12="","",IFERROR(IF(ISNUMBER(INDIRECT("'"&'Master of Masters'!K12&"'!A4",TRUE)),INDIRECT("'"&'Master of Masters'!K12&"'!A4",TRUE),"N/A"),"N/A"))} | P12: =IF(B12="","",B12) | Q12: =IF(OR(O12="",P12="",NOT(ISNUMBER(O12)),NOT(ISNUMBER(P12))),"",ROUND(P12/O12,0))
A13: =IF('Master of Masters'!K13="","",IF(ISNUMBER(SEARCH("Spring",'Master of Masters'!K13)),"S",IF(ISNUMBER(SEARCH("Fall",'Master of Masters'!K13)),"F","?"))&RIGHT('Master of Masters'!K13,2)) | B13: {=IF('Master of Masters'!K13="","",IFERROR(IF(ISNUMBER(INDIRECT("'"&'Master of Masters'!K13&"'!I6",TRUE)),INDIRECT("'"&'Master of Masters'!K13&"'!I6",TRUE),"N/A"),"N/A"))} | C13: =IF(B13="","",SUMPRODUCT((ISNUMBER(B$3:B13))*IF(ISNUMBER(B$3:B13),B$3:B13,0))) | E13: =IF(A13="","",A13) | F13: {=IF('Master of Masters'!K13="","",IFERROR(IF(ISNUMBER(INDIRECT("'"&'Master of Masters'!K13&"'!C6",TRUE)),INDIRECT("'"&'Master of Masters'!K13&"'!C6",TRUE),"N/A"),"N/A"))} | G13: {=IF('Master of Masters'!K13="","",IFERROR(IF(ISNUMBER(INDIRECT("'"&'Master of Masters'!K13&"'!F6",TRUE)),INDIRECT("'"&'Master of Masters'!K13&"'!F6",TRUE),"N/A"),"N/A"))} | I13: =IF(A13="","",A13) | J13: {=IF('Master of Masters'!K13="","",IFERROR(IF(ISNUMBER(INDIRECT("'"&'Master of Masters'!K13&"'!I12",TRUE)),INDIRECT("'"&'Master of Masters'!K13&"'!I12",TRUE),"N/A"),"N/A"))} | K13: =IF(J13="","",IF(NOT(ISNUMBER(J13)),"N/A",ROUND(J13/2000,2))) | L13: =IF(J13="","",IF(NOT(ISNUMBER(J13)),"N/A",ROUND(J13/0.891,0))) | N13: =IF(A13="","",A13) | O13: {=IF('Master of Masters'!K13="","",IFERROR(IF(ISNUMBER(INDIRECT("'"&'Master of Masters'!K13&"'!A4",TRUE)),INDIRECT("'"&'Master of Masters'!K13&"'!A4",TRUE),"N/A"),"N/A"))} | P13: =IF(B13="","",B13) | Q13: =IF(OR(O13="",P13="",NOT(ISNUMBER(O13)),NOT(ISNUMBER(P13))),"",ROUND(P13/O13,0))
A14: =IF('Master of Masters'!K14="","",IF(ISNUMBER(SEARCH("Spring",'Master of Masters'!K14)),"S",IF(ISNUMBER(SEARCH("Fall",'Master of Masters'!K14)),"F","?"))&RIGHT('Master of Masters'!K14,2)) | B14: {=IF('Master of Masters'!K14="","",IFERROR(IF(ISNUMBER(INDIRECT("'"&'Master of Masters'!K14&"'!I6",TRUE)),INDIRECT("'"&'Master of Masters'!K14&"'!I6",TRUE),"N/A"),"N/A"))} | C14: =IF(B14="","",SUMPRODUCT((ISNUMBER(B$3:B14))*IF(ISNUMBER(B$3:B14),B$3:B14,0))) | E14: =IF(A14="","",A14) | F14: {=IF('Master of Masters'!K14="","",IFERROR(IF(ISNUMBER(INDIRECT("'"&'Master of Masters'!K14&"'!C6",TRUE)),INDIRECT("'"&'Master of Masters'!K14&"'!C6",TRUE),"N/A"),"N/A"))} | G14: {=IF('Master of Masters'!K14="","",IFERROR(IF(ISNUMBER(INDIRECT("'"&'Master of Masters'!K14&"'!F6",TRUE)),INDIRECT("'"&'Master of Masters'!K14&"'!F6",TRUE),"N/A"),"N/A"))} | I14: =IF(A14="","",A14) | J14: {=IF('Master of Masters'!K14="","",IFERROR(IF(ISNUMBER(INDIRECT("'"&'Master of Masters'!K14&"'!I12",TRUE)),INDIRECT("'"&'Master of Masters'!K14&"'!I12",TRUE),"N/A"),"N/A"))} | K14: =IF(J14="","",IF(NOT(ISNUMBER(J14)),"N/A",ROUND(J14/2000,2))) | L14: =IF(J14="","",IF(NOT(ISNUMBER(J14)),"N/A",ROUND(J14/0.891,0))) | N14: =IF(A14="","",A14) | O14: {=IF('Master of Masters'!K14="","",IFERROR(IF(ISNUMBER(INDIRECT("'"&'Master of Masters'!K14&"'!A4",TRUE)),INDIRECT("'"&'Master of Masters'!K14&"'!A4",TRUE),"N/A"),"N/A"))} | P14: =IF(B14="","",B14) | Q14: =IF(OR(O14="",P14="",NOT(ISNUMBER(O14)),NOT(ISNUMBER(P14))),"",ROUND(P14/O14,0))
A15: =IF('Master of Masters'!K15="","",IF(ISNUMBER(SEARCH("Spring",'Master of Masters'!K15)),"S",IF(ISNUMBER(SEARCH("Fall",'Master of Masters'!K15)),"F","?"))&RIGHT('Master of Masters'!K15,2)) | B15: {=IF('Master of Masters'!K15="","",IFERROR(IF(ISNUMBER(INDIRECT("'"&'Master of Masters'!K15&"'!I6",TRUE)),INDIRECT("'"&'Master of Masters'!K15&"'!I6",TRUE),"N/A"),"N/A"))} | C15: =IF(B15="","",SUMPRODUCT((ISNUMBER(B$3:B15))*IF(ISNUMBER(B$3:B15),B$3:B15,0))) | E15: =IF(A15="","",A15) | F15: {=IF('Master of Masters'!K15="","",IFERROR(IF(ISNUMBER(INDIRECT("'"&'Master of Masters'!K15&"'!C6",TRUE)),INDIRECT("'"&'Master of Masters'!K15&"'!C6",TRUE),"N/A"),"N/A"))} | G15: {=IF('Master of Masters'!K15="","",IFERROR(IF(ISNUMBER(INDIRECT("'"&'Master of Masters'!K15&"'!F6",TRUE)),INDIRECT("'"&'Master of Masters'!K15&"'!F6",TRUE),"N/A"),"N/A"))} | I15: =IF(A15="","",A15) | J15: {=IF('Master of Masters'!K15="","",IFERROR(IF(ISNUMBER(INDIRECT("'"&'Master of Masters'!K15&"'!I12",TRUE)),INDIRECT("'"&'Master of Masters'!K15&"'!I12",TRUE),"N/A"),"N/A"))} | K15: =IF(J15="","",IF(NOT(ISNUMBER(J15)),"N/A",ROUND(J15/2000,2))) | L15: =IF(J15="","",IF(NOT(ISNUMBER(J15)),"N/A",ROUND(J15/0.891,0))) | N15: =IF(A15="","",A15) | O15: {=IF('Master of Masters'!K15="","",IFERROR(IF(ISNUMBER(INDIRECT("'"&'Master of Masters'!K15&"'!A4",TRUE)),INDIRECT("'"&'Master of Masters'!K15&"'!A4",TRUE),"N/A"),"N/A"))} | P15: =IF(B15="","",B15) | Q15: =IF(OR(O15="",P15="",NOT(ISNUMBER(O15)),NOT(ISNUMBER(P15))),"",ROUND(P15/O15,0))
A16: =IF('Master of Masters'!K16="","",IF(ISNUMBER(SEARCH("Spring",'Master of Masters'!K16)),"S",IF(ISNUMBER(SEARCH("Fall",'Master of Masters'!K16)),"F","?"))&RIGHT('Master of Masters'!K16,2)) | B16: {=IF('Master of Masters'!K16="","",IFERROR(IF(ISNUMBER(INDIRECT("'"&'Master of Masters'!K16&"'!I6",TRUE)),INDIRECT("'"&'Master of Masters'!K16&"'!I6",TRUE),"N/A"),"N/A"))} | C16: =IF(B16="","",SUMPRODUCT((ISNUMBER(B$3:B16))*IF(ISNUMBER(B$3:B16),B$3:B16,0))) | E16: =IF(A16="","",A16) | F16: {=IF('Master of Masters'!K16="","",IFERROR(IF(ISNUMBER(INDIRECT("'"&'Master of Masters'!K16&"'!C6",TRUE)),INDIRECT("'"&'Master of Masters'!K16&"'!C6",TRUE),"N/A"),"N/A"))} | G16: {=IF('Master of Masters'!K16="","",IFERROR(IF(ISNUMBER(INDIRECT("'"&'Master of Masters'!K16&"'!F6",TRUE)),INDIRECT("'"&'Master of Masters'!K16&"'!F6",TRUE),"N/A"),"N/A"))} | I16: =IF(A16="","",A16) | J16: {=IF('Master of Masters'!K16="","",IFERROR(IF(ISNUMBER(INDIRECT("'"&'Master of Masters'!K16&"'!I12",TRUE)),INDIRECT("'"&'Master of Masters'!K16&"'!I12",TRUE),"N/A"),"N/A"))} | K16: =IF(J16="","",IF(NOT(ISNUMBER(J16)),"N/A",ROUND(J16/2000,2))) | L16: =IF(J16="","",IF(NOT(ISNUMBER(J16)),"N/A",ROUND(J16/0.891,0))) | N16: =IF(A16="","",A16) | O16: {=IF('Master of Masters'!K16="","",IFERROR(IF(ISNUMBER(INDIRECT("'"&'Master of Masters'!K16&"'!A4",TRUE)),INDIRECT("'"&'Master of Masters'!K16&"'!A4",TRUE),"N/A"),"N/A"))} | P16: =IF(B16="","",B16) | Q16: =IF(OR(O16="",P16="",NOT(ISNUMBER(O16)),NOT(ISNUMBER(P16))),"",ROUND(P16/O16,0))
A17: =IF('Master of Masters'!K17="","",IF(ISNUMBER(SEARCH("Spring",'Master of Masters'!K17)),"S",IF(ISNUMBER(SEARCH("Fall",'Master of Masters'!K17)),"F","?"))&RIGHT('Master of Masters'!K17,2)) | B17: {=IF('Master of Masters'!K17="","",IFERROR(IF(ISNUMBER(INDIRECT("'"&'Master of Masters'!K17&"'!I6",TRUE)),INDIRECT("'"&'Master of Masters'!K17&"'!I6",TRUE),"N/A"),"N/A"))} | C17: =IF(B17="","",SUMPRODUCT((ISNUMBER(B$3:B17))*IF(ISNUMBER(B$3:B17),B$3:B17,0))) | E17: =IF(A17="","",A17) | F17: {=IF('Master of Masters'!K17="","",IFERROR(IF(ISNUMBER(INDIRECT("'"&'Master of Masters'!K17&"'!C6",TRUE)),INDIRECT("'"&'Master of Masters'!K17&"'!C6",TRUE),"N/A"),"N/A"))} | G17: {=IF('Master of Masters'!K17="","",IFERROR(IF(ISNUMBER(INDIRECT("'"&'Master of Masters'!K17&"'!F6",TRUE)),INDIRECT("'"&'Master of Masters'!K17&"'!F6",TRUE),"N/A"),"N/A"))} | I17: =IF(A17="","",A17) | J17: {=IF('Master of Masters'!K17="","",IFERROR(IF(ISNUMBER(INDIRECT("'"&'Master of Masters'!K17&"'!I12",TRUE)),INDIRECT("'"&'Master of Masters'!K17&"'!I12",TRUE),"N/A"),"N/A"))} | K17: =IF(J17="","",IF(NOT(ISNUMBER(J17)),"N/A",ROUND(J17/2000,2))) | L17: =IF(J17="","",IF(NOT(ISNUMBER(J17)),"N/A",ROUND(J17/0.891,0))) | N17: =IF(A17="","",A17) | O17: {=IF('Master of Masters'!K17="","",IFERROR(IF(ISNUMBER(INDIRECT("'"&'Master of Masters'!K17&"'!A4",TRUE)),INDIRECT("'"&'Master of Masters'!K17&"'!A4",TRUE),"N/A"),"N/A"))} | P17: =IF(B17="","",B17) | Q17: =IF(OR(O17="",P17="",NOT(ISNUMBER(O17)),NOT(ISNUMBER(P17))),"",ROUND(P17/O17,0))
E18: † S24 per-hall split unavailable — program-total only that semester | I18: ‡ EPA avg passenger vehicle: 404 g CO₂/mile (0.891 lb CO₂e/mile)
A21: T5 · Semester-over-Semester % Growth → standalone table | F21: T6 · lbs/hr Efficiency → bar chart (clock-in data req. — F25 onward)
A22: Transition | B22: Mainfare % | C22: Butterfield % | D22: Total % | F22: Semester | G22: MF lbs/hr | H22: BF lbs/hr | I22: Total lbs/hr
A23: =IF(OR(A3="",A4=""),"",A3&" → "&A4) -> S24 → F24 | B23: =IF(OR(NOT(ISNUMBER(F3)),NOT(ISNUMBER(F4))),"",(F4-F3)/F3) | C23: =IF(OR(NOT(ISNUMBER(G3)),NOT(ISNUMBER(G4))),"",(G4-G3)/G3) | D23: =IF(OR(NOT(ISNUMBER(B3)),NOT(ISNUMBER(B4))),"",(B4-B3)/B3) -> 2.7106623 | F23: =IF(A3="","",A3) -> S24 | G23: {=IF('Master of Masters'!K3="","",IFERROR(IF(ISNUMBER(INDIRECT("'"&'Master of Masters'!K3&"'!C8",TRUE)),INDIRECT("'"&'Master of Masters'!K3&"'!C8",TRUE),"N/A"),"N/A"))} -> N/A | H23: {=IF('Master of Masters'!K3="","",IFERROR(IF(ISNUMBER(INDIRECT("'"&'Master of Masters'!K3&"'!F8",TRUE)),INDIRECT("'"&'Master of Masters'!K3&"'!F8",TRUE),"N/A"),"N/A"))} -> N/A | I23: {=IF('Master of Masters'!K3="","",IFERROR(IF(ISNUMBER(INDIRECT("'"&'Master of Masters'!K3&"'!I8",TRUE)),INDIRECT("'"&'Master of Masters'!K3&"'!I8",TRUE),"N/A"),"N/A"))} -> N/A
A24: =IF(OR(A4="",A5=""),"",A4&" → "&A5) -> F24 → S25 | B24: =IF(OR(NOT(ISNUMBER(F4)),NOT(ISNUMBER(F5))),"",(F5-F4)/F4) -> 0.21118751 | C24: =IF(OR(NOT(ISNUMBER(G4)),NOT(ISNUMBER(G5))),"",(G5-G4)/G4) -> 0.15056487 | D24: =IF(OR(NOT(ISNUMBER(B4)),NOT(ISNUMBER(B5))),"",(B5-B4)/B4) -> 0.17763208 | F24: =IF(A4="","",A4) -> F24 | G24: {=IF('Master of Masters'!K4="","",IFERROR(IF(ISNUMBER(INDIRECT("'"&'Master of Masters'!K4&"'!C8",TRUE)),INDIRECT("'"&'Master of Masters'!K4&"'!C8",TRUE),"N/A"),"N/A"))} -> N/A | H24: {=IF('Master of Masters'!K4="","",IFERROR(IF(ISNUMBER(INDIRECT("'"&'Master of Masters'!K4&"'!F8",TRUE)),INDIRECT("'"&'Master of Masters'!K4&"'!F8",TRUE),"N/A"),"N/A"))} -> N/A | I24: {=IF('Master of Masters'!K4="","",IFERROR(IF(ISNUMBER(INDIRECT("'"&'Master of Masters'!K4&"'!I8",TRUE)),INDIRECT("'"&'Master of Masters'!K4&"'!I8",TRUE),"N/A"),"N/A"))} -> N/A
A25: =IF(OR(A5="",A6=""),"",A5&" → "&A6) -> S25 → F25 | B25: =IF(OR(NOT(ISNUMBER(F5)),NOT(ISNUMBER(F6))),"",(F6-F5)/F5) -> 0.40647558 | C25: =IF(OR(NOT(ISNUMBER(G5)),NOT(ISNUMBER(G6))),"",(G6-G5)/G5) -> -0.01660319 | D25: =IF(OR(NOT(ISNUMBER(B5)),NOT(ISNUMBER(B6))),"",(B6-B5)/B5) -> 0.17767837 | F25: =IF(A5="","",A5) -> S25 | G25: {=IF('Master of Masters'!K5="","",IFERROR(IF(ISNUMBER(INDIRECT("'"&'Master of Masters'!K5&"'!C8",TRUE)),INDIRECT("'"&'Master of Masters'!K5&"'!C8",TRUE),"N/A"),"N/A"))} -> N/A | H25: {=IF('Master of Masters'!K5="","",IFERROR(IF(ISNUMBER(INDIRECT("'"&'Master of Masters'!K5&"'!F8",TRUE)),INDIRECT("'"&'Master of Masters'!K5&"'!F8",TRUE),"N/A"),"N/A"))} -> N/A | I25: {=IF('Master of Masters'!K5="","",IFERROR(IF(ISNUMBER(INDIRECT("'"&'Master of Masters'!K5&"'!I8",TRUE)),INDIRECT("'"&'Master of Masters'!K5&"'!I8",TRUE),"N/A"),"N/A"))} -> N/A
A26: =IF(OR(A6="",A7=""),"",A6&" → "&A7) -> F25 → S26* | B26: =IF(OR(NOT(ISNUMBER(F6)),NOT(ISNUMBER(F7))),"",(F7-F6)/F6) -> -0.10723006 | C26: =IF(OR(NOT(ISNUMBER(G6)),NOT(ISNUMBER(G7))),"",(G7-G6)/G6) -> -0.026202723 | D26: =IF(OR(NOT(ISNUMBER(B6)),NOT(ISNUMBER(B7))),"",(B7-B6)/B6) -> -0.070639996 | F26: =IF(A6="","",A6) -> F25 | G26: {=IF('Master of Masters'!K6="","",IFERROR(IF(ISNUMBER(INDIRECT("'"&'Master of Masters'!K6&"'!C8",TRUE)),INDIRECT("'"&'Master of Masters'!K6&"'!C8",TRUE),"N/A"),"N/A"))} -> 51.42 | H26: {=IF('Master of Masters'!K6="","",IFERROR(IF(ISNUMBER(INDIRECT("'"&'Master of Masters'!K6&"'!F8",TRUE)),INDIRECT("'"&'Master of Masters'!K6&"'!F8",TRUE),"N/A"),"N/A"))} -> 41.84 | I26: {=IF('Master of Masters'!K6="","",IFERROR(IF(ISNUMBER(INDIRECT("'"&'Master of Masters'!K6&"'!I8",TRUE)),INDIRECT("'"&'Master of Masters'!K6&"'!I8",TRUE),"N/A"),"N/A"))} -> 46.41
